#VRML_SIM R2025a utf8

EXTERNPROTO "https://raw.githubusercontent.com/cyberbotics/webots/R2025a/projects/objects/backgrounds/protos/TexturedBackground.proto"
EXTERNPROTO "https://raw.githubusercontent.com/cyberbotics/webots/R2025a/projects/objects/backgrounds/protos/TexturedBackgroundLight.proto"
EXTERNPROTO "https://raw.githubusercontent.com/cyberbotics/webots/R2025a/projects/objects/floors/protos/RectangleArena.proto"

WorldInfo {
  basicTimeStep 1
}
Viewpoint {
  orientation 0.1320499919092997 0.0832151022707039 -0.9877439174152531 2.0280366569112727
  position 0.7917113731100606 1.7277724510338253 0.8363196549010631
}
TexturedBackground {
}
TexturedBackgroundLight {
}
RectangleArena {
  floorSize 10 10
}
DEF GalileoMiniDescription Robot {
  translation 6.040301819094929e-05 -3.9197696322384665e-05 0.3997822963711193
  rotation 0.5449710058646879 -0.7824212262362052 -0.3013695862257223 0.0001383575840168369
  children [
    Solid {
      children [
        Gyro {
        }
        InertialUnit {
          name "imu"
        }
      ]
      name "imu_link"
      physics Physics {
        density -1
        mass 0.001
      }
    }
    Shape {
      appearance DEF base_link_material PBRAppearance {
        baseColor 0.75294 0.75294 0.75294
        roughness 1
        metalness 0
      }
      geometry DEF base_link Mesh {
        url [
          "/home/zishang/Webots/galileo_mini/protos/meshes/base_link.STL"
        ]
      }
    }
    HingeJoint {
      jointParameters HingeJointParameters {
        position 2.1483783579193593e-05
        anchor 0.2015 0.08 0
      }
      device [
        RotationalMotor {
          name "FL_abd_joint"
          maxVelocity 21
          minPosition -0.80285
          maxPosition 0.80285
          maxTorque 100
        }
        PositionSensor {
          name "FL_abd_joint_sensor"
        }
      ]
      endPoint Solid {
        translation 0.2015 0.08 0
        rotation 1 0 0 2.1483774667004973e-05
        children [
          Shape {
            appearance DEF FL_abd_link_material PBRAppearance {
              baseColor 0.75294 0.75294 0.75294
              roughness 1
              metalness 0
            }
            geometry DEF FL_abd_link Mesh {
              url [
                "/home/zishang/Webots/galileo_mini/protos/meshes/FL_abd_link.STL"
              ]
            }
          }
          HingeJoint {
            jointParameters HingeJointParameters {
              position 0.7199876628404016
              axis 0 1 0
              anchor 0.1 0.1065 0
            }
            device [
              RotationalMotor {
                name "FL_hip_joint"
                maxVelocity 21
                minPosition -1.0472
                maxPosition 4.1888
                maxTorque 100
              }
              PositionSensor {
                name "FL_hip_joint_sensor"
              }
            ]
            endPoint Solid {
              translation 0.1 0.1065 0
              rotation 0 1 0 0.7199876628404014
              children [
                Shape {
                  appearance DEF FL_hip_link_material PBRAppearance {
                    baseColor 0.75294 0.75294 0.75294
                    roughness 1
                    metalness 0
                  }
                  geometry DEF FL_hip_link Mesh {
                    url [
                      "/home/zishang/Webots/galileo_mini/protos/meshes/FL_hip_link.STL"
                    ]
                  }
                }
                HingeJoint {
                  jointParameters HingeJointParameters {
                    position -1.440056607539892
                    axis 0 1 0
                    anchor 0 0 -0.26
                  }
                  device [
                    RotationalMotor {
                      name "FL_knee_joint"
                      maxVelocity 21
                      minPosition -2.6965
                      maxPosition -0.9163
                      maxTorque 150
                    }
                    PositionSensor {
                      name "FL_knee_joint_sensor"
                    }
                  ]
                  endPoint Solid {
                    translation 0 0 -0.26
                    rotation 0 -1 0 1.440056607539892
                    children [
                      Shape {
                        appearance DEF FL_knee_link_material PBRAppearance {
                          baseColor 0.75294 0.75294 0.75294
                          roughness 1
                          metalness 0
                        }
                        geometry DEF FL_knee_link Mesh {
                          url [
                            "/home/zishang/Webots/galileo_mini/protos/meshes/FL_knee_link.STL"
                          ]
                        }
                      }
                      Solid {
                        translation 0.032939 0 -0.26149
                        children [
                          Shape {
                            appearance DEF FL_foot_link_material PBRAppearance {
                              roughness 1
                              metalness 0
                            }
                            geometry Sphere {
                              radius 0.03
                            }
                          }
                        ]
                        name "FL_foot_link"
                        boundingObject Sphere {
                          radius 0.03
                        }
                        physics Physics {
                          density -1
                          mass 0.000205
                          centerOfMass [
                            0 0 0
                          ]
                          inertiaMatrix [
                            1.096e-09 1.096e-09 1.096e-09
                            -2.0392e-56 0 0
                          ]
                        }
                      }
                    ]
                    name "FL_knee_link"
                    boundingObject Pose {
                      translation 0.01647 0 -0.13
                      rotation 0 -1 0 0.17453
                      children [
                        Box {
                          size 0.05 0.03 0.23
                        }
                      ]
                    }
                    physics Physics {
                      density -1
                      mass 0.314
                      centerOfMass [
                        0.017829 -1.6e-05 -0.099213
                      ]
                      inertiaMatrix [
                        0.003733 0.003882 0.000177
                        -8.7e-08 -0.0006 8.38e-07
                      ]
                    }
                  }
                }
              ]
              name "FL_hip_link"
              boundingObject Pose {
                translation -0.025 0 -0.08
                children [
                  Box {
                    size 0.06 0.035 0.26
                  }
                ]
              }
              physics Physics {
                density -1
                mass 2.6
                centerOfMass [
                  -0.009099 -0.006529 -0.0688
                ]
                inertiaMatrix [
                  0.016848 0.016749 0.002088
                  -0.00031 0.001116 -0.00227
                ]
              }
            }
          }
        ]
        name "FL_abd_link"
        boundingObject Pose {
          translation 0.1 0.03325 0
          rotation 1 0 0 1.570796
          children [
            Cylinder {
              height 0.1065
              radius 0.06
            }
          ]
        }
        physics Physics {
          density -1
          mass 2.86
          centerOfMass [
            0.067568 0.009593 1.4e-05
          ]
          inertiaMatrix [
            0.004368 0.007476 0.006777
            0.000362 0.000114 3.5e-05
          ]
        }
      }
    }
    HingeJoint {
      jointParameters HingeJointParameters {
        position -2.4775698855172834e-05
        anchor 0.2015 -0.08 0
      }
      device [
        RotationalMotor {
          name "FR_abd_joint"
          maxVelocity 21
          minPosition -0.80285
          maxPosition 0.80285
          maxTorque 100
        }
        PositionSensor {
          name "FR_abd_joint_sensor"
        }
      ]
      endPoint Solid {
        translation 0.2015 -0.08 0
        rotation -0.9999999999999999 0 0 2.4775697868995362e-05
        children [
          Shape {
            appearance DEF FR_abd_link_material PBRAppearance {
              baseColor 0.75294 0.75294 0.75294
              roughness 1
              metalness 0
            }
            geometry DEF FR_abd_link Mesh {
              url [
                "/home/zishang/Webots/galileo_mini/protos/meshes/FR_abd_link.STL"
              ]
            }
          }
          HingeJoint {
            jointParameters HingeJointParameters {
              position 0.7199872975412298
              axis 0 1 0
              anchor 0.1 -0.10685 0
            }
            device [
              RotationalMotor {
                name "FR_hip_joint"
                maxVelocity 21
                minPosition -1.0472
                maxPosition 4.1888
                maxTorque 100
              }
              PositionSensor {
                name "FR_hip_joint_sensor"
              }
            ]
            endPoint Solid {
              translation 0.1 -0.10685 0
              rotation 0 1 0 0.7199872975412296
              children [
                Shape {
                  appearance DEF FR_hip_link_material PBRAppearance {
                    baseColor 0.75294 0.75294 0.75294
                    roughness 1
                    metalness 0
                  }
                  geometry DEF FR_hip_link Mesh {
                    url [
                      "/home/zishang/Webots/galileo_mini/protos/meshes/FR_hip_link.STL"
                    ]
                  }
                }
                HingeJoint {
                  jointParameters HingeJointParameters {
                    position -1.4400597527804133
                    axis 0 1 0
                    anchor 0 0 -0.26
                  }
                  device [
                    RotationalMotor {
                      name "FR_knee_joint"
                      maxVelocity 21
                      minPosition -2.6965
                      maxPosition -0.9163
                      maxTorque 150
                    }
                    PositionSensor {
                      name "FR_knee_joint_sensor"
                    }
                  ]
                  endPoint Solid {
                    translation 0 0 -0.26
                    rotation 0 -0.9999999999999999 0 1.4400597527804133
                    children [
                      Shape {
                        appearance DEF FR_knee_link_material PBRAppearance {
                          baseColor 0.75294 0.75294 0.75294
                          roughness 1
                          metalness 0
                        }
                        geometry DEF FR_knee_link Mesh {
                          url [
                            "/home/zishang/Webots/galileo_mini/protos/meshes/FR_knee_link.STL"
                          ]
                        }
                      }
                      Solid {
                        translation 0.032939 0 -0.26149
                        children [
                          Shape {
                            appearance DEF FR_foot_link_material PBRAppearance {
                              roughness 1
                              metalness 0
                            }
                            geometry Sphere {
                              radius 0.03
                            }
                          }
                        ]
                        name "FR_foot_link"
                        boundingObject Sphere {
                          radius 0.03
                        }
                        physics Physics {
                          density -1
                          mass 0.000205
                          centerOfMass [
                            0 0 0
                          ]
                          inertiaMatrix [
                            1.096e-09 1.096e-09 1.096e-09
                            0 1.7152e-40 0
                          ]
                        }
                      }
                    ]
                    name "FR_knee_link"
                    boundingObject Pose {
                      translation 0.01647 0 -0.13
                      rotation 0 -1 0 0.17453
                      children [
                        Box {
                          size 0.05 0.03 0.23
                        }
                      ]
                    }
                    physics Physics {
                      density -1
                      mass 0.314
                      centerOfMass [
                        0.017829 -1.6e-05 -0.099213
                      ]
                      inertiaMatrix [
                        0.003733 0.003882 0.000177
                        -8.7e-08 -0.0006 8.38e-07
                      ]
                    }
                  }
                }
              ]
              name "FR_hip_link"
              boundingObject Pose {
                translation -0.025 0 -0.08
                children [
                  Box {
                    size 0.06 0.035 0.26
                  }
                ]
              }
              physics Physics {
                density -1
                mass 2.6
                centerOfMass [
                  -0.009534 0.026092 -0.067392
                ]
                inertiaMatrix [
                  0.016261 0.016389 0.002194
                  0.000284 0.001143 0.002508
                ]
              }
            }
          }
        ]
        name "FR_abd_link"
        boundingObject Pose {
          translation 0.1 -0.03325 0
          rotation 1 0 0 1.570796
          children [
            Cylinder {
              height 0.1065
              radius 0.06
            }
          ]
        }
        physics Physics {
          density -1
          mass 2.86
          centerOfMass [
            0.067568 -0.009176 -0.000237
          ]
          inertiaMatrix [
            0.004373 0.007483 0.006775
            -0.000397 -9.6e-05 3e-05
          ]
        }
      }
    }
    HingeJoint {
      jointParameters HingeJointParameters {
        position -2.8261470186308202e-05
        anchor -0.2015 -0.08 0
      }
      device [
        RotationalMotor {
          name "HR_abd_joint"
          maxVelocity 21
          minPosition -0.80285
          maxPosition 0.80285
          maxTorque 100
        }
        PositionSensor {
          name "HR_abd_joint_sensor"
        }
      ]
      endPoint Solid {
        translation -0.2015 -0.08 0
        rotation -0.9999999999999999 0 0 2.8261465481113726e-05
        children [
          Shape {
            appearance DEF HR_abd_link_material PBRAppearance {
              baseColor 0.75294 0.75294 0.75294
              roughness 1
              metalness 0
            }
            geometry DEF HR_abd_link Mesh {
              url [
                "/home/zishang/Webots/galileo_mini/protos/meshes/HR_abd_link.STL"
              ]
            }
          }
          HingeJoint {
            jointParameters HingeJointParameters {
              position 0.7199863394342119
              axis 0 1 0
              anchor -0.1 -0.10685 0
            }
            device [
              RotationalMotor {
                name "HR_hip_joint"
                maxVelocity 21
                minPosition -1.0472
                maxPosition 4.1888
                maxTorque 100
              }
              PositionSensor {
                name "HR_hip_joint_sensor"
              }
            ]
            endPoint Solid {
              translation -0.1 -0.10685 0
              rotation 0 0.9999999999999999 0 0.7199863394342121
              children [
                Shape {
                  appearance DEF HR_hip_link_material PBRAppearance {
                    baseColor 0.75294 0.75294 0.75294
                    roughness 1
                    metalness 0
                  }
                  geometry DEF HR_hip_link Mesh {
                    url [
                      "/home/zishang/Webots/galileo_mini/protos/meshes/HR_hip_link.STL"
                    ]
                  }
                }
                HingeJoint {
                  jointParameters HingeJointParameters {
                    position -1.4400670195055423
                    axis 0 1 0
                    anchor 0 0 -0.26
                  }
                  device [
                    RotationalMotor {
                      name "HR_knee_joint"
                      maxVelocity 21
                      minPosition -2.6965
                      maxPosition -0.9163
                      maxTorque 150
                    }
                    PositionSensor {
                      name "HR_knee_joint_sensor"
                    }
                  ]
                  endPoint Solid {
                    translation 0 0 -0.26
                    rotation 0 -1 0 1.440067019505542
                    children [
                      Shape {
                        appearance DEF HR_knee_link_material PBRAppearance {
                          baseColor 0.75294 0.75294 0.75294
                          roughness 1
                          metalness 0
                        }
                        geometry DEF HR_knee_link Mesh {
                          url [
                            "/home/zishang/Webots/galileo_mini/protos/meshes/HR_knee_link.STL"
                          ]
                        }
                      }
                      Solid {
                        translation 0.032939 0 -0.26149
                        children [
                          Shape {
                            appearance DEF HR_foot_link_material PBRAppearance {
                              roughness 1
                              metalness 0
                            }
                            geometry Sphere {
                              radius 0.03
                            }
                          }
                        ]
                        name "HR_foot_link"
                        boundingObject Sphere {
                          radius 0.03
                        }
                        physics Physics {
                          density -1
                          mass 0.000205
                          centerOfMass [
                            0 0 0
                          ]
                          inertiaMatrix [
                            1.096001e-09 1.096001e-09 1.096001e-09
                            0 5.284431e-42 0
                          ]
                        }
                      }
                    ]
                    name "HR_knee_link"
                    boundingObject Pose {
                      translation 0.01647 0 -0.13
                      rotation 0 -1 0 0.17453
                      children [
                        Box {
                          size 0.05 0.03 0.23
                        }
                      ]
                    }
                    physics Physics {
                      density -1
                      mass 0.314
                      centerOfMass [
                        0.017829 -1.6e-05 -0.099213
                      ]
                      inertiaMatrix [
                        0.003733 0.003882 0.000177
                        -8.7e-08 -0.0006 8.38e-07
                      ]
                    }
                  }
                }
              ]
              name "HR_hip_link"
              boundingObject Pose {
                translation -0.025 0 -0.08
                children [
                  Box {
                    size 0.06 0.035 0.26
                  }
                ]
              }
              physics Physics {
                density -1
                mass 2.6
                centerOfMass [
                  -0.009805 0.020667 -0.067167
                ]
                inertiaMatrix [
                  0.017144 0.016508 0.002907
                  0.000198 0.001067 0.002833
                ]
              }
            }
          }
        ]
        name "HR_abd_link"
        boundingObject Pose {
          translation -0.1 -0.03325 0
          rotation 1 0 0 1.570796
          children [
            Cylinder {
              height 0.1065
              radius 0.06
            }
          ]
        }
        physics Physics {
          density -1
          mass 2.86
          centerOfMass [
            -0.067556 -0.009593 -1.7e-05
          ]
          inertiaMatrix [
            0.004372 0.007471 0.006768
            0.000364 -0.000106 -3.8e-05
          ]
        }
      }
    }
    HingeJoint {
      jointParameters HingeJointParameters {
        position 2.8071580683994263e-05
        anchor -0.2015 0.08 0
      }
      device [
        RotationalMotor {
          name "HL_abd_joint"
          maxVelocity 21
          minPosition -0.80285
          maxPosition 0.80285
          maxTorque 100
        }
        PositionSensor {
          name "HL_abd_joint_sensor"
        }
      ]
      endPoint Solid {
        translation -0.2015 0.08 0
        rotation 1 0 0 2.8071572992138518e-05
        children [
          Shape {
            appearance DEF HL_abd_link_material PBRAppearance {
              baseColor 0.75294 0.75294 0.75294
              roughness 1
              metalness 0
            }
            geometry DEF HL_abd_link Mesh {
              url [
                "/home/zishang/Webots/galileo_mini/protos/meshes/HL_abd_link.STL"
              ]
            }
          }
          HingeJoint {
            jointParameters HingeJointParameters {
              position 0.7199860511868208
              axis 0 1 0
              anchor -0.1 0.1065 0
            }
            device [
              RotationalMotor {
                name "HL_hip_joint"
                maxVelocity 21
                minPosition -1.0472
                maxPosition 4.1888
                maxTorque 100
              }
              PositionSensor {
                name "HL_hip_joint_sensor"
              }
            ]
            endPoint Solid {
              translation -0.1 0.1065 0
              rotation 0 1 0 0.719986051186821
              children [
                Shape {
                  appearance DEF HL_hip_link_material PBRAppearance {
                    baseColor 0.75294 0.75294 0.75294
                    roughness 1
                    metalness 0
                  }
                  geometry DEF HL_hip_link Mesh {
                    url [
                      "/home/zishang/Webots/galileo_mini/protos/meshes/HL_hip_link.STL"
                    ]
                  }
                }
                HingeJoint {
                  jointParameters HingeJointParameters {
                    position -1.44006880374454
                    axis 0 1 0
                    anchor 6.3e-05 0 -0.26
                  }
                  device [
                    RotationalMotor {
                      name "HL_knee_joint"
                      maxVelocity 21
                      minPosition -2.6965
                      maxPosition -0.9163
                      maxTorque 150
                    }
                    PositionSensor {
                      name "HL_knee_joint_sensor"
                    }
                  ]
                  endPoint Solid {
                    translation 6.3e-05 0 -0.26
                    rotation 0 -0.9999999999999999 0 1.44006880374454
                    children [
                      Shape {
                        appearance DEF HL_knee_link_material PBRAppearance {
                          baseColor 0.75294 0.75294 0.75294
                          roughness 1
                          metalness 0
                        }
                        geometry DEF HL_knee_link Mesh {
                          url [
                            "/home/zishang/Webots/galileo_mini/protos/meshes/HL_knee_link.STL"
                          ]
                        }
                      }
                      Solid {
                        translation 0.032939 0 -0.261493
                        children [
                          Shape {
                            appearance DEF HL_foot_link_material PBRAppearance {
                              roughness 1
                              metalness 0
                            }
                            geometry Sphere {
                              radius 0.03
                            }
                          }
                        ]
                        name "HL_foot_link"
                        boundingObject Sphere {
                          radius 0.03
                        }
                        physics Physics {
                          density -1
                          mass 0.000205
                          centerOfMass [
                            0 0 0
                          ]
                          inertiaMatrix [
                            1.096001e-09 1.096001e-09 1.096001e-09
                            0 7.974876e-42 0
                          ]
                        }
                      }
                    ]
                    name "HL_knee_link"
                    boundingObject Pose {
                      translation 0.01647 0 -0.13
                      rotation 0 -1 0 0.17453
                      children [
                        Box {
                          size 0.05 0.03 0.23
                        }
                      ]
                    }
                    physics Physics {
                      density -1
                      mass 0.314
                      centerOfMass [
                        0.017829 -1.6e-05 -0.099213
                      ]
                      inertiaMatrix [
                        0.003733 0.003882 0.000177
                        -8.7e-08 -0.0006 8.38e-07
                      ]
                    }
                  }
                }
              ]
              name "HL_hip_link"
              boundingObject Pose {
                translation -0.025 0 -0.08
                children [
                  Box {
                    size 0.06 0.035 0.26
                  }
                ]
              }
              physics Physics {
                density -1
                mass 2.6
                centerOfMass [
                  -0.009036 -0.006529 -0.0688
                ]
                inertiaMatrix [
                  0.016848 0.016749 0.002088
                  -0.00031 0.001116 -0.00227
                ]
              }
            }
          }
        ]
        name "HL_abd_link"
        boundingObject Pose {
          translation -0.1 0.03325 0
          rotation 1 0 0 1.570796
          children [
            Cylinder {
              height 0.1065
              radius 0.06
            }
          ]
        }
        physics Physics {
          density -1
          mass 2.86
          centerOfMass [
            -0.06741 0.009593 7.3e-05
          ]
          inertiaMatrix [
            0.004372 0.007471 0.006768
            0.000364 -0.000106 -3.8e-05
          ]
        }
      }
    }
  ]
  name "GalileoMiniDescription"
  boundingObject Box {
    size 0.45 0.25 0.1
  }
  physics Physics {
    density -1
    mass 20.8
    centerOfMass [
      0.03738 -0.00659 0.005793
    ]
    inertiaMatrix [
      0.131102 0.407915 0.476755
      0.001924 0.001299 0.002595
    ]
  }
  controller "<extern>"
  supervisor TRUE
}
