#VRML_SIM R2025a utf8
# license: Apache License 2.0
# license url: http://www.apache.org/licenses/LICENSE-2.0
# This is a proto file for Webots for the Bqr3Arm
# Extracted from: ../urdf/bqr3_arm.urdf

PROTO Bqr3Arm [
  field  SFVec3f     translation     0 0 0
  field  SFRotation  rotation        0 0 1 0
  field  SFString    name            "Bqr3Arm"  # Is `Robot.name`.
  field  SFString    controller      "void"     # Is `Robot.controller`.
  field  MFString    controllerArgs  []         # Is `Robot.controllerArgs`.
  field  SFString    customData      ""         # Is `Robot.customData`.
  field  SFBool      supervisor      FALSE      # Is `Robot.supervisor`.
  field  SFBool      synchronization TRUE       # Is `Robot.synchronization`.
  field  SFBool      selfCollision   FALSE      # Is `Robot.selfCollision`.
]
{
  Robot {
    translation IS translation
    rotation IS rotation
    controller IS controller
    controllerArgs IS controllerArgs
    customData IS customData
    supervisor IS supervisor
    synchronization IS synchronization
    selfCollision IS selfCollision
    children [
      Shape {
        appearance DEF base_link_material PBRAppearance {
          baseColor 0.792160 0.819610 0.933330
          roughness 1.000000
          metalness 0
        }
        geometry DEF base_link Mesh {
          url "../meshes/base_link.STL"
        }
      }
      HingeJoint {
        jointParameters HingeJointParameters {
          anchor 0.244000 -0.115000 0.000000
        }
        device [
          RotationalMotor {
            name "FR_abd_joint"
            maxVelocity 10.0
            minPosition -3.14
            maxPosition 3.14
            maxTorque 300.0
          }
          PositionSensor {
            name "FR_abd_joint_sensor"
          }
        ]
        endPoint Solid {
          translation 0.244000 -0.115000 0.000000
          children [
            Shape {
              appearance DEF FR_abd_link_material PBRAppearance {
                baseColor 0.898040 0.917650 0.929410
                roughness 1.000000
                metalness 0
              }
              geometry DEF FR_abd_link Mesh {
                url "../meshes/FR_abd_link.STL"
              }
            }
            HingeJoint {
              jointParameters HingeJointParameters {
                axis 0.000000 1.000000 0.000000
                anchor 0.056000 0.018587 0.000000
              }
              device [
                RotationalMotor {
                  name "FR_hip_joint"
                  maxVelocity 10.0
                  minPosition -3.14
                  maxPosition 3.14
                  maxTorque 300.0
                }
                PositionSensor {
                  name "FR_hip_joint_sensor"
                }
              ]
              endPoint Solid {
                translation 0.056000 0.018587 0.000000
                children [
                  Shape {
                    appearance DEF FR_hip_link_material PBRAppearance {
                      baseColor 0.792160 0.819610 0.933330
                      roughness 1.000000
                      metalness 0
                    }
                    geometry DEF FR_hip_link Mesh {
                      url "../meshes/FR_hip_link.STL"
                    }
                  }
                  HingeJoint {
                    jointParameters HingeJointParameters {
                      axis 0.000000 1.000000 0.000000
                      anchor 0.000000 -0.100090 -0.360000
                    }
                    device [
                      RotationalMotor {
                        name "FR_knee_joint"
                        maxVelocity 10.0
                        minPosition -3.14
                        maxPosition 3.14
                        maxTorque 300.0
                      }
                      PositionSensor {
                        name "FR_knee_joint_sensor"
                      }
                    ]
                    endPoint Solid {
                      translation 0.000000 -0.100090 -0.360000
                      children [
                        Shape {
                          appearance DEF FR_knee_link_material PBRAppearance {
                            baseColor 0.898039 0.917647 0.929412
                            roughness 1.000000
                            metalness 0
                          }
                          geometry DEF FR_knee_link Mesh {
                            url "../meshes/FR_knee_link.STL"
                          }
                        }
                        Solid {
                          translation -0.000548 0.000000 -0.360000
                          children [
                            Shape {
                              appearance DEF FR_foot_link_material PBRAppearance {
                                roughness 1.000000
                                metalness 0
                              }
                              geometry DEF FR_foot_link Mesh {
                                url "../meshes/FR_foot_link.STL"
                              }
                            }
                          ]
                          name "FR_foot_link"
                          boundingObject USE FR_foot_link
                          physics Physics {
                            density -1
                            mass 0.103210
                            centerOfMass [ 0.001179 -0.000301 -0.002438 ]
                            inertiaMatrix [
                              2.957200e-05 3.540100e-05 2.916700e-05
                              3.631700e-09 6.748400e-07 -9.146700e-09
                            ]
                          }
                        }
                      ]
                      name "FR_knee_link"
                      boundingObject USE FR_knee_link
                      physics Physics {
                        density -1
                        mass 0.648900
                        centerOfMass [ -0.005170 0.000000 -0.125210 ]
                        inertiaMatrix [
                          6.478288e-03 6.528945e-03 1.356800e-04
                          2.400000e-10 -1.300000e-04 -1.015000e-08
                        ]
                      }
                    }
                  }
                ]
                name "FR_hip_link"
                boundingObject USE FR_hip_link
                physics Physics {
                  density -1
                  mass 1.337000
                  centerOfMass [ -0.000630 -0.020100 -0.158270 ]
                  inertiaMatrix [
                    1.881681e-02 1.886442e-02 8.374510e-04
                    -3.299290e-05 7.920000e-04 1.850000e-04
                  ]
                }
              }
            }
          ]
          name "FR_abd_link"
          boundingObject USE FR_abd_link
          physics Physics {
            density -1
            mass 1.656000
            centerOfMass [ 0.050570 0.046892 0.000001 ]
            inertiaMatrix [
              2.476692e-03 2.206021e-03 2.653852e-03
              4.008270e-04 3.000000e-09 -5.900000e-08
            ]
          }
        }
      }
      HingeJoint {
        jointParameters HingeJointParameters {
          anchor -0.244000 -0.115000 0.000000
        }
        device [
          RotationalMotor {
            name "HR_abd_joint"
            maxVelocity 10.0
            minPosition -3.14
            maxPosition 3.14
            maxTorque 300.0
          }
          PositionSensor {
            name "HR_abd_joint_sensor"
          }
        ]
        endPoint Solid {
          translation -0.244000 -0.115000 0.000000
          children [
            Shape {
              appearance DEF HR_abd_link_material PBRAppearance {
                baseColor 0.898040 0.917650 0.929410
                roughness 1.000000
                metalness 0
              }
              geometry DEF HR_abd_link Mesh {
                url "../meshes/HR_abd_link.STL"
              }
            }
            HingeJoint {
              jointParameters HingeJointParameters {
                axis 0.000000 1.000000 0.000000
                anchor -0.056000 0.018587 0.000000
              }
              device [
                RotationalMotor {
                  name "HR_hip_joint"
                  maxVelocity 10.0
                  minPosition -3.14
                  maxPosition 3.14
                  maxTorque 300.0
                }
                PositionSensor {
                  name "HR_hip_joint_sensor"
                }
              ]
              endPoint Solid {
                translation -0.056000 0.018587 0.000000
                children [
                  Shape {
                    appearance DEF HR_hip_link_material PBRAppearance {
                      baseColor 0.792160 0.819610 0.933330
                      roughness 1.000000
                      metalness 0
                    }
                    geometry DEF HR_hip_link Mesh {
                      url "../meshes/HR_hip_link.STL"
                    }
                  }
                  HingeJoint {
                    jointParameters HingeJointParameters {
                      axis 0.000000 1.000000 0.000000
                      anchor 0.000000 -0.100090 -0.360000
                    }
                    device [
                      RotationalMotor {
                        name "HR_knee_joint"
                        maxVelocity 10.0
                        minPosition -3.14
                        maxPosition 3.14
                        maxTorque 300.0
                      }
                      PositionSensor {
                        name "HR_knee_joint_sensor"
                      }
                    ]
                    endPoint Solid {
                      translation 0.000000 -0.100090 -0.360000
                      children [
                        Shape {
                          appearance DEF HR_knee_link_material PBRAppearance {
                            baseColor 0.898040 0.917650 0.929410
                            roughness 1.000000
                            metalness 0
                          }
                          geometry DEF HR_knee_link Mesh {
                            url "../meshes/HR_knee_link.STL"
                          }
                        }
                        Solid {
                          translation -0.000548 0.000000 -0.360000
                          children [
                            Shape {
                              appearance DEF HR_foot_link_material PBRAppearance {
                                roughness 1.000000
                                metalness 0
                              }
                              geometry DEF HR_foot_link Mesh {
                                url "../meshes/HR_foot_link.STL"
                              }
                            }
                          ]
                          name "HR_foot_link"
                          boundingObject USE HR_foot_link
                          physics Physics {
                            density -1
                            mass 0.103210
                            centerOfMass [ 0.001179 -0.000301 -0.002438 ]
                            inertiaMatrix [
                              2.957200e-05 3.540100e-05 2.916700e-05
                              3.626100e-09 6.748400e-07 -9.144200e-09
                            ]
                          }
                        }
                      ]
                      name "HR_knee_link"
                      boundingObject USE HR_knee_link
                      physics Physics {
                        density -1
                        mass 0.648900
                        centerOfMass [ -0.005170 0.000000 -0.125210 ]
                        inertiaMatrix [
                          6.478288e-03 6.528945e-03 1.356800e-04
                          2.400000e-10 -1.300000e-04 -1.015000e-08
                        ]
                      }
                    }
                  }
                ]
                name "HR_hip_link"
                boundingObject USE HR_hip_link
                physics Physics {
                  density -1
                  mass 1.337000
                  centerOfMass [ -0.000630 -0.020100 -0.158270 ]
                  inertiaMatrix [
                    1.881681e-02 1.886442e-02 8.374510e-04
                    -3.299290e-05 7.920000e-04 1.850000e-04
                  ]
                }
              }
            }
          ]
          name "HR_abd_link"
          boundingObject USE HR_abd_link
          physics Physics {
            density -1
            mass 1.656000
            centerOfMass [ -0.050570 0.046982 -0.000001 ]
            inertiaMatrix [
              2.476692e-03 2.206021e-03 2.653852e-03
              -4.008270e-04 3.000000e-09 5.900000e-08
            ]
          }
        }
      }
      HingeJoint {
        jointParameters HingeJointParameters {
          anchor 0.244000 0.115000 0.000000
        }
        device [
          RotationalMotor {
            name "FL_abd_joint"
            maxVelocity 10.0
            minPosition -3.14
            maxPosition 3.14
            maxTorque 300.0
          }
          PositionSensor {
            name "FL_abd_joint_sensor"
          }
        ]
        endPoint Solid {
          translation 0.244000 0.115000 0.000000
          children [
            Shape {
              appearance DEF FL_abd_link_material PBRAppearance {
                baseColor 0.898040 0.917650 0.929410
                roughness 1.000000
                metalness 0
              }
              geometry DEF FL_abd_link Mesh {
                url "../meshes/FL_abd_link.STL"
              }
            }
            HingeJoint {
              jointParameters HingeJointParameters {
                axis 0.000000 1.000000 0.000000
                anchor 0.056000 -0.018587 0.000000
              }
              device [
                RotationalMotor {
                  name "FL_hip_joint"
                  maxVelocity 10.0
                  minPosition -3.14
                  maxPosition 3.14
                  maxTorque 300.0
                }
                PositionSensor {
                  name "FL_hip_joint_sensor"
                }
              ]
              endPoint Solid {
                translation 0.056000 -0.018587 0.000000
                children [
                  Shape {
                    appearance DEF FL_hip_link_material PBRAppearance {
                      baseColor 0.792160 0.819610 0.933330
                      roughness 1.000000
                      metalness 0
                    }
                    geometry DEF FL_hip_link Mesh {
                      url "../meshes/FL_hip_link.STL"
                    }
                  }
                  HingeJoint {
                    jointParameters HingeJointParameters {
                      axis 0.000000 1.000000 0.000000
                      anchor 0.000000 0.100090 -0.360000
                    }
                    device [
                      RotationalMotor {
                        name "FL_knee_joint"
                        maxVelocity 10.0
                        minPosition -3.14
                        maxPosition 3.14
                        maxTorque 300.0
                      }
                      PositionSensor {
                        name "FL_knee_joint_sensor"
                      }
                    ]
                    endPoint Solid {
                      translation 0.000000 0.100090 -0.360000
                      children [
                        Shape {
                          appearance DEF FL_knee_link_material PBRAppearance {
                            baseColor 0.898040 0.917650 0.929410
                            roughness 1.000000
                            metalness 0
                          }
                          geometry DEF FL_knee_link Mesh {
                            url "../meshes/FL_knee_link.STL"
                          }
                        }
                        Solid {
                          translation -0.000548 0.000000 -0.360000
                          children [
                            Shape {
                              appearance DEF FL_foot_link_material PBRAppearance {
                                roughness 1.000000
                                metalness 0
                              }
                              geometry DEF FL_foot_link Mesh {
                                url "../meshes/FL_foot_link.STL"
                              }
                            }
                          ]
                          name "FL_foot_link"
                          boundingObject USE FL_foot_link
                          physics Physics {
                            density -1
                            mass 0.103210
                            centerOfMass [ 0.001179 0.000099 -0.002438 ]
                            inertiaMatrix [
                              2.957200e-05 3.540100e-05 2.916700e-05
                              3.629500e-09 6.748400e-07 -9.145700e-09
                            ]
                          }
                        }
                      ]
                      name "FL_knee_link"
                      boundingObject USE FL_knee_link
                      physics Physics {
                        density -1
                        mass 0.648900
                        centerOfMass [ -0.005170 0.000000 -0.125210 ]
                        inertiaMatrix [
                          6.478288e-03 6.528945e-03 1.356800e-04
                          2.400000e-10 -1.300000e-04 -1.015000e-08
                        ]
                      }
                    }
                  }
                ]
                name "FL_hip_link"
                boundingObject USE FL_hip_link
                physics Physics {
                  density -1
                  mass 1.337000
                  centerOfMass [ -0.000630 0.020100 -0.158270 ]
                  inertiaMatrix [
                    1.881684e-02 1.886441e-02 8.374130e-04
                    -3.299640e-05 7.920000e-04 1.853530e-04
                  ]
                }
              }
            }
          ]
          name "FL_abd_link"
          boundingObject USE FL_abd_link
          physics Physics {
            density -1
            mass 1.656000
            centerOfMass [ 0.050570 -0.046982 -0.000001 ]
            inertiaMatrix [
              2.476692e-03 2.206021e-03 2.653852e-03
              -4.008270e-04 -3.000000e-09 -5.900000e-08
            ]
          }
        }
      }
      HingeJoint {
        jointParameters HingeJointParameters {
          anchor -0.244000 0.115000 0.000000
        }
        device [
          RotationalMotor {
            name "HL_abd_joint"
            maxVelocity 10.0
            minPosition -3.14
            maxPosition 3.14
            maxTorque 300.0
          }
          PositionSensor {
            name "HL_abd_joint_sensor"
          }
        ]
        endPoint Solid {
          translation -0.244000 0.115000 0.000000
          children [
            Shape {
              appearance DEF HL_abd_link_material PBRAppearance {
                baseColor 0.898040 0.917650 0.929410
                roughness 1.000000
                metalness 0
              }
              geometry DEF HL_abd_link Mesh {
                url "../meshes/HL_abd_link.STL"
              }
            }
            HingeJoint {
              jointParameters HingeJointParameters {
                axis 0.000000 1.000000 0.000000
                anchor -0.056000 -0.018588 0.000000
              }
              device [
                RotationalMotor {
                  name "HL_hip_joint"
                  maxVelocity 10.0
                  minPosition -3.14
                  maxPosition 3.14
                  maxTorque 300.0
                }
                PositionSensor {
                  name "HL_hip_joint_sensor"
                }
              ]
              endPoint Solid {
                translation -0.056000 -0.018588 0.000000
                children [
                  Shape {
                    appearance DEF HL_hip_link_material PBRAppearance {
                      baseColor 0.898040 0.917650 0.929410
                      roughness 1.000000
                      metalness 0
                    }
                    geometry DEF HL_hip_link Mesh {
                      url "../meshes/HL_hip_link.STL"
                    }
                  }
                  HingeJoint {
                    jointParameters HingeJointParameters {
                      axis 0.000000 1.000000 0.000000
                      anchor 0.000000 0.100090 -0.360000
                    }
                    device [
                      RotationalMotor {
                        name "HL_knee_joint"
                        maxVelocity 10.0
                        minPosition -3.14
                        maxPosition 3.14
                        maxTorque 300.0
                      }
                      PositionSensor {
                        name "HL_knee_joint_sensor"
                      }
                    ]
                    endPoint Solid {
                      translation 0.000000 0.100090 -0.360000
                      children [
                        Shape {
                          appearance DEF HL_knee_link_material PBRAppearance {
                            baseColor 0.898040 0.917650 0.929410
                            roughness 1.000000
                            metalness 0
                          }
                          geometry DEF HL_knee_link Mesh {
                            url "../meshes/HL_knee_link.STL"
                          }
                        }
                        Solid {
                          translation -0.000548 0.000000 -0.360000
                          children [
                            Shape {
                              appearance DEF HL_foot_link_material PBRAppearance {
                                roughness 1.000000
                                metalness 0
                              }
                              geometry DEF HL_foot_link Mesh {
                                url "../meshes/HL_foot_link.STL"
                              }
                            }
                          ]
                          name "HL_foot_link"
                          boundingObject USE HL_foot_link
                          physics Physics {
                            density -1
                            mass 0.103210
                            centerOfMass [ 0.001179 0.000499 -0.002438 ]
                            inertiaMatrix [
                              2.957200e-05 3.540100e-05 2.916700e-05
                              3.635100e-09 6.748300e-07 -9.148200e-09
                            ]
                          }
                        }
                      ]
                      name "HL_knee_link"
                      boundingObject USE HL_knee_link
                      physics Physics {
                        density -1
                        mass 0.648900
                        centerOfMass [ -0.005170 0.000000 -0.125210 ]
                        inertiaMatrix [
                          6.478288e-03 6.528945e-03 1.356800e-04
                          2.400000e-10 -1.300000e-04 -1.015000e-08
                        ]
                      }
                    }
                  }
                ]
                name "HL_hip_link"
                boundingObject USE HL_hip_link
                physics Physics {
                  density -1
                  mass 1.337000
                  centerOfMass [ -0.000630 0.020100 -0.158270 ]
                  inertiaMatrix [
                    1.881684e-02 1.886441e-02 8.374130e-04
                    -3.299640e-05 7.920000e-04 1.853530e-04
                  ]
                }
              }
            }
          ]
          name "HL_abd_link"
          boundingObject USE HL_abd_link
          physics Physics {
            density -1
            mass 1.656000
            centerOfMass [ -0.050570 -0.046982 0.000001 ]
            inertiaMatrix [
              2.476692e-03 2.206021e-03 2.653852e-03
              4.008270e-04 -3.000000e-09 5.900000e-08
            ]
          }
        }
      }
      HingeJoint {
        jointParameters HingeJointParameters {
          axis 0.000000 0.000000 1.000000
          anchor 0.131409 0.000657 0.070000
        }
        device [
          RotationalMotor {
            name "shoulder_joint"
            maxVelocity 10.0
            minPosition -3.14
            maxPosition 3.14
            maxTorque 300.0
          }
          PositionSensor {
            name "shoulder_joint_sensor"
          }
        ]
        endPoint Solid {
          translation 0.131409 0.000657 0.070000
          children [
            Shape {
              appearance DEF shoulder_Link_material PBRAppearance {
                baseColor 0.752941 0.752941 0.752941
                roughness 1.000000
                metalness 0
              }
              geometry DEF shoulder_Link Mesh {
                url "../meshes/shoulder_Link.STL"
              }
            }
            HingeJoint {
              jointParameters HingeJointParameters {
                axis 0.000000 1.000000 0.000000
                anchor 0.000000 -0.070087 0.055942
              }
              device [
                RotationalMotor {
                  name "upper_arm_joint"
                  maxVelocity 10.0
                  minPosition -3.14
                  maxPosition 3.14
                  maxTorque 300.0
                }
                PositionSensor {
                  name "upper_arm_joint_sensor"
                }
              ]
              endPoint Solid {
                translation 0.000000 -0.070087 0.055942
                children [
                  Shape {
                    appearance DEF upper_arm_material PBRAppearance {
                      baseColor 0.752941 0.752941 0.752941
                      roughness 1.000000
                      metalness 0
                    }
                    geometry DEF upper_arm Mesh {
                      url "../meshes/upper_arm.STL"
                    }
                  }
                  HingeJoint {
                    jointParameters HingeJointParameters {
                      axis 0.000000 1.000000 0.000000
                      anchor -0.000996 0.051088 0.399999
                    }
                    device [
                      RotationalMotor {
                        name "forearm_joint"
                        maxVelocity 10.0
                        minPosition -3.14
                        maxPosition 3.14
                        maxTorque 300.0
                      }
                      PositionSensor {
                        name "forearm_joint_sensor"
                      }
                    ]
                    endPoint Solid {
                      translation -0.000996 0.051088 0.399999
                      children [
                        Shape {
                          appearance DEF forearm_material PBRAppearance {
                            baseColor 0.752941 0.752941 0.752941
                            roughness 1.000000
                            metalness 0
                          }
                          geometry DEF forearm Mesh {
                            url "../meshes/forearm.STL"
                          }
                        }
                        HingeJoint {
                          jointParameters HingeJointParameters {
                            axis 0.000000 1.000000 0.000000
                            anchor -0.001899 0.014000 0.399126
                          }
                          device [
                            RotationalMotor {
                              name "wrist_pitch_joint"
                              maxVelocity 10.0
                              minPosition -3.14
                              maxPosition 3.14
                              maxTorque 300.0
                            }
                            PositionSensor {
                              name "wrist_pitch_joint_sensor"
                            }
                          ]
                          endPoint Solid {
                            translation -0.001899 0.014000 0.399126
                            children [
                              Shape {
                                appearance DEF wrist_pitch_material PBRAppearance {
                                  baseColor 0.752941 0.752941 0.752941
                                  roughness 1.000000
                                  metalness 0
                                }
                                geometry DEF wrist_pitch Mesh {
                                  url "../meshes/wrist_pitch.STL"
                                }
                              }
                              HingeJoint {
                                jointParameters HingeJointParameters {
                                  axis 0.000000 0.000000 1.000000
                                  anchor -0.000331 0.000000 0.133108
                                }
                                device [
                                  RotationalMotor {
                                    name "wrist_yall_joint"
                                    maxVelocity 10.0
                                    minPosition -3.14
                                    maxPosition 3.14
                                    maxTorque 300.0
                                  }
                                  PositionSensor {
                                    name "wrist_yall_joint_sensor"
                                  }
                                ]
                                endPoint Solid {
                                  translation -0.000331 0.000000 0.133108
                                  children [
                                    Shape {
                                      appearance DEF wrist_yall_material PBRAppearance {
                                        baseColor 0.752941 0.752941 0.752941
                                        roughness 1.000000
                                        metalness 0
                                      }
                                      geometry DEF wrist_yall Mesh {
                                        url "../meshes/wrist_yall.STL"
                                      }
                                    }
                                    HingeJoint {
                                      jointParameters HingeJointParameters {
                                        axis -0.999997 0.000000 -0.002489
                                        anchor 0.000787 0.030000 0.085444
                                      }
                                      device [
                                        RotationalMotor {
                                          name "paw_left_joint"
                                          maxVelocity 10.0
                                          minPosition -3.14
                                          maxPosition 3.14
                                          maxTorque 300.0
                                        }
                                        PositionSensor {
                                          name "paw_left_joint_sensor"
                                        }
                                      ]
                                      endPoint Solid {
                                        translation 0.000787 0.030000 0.085444
                                        children [
                                          Shape {
                                            appearance DEF paw_left_material PBRAppearance {
                                              baseColor 0.752941 0.752941 0.752941
                                              roughness 1.000000
                                              metalness 0
                                            }
                                            geometry DEF paw_left Mesh {
                                              url "../meshes/paw_left.STL"
                                            }
                                          }
                                        ]
                                        name "paw_left"
                                        boundingObject USE paw_left
                                        physics Physics {
                                          density -1
                                          mass 0.008460
                                          centerOfMass [ -0.001093 0.006248 0.037444 ]
                                          inertiaMatrix [
                                            1.170216e-06 1.224844e-06 3.852595e-07
                                            1.520896e-10 1.954171e-09 -6.114301e-08
                                          ]
                                        }
                                      }
                                    }
                                    HingeJoint {
                                      jointParameters HingeJointParameters {
                                        axis -0.999997 0.000000 -0.002489
                                        anchor 0.000787 -0.030000 0.085444
                                      }
                                      device [
                                        RotationalMotor {
                                          name "paw_right_joint"
                                          maxVelocity 10.0
                                          minPosition -3.14
                                          maxPosition 3.14
                                          maxTorque 300.0
                                        }
                                        PositionSensor {
                                          name "paw_right_joint_sensor"
                                        }
                                      ]
                                      endPoint Solid {
                                        translation 0.000787 -0.030000 0.085444
                                        children [
                                          Shape {
                                            appearance DEF paw_right_material PBRAppearance {
                                              baseColor 0.752941 0.752941 0.752941
                                              roughness 1.000000
                                              metalness 0
                                            }
                                            geometry DEF paw_right Mesh {
                                              url "../meshes/paw_right.STL"
                                            }
                                          }
                                        ]
                                        name "paw_right"
                                        boundingObject USE paw_right
                                        physics Physics {
                                          density -1
                                          mass 0.008460
                                          centerOfMass [ -0.001093 -0.007563 0.037444 ]
                                          inertiaMatrix [
                                            1.170216e-06 1.224844e-06 3.852595e-07
                                            -1.523048e-10 1.953656e-09 6.114301e-08
                                          ]
                                        }
                                      }
                                    }
                                  ]
                                  name "wrist_yall"
                                  boundingObject USE wrist_yall
                                  physics Physics {
                                    density -1
                                    mass 0.082411
                                    centerOfMass [ -0.000144 -0.000644 0.041479 ]
                                    inertiaMatrix [
                                      6.407560e-05 5.296054e-05 2.396825e-05
                                      -3.238448e-10 6.575300e-08 2.082414e-08
                                    ]
                                  }
                                }
                              }
                            ]
                            name "wrist_pitch"
                            boundingObject USE wrist_pitch
                            physics Physics {
                              density -1
                              mass 0.318550
                              centerOfMass [ -0.000104 0.007754 0.044674 ]
                              inertiaMatrix [
                                1.090245e-04 1.495111e-04 1.393701e-04
                                -2.806361e-08 -1.520233e-07 2.865905e-07
                              ]
                            }
                          }
                        }
                      ]
                      name "forearm"
                      boundingObject USE forearm
                      physics Physics {
                        density -1
                        mass 0.176801
                        centerOfMass [ -0.000225 -0.002405 0.179831 ]
                        inertiaMatrix [
                          3.088208e-03 3.154860e-03 1.397180e-04
                          3.498415e-07 8.294059e-06 -1.141079e-04
                        ]
                      }
                    }
                  }
                ]
                name "upper_arm"
                boundingObject USE upper_arm
                physics Physics {
                  density -1
                  mass 0.373394
                  centerOfMass [ -0.000679 0.025356 0.272935 ]
                  inertiaMatrix [
                    6.081646e-03 6.225370e-03 3.557652e-04
                    -9.470376e-09 1.422817e-05 8.858079e-09
                  ]
                }
              }
            }
          ]
          name "shoulder_Link"
          boundingObject USE shoulder_Link
          physics Physics {
            density -1
            mass 0.219278
            centerOfMass [ -0.000016 -0.012052 0.049414 ]
            inertiaMatrix [
              2.725070e-04 3.939693e-04 2.419736e-04
              -1.217061e-08 -1.395598e-08 3.045883e-05
            ]
          }
        }
      }
    ]
    name IS name
    boundingObject USE base_link
    physics Physics {
      density -1
      mass 26.500000
      centerOfMass [ -0.000092 0.001447 -0.042478 ]
      inertiaMatrix [
        2.594948e-01 8.599393e-01 9.455674e-01
        -4.122700e-05 1.938620e-04 -2.040130e-03
      ]
    }
  }
}
