#VRML_SIM R2025a utf8

EXTERNPROTO "https://raw.githubusercontent.com/cyberbotics/webots/R2025a/projects/objects/backgrounds/protos/TexturedBackground.proto"
EXTERNPROTO "https://raw.githubusercontent.com/cyberbotics/webots/R2025a/projects/objects/backgrounds/protos/TexturedBackgroundLight.proto"
EXTERNPROTO "https://raw.githubusercontent.com/cyberbotics/webots/R2025a/projects/objects/floors/protos/RectangleArena.proto"

WorldInfo {
  basicTimeStep 1
}
Viewpoint {
  orientation 0.11487095626257218 -0.06867235399170792 -0.991003920882536 4.211257750401115
  position 1.1283433358013928 -1.8747741522095125 0.7056511443268523
  follow "GalileoV1d6"
}
TexturedBackground {
}
TexturedBackgroundLight {
}
RectangleArena {
  floorSize 100 100
}
DEF GalileoV1d6 Robot {
  translation 0 0 0.416422
  children [
    Solid {
      children [
        Gyro {
        }
        InertialUnit {
        }
        Accelerometer {
        }
      ]
      physics Physics {
        density -1
        mass 0.001
      }
    }
    Shape {
      appearance DEF base_link_material PBRAppearance {
        roughness 1
        metalness 0
      }
      geometry DEF TRUCK Mesh {
        url [
          "../protos/meshes/TRUCK.STL"
        ]
      }
    }
    HingeJoint {
      jointParameters HingeJointParameters {
        position 8.521191897473657e-06
        anchor 0.279 0.067 0
      }
      device [
        RotationalMotor {
          name "FL_hip_joint"
          maxVelocity 12
          minPosition -0.698132
          maxPosition 0.698132
          maxTorque 120
        }
        PositionSensor {
          name "FL_hip_joint_sensor"
        }
      ]
      endPoint Solid {
        translation 0.279 0.067 0
        rotation 1 0 0 8.521171408171208e-06
        children [
          Shape {
            appearance DEF FL_hip_material PBRAppearance {
              roughness 1
              metalness 0
            }
            geometry DEF FL_HIP Mesh {
              url [
                "../protos/meshes/FL_HIP.STL"
              ]
            }
          }
          HingeJoint {
            jointParameters HingeJointParameters {
              position 0.7199993861136071
              axis 0 1 0
              anchor 0 0.1103 0
            }
            device [
              RotationalMotor {
                name "FL_thigh_joint"
                maxVelocity 12
                minPosition -1.762783
                maxPosition 3.647738
                maxTorque 120
              }
              PositionSensor {
                name "FL_thigh_joint_sensor"
              }
            ]
            endPoint Solid {
              translation 0 0.1103 0
              rotation 0 1 0 0.7199993861136074
              children [
                Shape {
                  appearance DEF FL_thigh_material PBRAppearance {
                    roughness 1
                    metalness 0
                  }
                  geometry DEF FL_THIGH Mesh {
                    url [
                      "../protos/meshes/FL_THIGH.STL"
                    ]
                  }
                }
                HingeJoint {
                  jointParameters HingeJointParameters {
                    position -1.4400159473101612
                    axis 0 1 0
                    anchor 0 0 -0.26
                  }
                  device [
                    RotationalMotor {
                      name "FL_calf_joint"
                      maxVelocity 12
                      minPosition -2.740167
                      maxPosition -0.383972
                      maxTorque 120
                    }
                    PositionSensor {
                      name "FL_calf_joint_sensor"
                    }
                  ]
                  endPoint Solid {
                    translation 0 0 -0.26
                    rotation 0 -1 0 1.4400159473101612
                    children [
                      Shape {
                        appearance DEF FL_calf_material PBRAppearance {
                          roughness 1
                          metalness 0
                        }
                        geometry DEF FL_CALF Mesh {
                          url [
                            "../protos/meshes/FL_CALF.STL"
                          ]
                        }
                      }
                      Solid {
                        translation 0 0 -0.26
                        children [
                          TouchSensor {
                            name "FL_touch_sensor"
                            boundingObject Sphere {
                              radius 0.026
                            }
                          }
                          Shape {
                            appearance DEF FL_foot_material PBRAppearance {
                              roughness 1
                              metalness 0
                            }
                            geometry Sphere {
                              radius 0.026
                            }
                          }
                        ]
                        name "FL_foot"
                        boundingObject Sphere {
                          radius 0.026
                        }
                        physics Physics {
                          density -1
                          mass 0.04
                          centerOfMass [
                            0 0 0
                          ]
                          inertiaMatrix [
                            9.6e-06 9.6e-06 9.6e-06
                            0 0 0
                          ]
                        }
                      }
                    ]
                    name "FL_calf"
                    boundingObject Group {
                      children [
                        Pose {
                          translation 0.015 0 -0.235
                          rotation 0 1 0 0.5
                          children [
                            Box {
                              size 0.04 0.02 0.05
                            }
                          ]
                        }
                        Pose {
                          translation 0.0085 0 -0.092
                          rotation 0 -1 0 0.15
                          children [
                            Box {
                              size 0.032 0.02 0.27
                            }
                          ]
                        }
                      ]
                    }
                    physics Physics {
                      density -1
                      mass 0.324831
                      centerOfMass [
                        0.006276 6e-05 -0.145811
                      ]
                      inertiaMatrix [
                        0.0041942 0.0042423 9.93e-05
                        0 -3e-07 0
                      ]
                    }
                  }
                }
              ]
              name "FL_thigh"
              boundingObject Group {
                children [
                  Pose {
                    translation -0.025 0 -0.15
                    children [
                      Box {
                        size 0.05 0.02 0.18
                      }
                    ]
                  }
                  Pose {
                    translation 0 -0.065 0
                    rotation 0.5775032287046065 0.5775032287046065 -0.5770442285228318 2.093475
                    children [
                      Cylinder {
                        height 0.08
                        radius 0.06
                      }
                    ]
                  }
                ]
              }
              physics Physics {
                density -1
                mass 2.211555
                centerOfMass [
                  -0.0028 -0.03681 -0.023902
                ]
                inertiaMatrix [
                  0.012133 0.0117725 0.0019164
                  0.0002099 -0.000542 0.0020399
                ]
              }
            }
          }
        ]
        name "FL_hip"
        physics Physics {
          density -1
          mass 1.645937
          centerOfMass [
            -0.003454 0.000147 -0.00096
          ]
          inertiaMatrix [
            0.0004144 0.000796 0.0005767
            1e-05 1.5e-06 -1.4e-06
          ]
        }
      }
    }
    HingeJoint {
      jointParameters HingeJointParameters {
        position 8.921854833166502e-06
        anchor -0.279 0.067 0
      }
      device [
        RotationalMotor {
          name "RL_hip_joint"
          maxVelocity 12
          minPosition -0.698132
          maxPosition 0.698132
          maxTorque 120
        }
        PositionSensor {
          name "RL_hip_joint_sensor"
        }
      ]
      endPoint Solid {
        translation -0.279 0.067 0
        rotation 1 0 0 8.921851722152579e-06
        children [
          Shape {
            appearance DEF RL_hip_material PBRAppearance {
              roughness 1
              metalness 0
            }
            geometry DEF RL_HIP Mesh {
              url [
                "../protos/meshes/RL_HIP.STL"
              ]
            }
          }
          HingeJoint {
            jointParameters HingeJointParameters {
              position 0.7199994638310617
              axis 0 1 0
              anchor 0 0.1103 0
            }
            device [
              RotationalMotor {
                name "RL_thigh_joint"
                maxVelocity 12
                minPosition -1.762783
                maxPosition 3.647738
                maxTorque 120
              }
              PositionSensor {
                name "RL_thigh_joint_sensor"
              }
            ]
            endPoint Solid {
              translation 0 0.1103 0
              rotation 0 1 0 0.7199994638310618
              children [
                Shape {
                  appearance DEF RL_thigh_material PBRAppearance {
                    roughness 1
                    metalness 0
                  }
                  geometry USE FL_THIGH
                }
                HingeJoint {
                  jointParameters HingeJointParameters {
                    position -1.4400165691785074
                    axis 0 1 0
                    anchor 0 0 -0.26
                  }
                  device [
                    RotationalMotor {
                      name "RL_calf_joint"
                      maxVelocity 12
                      minPosition -2.740167
                      maxPosition -0.383972
                      maxTorque 120
                    }
                    PositionSensor {
                      name "RL_calf_joint_sensor"
                    }
                  ]
                  endPoint Solid {
                    translation 0 0 -0.26
                    rotation 0 -1 0 1.4400165691785074
                    children [
                      Shape {
                        appearance DEF RL_calf_material PBRAppearance {
                          roughness 1
                          metalness 0
                        }
                        geometry USE FL_CALF
                      }
                      Solid {
                        translation 0 0 -0.26
                        children [
                          TouchSensor {
                            name "RL_touch_sensor"
                            boundingObject Sphere {
                              radius 0.026
                            }
                          }
                          Shape {
                            appearance DEF RL_foot_material PBRAppearance {
                              roughness 1
                              metalness 0
                            }
                            geometry Sphere {
                              radius 0.026
                            }
                          }
                        ]
                        name "RL_foot"
                        boundingObject Sphere {
                          radius 0.026
                        }
                        physics Physics {
                          density -1
                          mass 0.04
                          centerOfMass [
                            0 0 0
                          ]
                          inertiaMatrix [
                            9.6e-06 9.6e-06 9.6e-06
                            0 0 0
                          ]
                        }
                      }
                    ]
                    name "RL_calf"
                    boundingObject Group {
                      children [
                        Pose {
                          translation 0.015 0 -0.235
                          rotation 0 1 0 0.5
                          children [
                            Box {
                              size 0.04 0.02 0.05
                            }
                          ]
                        }
                        Pose {
                          translation 0.0085 0 -0.092
                          rotation 0 -1 0 0.15
                          children [
                            Box {
                              size 0.032 0.02 0.27
                            }
                          ]
                        }
                      ]
                    }
                    physics Physics {
                      density -1
                      mass 0.324831
                      centerOfMass [
                        0.006276 6e-05 -0.145811
                      ]
                      inertiaMatrix [
                        0.0041942 0.0042423 9.93e-05
                        0 -3e-07 0
                      ]
                    }
                  }
                }
              ]
              name "RL_thigh"
              boundingObject Group {
                children [
                  Pose {
                    translation -0.025 0 -0.15
                    children [
                      Box {
                        size 0.05 0.02 0.18
                      }
                    ]
                  }
                  Pose {
                    translation 0 -0.065 0
                    rotation 0.5775032287046065 0.5775032287046065 -0.5770442285228318 2.093475
                    children [
                      Cylinder {
                        height 0.08
                        radius 0.06
                      }
                    ]
                  }
                ]
              }
              physics Physics {
                density -1
                mass 2.211555
                centerOfMass [
                  -0.0028 -0.03681 -0.023902
                ]
                inertiaMatrix [
                  0.012133 0.0117725 0.0019164
                  0.0002099 -0.000542 0.0020399
                ]
              }
            }
          }
        ]
        name "RL_hip"
        physics Physics {
          density -1
          mass 1.645937
          centerOfMass [
            -0.003454 0.000147 -0.00096
          ]
          inertiaMatrix [
            0.0004144 0.000796 0.0005767
            -1e-05 -1.5e-06 -1.4e-06
          ]
        }
      }
    }
    HingeJoint {
      jointParameters HingeJointParameters {
        position -9.242718352608645e-06
        anchor 0.279 -0.067 0
      }
      device [
        RotationalMotor {
          name "FR_hip_joint"
          maxVelocity 12
          minPosition -0.698132
          maxPosition 0.698132
          maxTorque 120
        }
        PositionSensor {
          name "FR_hip_joint_sensor"
        }
      ]
      endPoint Solid {
        translation 0.279 -0.067 0
        rotation -1 0 0 9.2427087448523e-06
        children [
          Transform {
            scale 1 -1 1
            children [
              Shape {
                appearance DEF FR_hip_material PBRAppearance {
                  roughness 1
                  metalness 0
                }
                geometry DEF FL_HIP_cw Mesh {
                  url [
                    "../protos/meshes/FL_HIP.STL"
                  ]
                  ccw FALSE
                }
              }
            ]
          }
          HingeJoint {
            jointParameters HingeJointParameters {
              position 0.7199993926892898
              axis 0 1 0
              anchor 0 -0.1103 0
            }
            device [
              RotationalMotor {
                name "FR_thigh_joint"
                maxVelocity 12
                minPosition -1.762783
                maxPosition 3.647738
                maxTorque 120
              }
              PositionSensor {
                name "FR_thigh_joint_sensor"
              }
            ]
            endPoint Solid {
              translation 0 -0.1103 0
              rotation 0 1 0 0.71999939268929
              children [
                Transform {
                  scale 1 -1 1
                  children [
                    Shape {
                      appearance DEF FR_thigh_material PBRAppearance {
                        roughness 1
                        metalness 0
                      }
                      geometry DEF FL_THIGH_cw Mesh {
                        url [
                          "../protos/meshes/FL_THIGH.STL"
                        ]
                        ccw FALSE
                      }
                    }
                  ]
                }
                HingeJoint {
                  jointParameters HingeJointParameters {
                    position -1.4400170767898748
                    axis 0 1 0
                    anchor 0 0 -0.26
                  }
                  device [
                    RotationalMotor {
                      name "FR_calf_joint"
                      maxVelocity 12
                      minPosition -2.740167
                      maxPosition -0.383972
                      maxTorque 120
                    }
                    PositionSensor {
                      name "FR_calf_joint_sensor"
                    }
                  ]
                  endPoint Solid {
                    translation 0 0 -0.26
                    rotation 0 -1 0 1.440017076789875
                    children [
                      Transform {
                        scale 1 -1 1
                        children [
                          Shape {
                            appearance DEF FR_calf_material PBRAppearance {
                              roughness 1
                              metalness 0
                            }
                            geometry DEF FL_CALF_cw Mesh {
                              url [
                                "../protos/meshes/FL_CALF.STL"
                              ]
                              ccw FALSE
                            }
                          }
                        ]
                      }
                      Solid {
                        translation 0 0 -0.26
                        children [
                          TouchSensor {
                            name "FR_touch_sensor"
                            boundingObject Sphere {
                              radius 0.026
                            }
                          }
                          Shape {
                            appearance DEF FR_foot_material PBRAppearance {
                              roughness 1
                              metalness 0
                            }
                            geometry Sphere {
                              radius 0.026
                            }
                          }
                        ]
                        name "FR_foot"
                        boundingObject Sphere {
                          radius 0.026
                        }
                        physics Physics {
                          density -1
                          mass 0.04
                          centerOfMass [
                            0 0 0
                          ]
                          inertiaMatrix [
                            9.6e-06 9.6e-06 9.6e-06
                            0 0 0
                          ]
                        }
                      }
                    ]
                    name "FR_calf"
                    boundingObject Group {
                      children [
                        Pose {
                          translation 0.015 0 -0.235
                          rotation 0 1 0 0.5
                          children [
                            Box {
                              size 0.04 0.02 0.05
                            }
                          ]
                        }
                        Pose {
                          translation 0.0085 0 -0.092
                          rotation 0 -1 0 0.15
                          children [
                            Box {
                              size 0.032 0.02 0.27
                            }
                          ]
                        }
                      ]
                    }
                    physics Physics {
                      density -1
                      mass 0.324831
                      centerOfMass [
                        0.006276 -6e-05 -0.145811
                      ]
                      inertiaMatrix [
                        0.0041942 0.0042423 9.93e-05
                        0 -3e-07 0
                      ]
                    }
                  }
                }
              ]
              name "FR_thigh"
              boundingObject Group {
                children [
                  Pose {
                    translation -0.025 0 -0.15
                    children [
                      Box {
                        size 0.05 0.02 0.18
                      }
                    ]
                  }
                  Pose {
                    translation 0 0.065 0
                    rotation 0.5775032287046065 0.5775032287046065 -0.5770442285228318 2.093475
                    children [
                      Cylinder {
                        height 0.08
                        radius 0.06
                      }
                    ]
                  }
                ]
              }
              physics Physics {
                density -1
                mass 2.211555
                centerOfMass [
                  -0.0028 0.03681 -0.023902
                ]
                inertiaMatrix [
                  0.012133 0.0117725 0.0019164
                  -0.0002099 -0.000542 -0.0020399
                ]
              }
            }
          }
        ]
        name "FR_hip"
        physics Physics {
          density -1
          mass 1.645937
          centerOfMass [
            -0.003454 -0.000147 -0.00096
          ]
          inertiaMatrix [
            0.0004144 0.000796 0.0005767
            -1e-05 1.5e-06 1.4e-06
          ]
        }
      }
    }
    HingeJoint {
      jointParameters HingeJointParameters {
        position -9.639032327554168e-06
        anchor -0.279 -0.067 0
      }
      device [
        RotationalMotor {
          name "RR_hip_joint"
          maxVelocity 12
          minPosition -0.698132
          maxPosition 0.698132
          maxTorque 120
        }
        PositionSensor {
          name "RR_hip_joint_sensor"
        }
      ]
      endPoint Solid {
        translation -0.279 -0.067 0
        rotation -1 0 0 9.639012819172436e-06
        children [
          Transform {
            scale 1 -1 1
            children [
              Shape {
                appearance DEF RR_hip_material PBRAppearance {
                  roughness 1
                  metalness 0
                }
                geometry DEF RL_HIP_cw Mesh {
                  url [
                    "../protos/meshes/RL_HIP.STL"
                  ]
                  ccw FALSE
                }
              }
            ]
          }
          HingeJoint {
            jointParameters HingeJointParameters {
              position 0.7199993855535218
              axis 0 1 0
              anchor 0 -0.1103 0
            }
            device [
              RotationalMotor {
                name "RR_thigh_joint"
                maxVelocity 12
                minPosition -1.762783
                maxPosition 3.647738
                maxTorque 120
              }
              PositionSensor {
                name "RR_thigh_joint_sensor"
              }
            ]
            endPoint Solid {
              translation 0 -0.1103 0
              rotation 0 1 0 0.7199993855535218
              children [
                Transform {
                  scale 1 -1 1
                  children [
                    Shape {
                      appearance DEF RR_thigh_material PBRAppearance {
                        roughness 1
                        metalness 0
                      }
                      geometry USE FL_THIGH_cw
                    }
                  ]
                }
                HingeJoint {
                  jointParameters HingeJointParameters {
                    position -1.4400176982048465
                    axis 0 1 0
                    anchor 0 0 -0.26
                  }
                  device [
                    RotationalMotor {
                      name "RR_calf_joint"
                      maxVelocity 12
                      minPosition -2.740167
                      maxPosition -0.383972
                      maxTorque 120
                    }
                    PositionSensor {
                      name "RR_calf_joint_sensor"
                    }
                  ]
                  endPoint Solid {
                    translation 0 0 -0.26
                    rotation 0 -1 0 1.4400176982048465
                    children [
                      Transform {
                        scale 1 -1 1
                        children [
                          Shape {
                            appearance DEF RR_calf_material PBRAppearance {
                              roughness 1
                              metalness 0
                            }
                            geometry USE FL_CALF_cw
                          }
                        ]
                      }
                      Solid {
                        translation 0 0 -0.26
                        children [
                          TouchSensor {
                            name "RR_touch_sensor"
                            boundingObject Sphere {
                              radius 0.026
                            }
                          }
                          Shape {
                            appearance DEF RR_foot_material PBRAppearance {
                              roughness 1
                              metalness 0
                            }
                            geometry Sphere {
                              radius 0.026
                            }
                          }
                        ]
                        name "RR_foot"
                        boundingObject Sphere {
                          radius 0.026
                        }
                        physics Physics {
                          density -1
                          mass 0.04
                          centerOfMass [
                            0 0 0
                          ]
                          inertiaMatrix [
                            9.6e-06 9.6e-06 9.6e-06
                            0 0 0
                          ]
                        }
                      }
                    ]
                    name "RR_calf"
                    boundingObject Group {
                      children [
                        Pose {
                          translation 0.015 0 -0.235
                          rotation 0 1 0 0.5
                          children [
                            Box {
                              size 0.04 0.02 0.05
                            }
                          ]
                        }
                        Pose {
                          translation 0.0085 0 -0.092
                          rotation 0 -1 0 0.15
                          children [
                            Box {
                              size 0.032 0.02 0.27
                            }
                          ]
                        }
                      ]
                    }
                    physics Physics {
                      density -1
                      mass 0.324831
                      centerOfMass [
                        0.006276 -6e-05 -0.145811
                      ]
                      inertiaMatrix [
                        0.0041942 0.0042423 9.93e-05
                        0 -3e-07 0
                      ]
                    }
                  }
                }
              ]
              name "RR_thigh"
              boundingObject Group {
                children [
                  Pose {
                    translation -0.025 0 -0.15
                    children [
                      Box {
                        size 0.05 0.02 0.18
                      }
                    ]
                  }
                  Pose {
                    translation 0 0.065 0
                    rotation 0.5775032287046065 0.5775032287046065 -0.5770442285228318 2.093475
                    children [
                      Cylinder {
                        height 0.08
                        radius 0.06
                      }
                    ]
                  }
                ]
              }
              physics Physics {
                density -1
                mass 2.211555
                centerOfMass [
                  -0.0028 0.03681 -0.023902
                ]
                inertiaMatrix [
                  0.012133 0.0117725 0.0019164
                  -0.0002099 -0.000542 -0.0020399
                ]
              }
            }
          }
        ]
        name "RR_hip"
        physics Physics {
          density -1
          mass 1.645937
          centerOfMass [
            -0.003454 -0.000147 -0.00096
          ]
          inertiaMatrix [
            0.0004144 0.000796 0.0005767
            1e-05 -1.5e-06 1.4e-06
          ]
        }
      }
    }
  ]
  name "GalileoV1d6"
  boundingObject Pose {
    translation 0 0 -0.01
    children [
      Box {
        size 0.42 0.26 0.18
      }
    ]
  }
  physics Physics {
    density -1
    mass 24.042743
    centerOfMass [
      0.002783 -0.009841 -0.000267
    ]
    inertiaMatrix [
      0.1136788 0.3485644 0.408405
      0.0016372 0.0001502 3.6e-05
    ]
  }
  controller "<extern>"
  supervisor TRUE
}
