#VRML_SIM R2025a utf8

EXTERNPROTO "https://raw.githubusercontent.com/cyberbotics/webots/R2025a/projects/objects/backgrounds/protos/TexturedBackground.proto"
EXTERNPROTO "https://raw.githubusercontent.com/cyberbotics/webots/R2025a/projects/objects/backgrounds/protos/TexturedBackgroundLight.proto"
EXTERNPROTO "https://raw.githubusercontent.com/cyberbotics/webots/R2025a/projects/objects/floors/protos/RectangleArena.proto"

WorldInfo {
  basicTimeStep 1
}
Viewpoint {
  orientation 0.07214401702280894 -0.04300765979840864 -0.996466548363003 4.213589590502311
  position 1.9685425808718482 -3.114366765744043 0.6948941852244853
}
TexturedBackground {
}
TexturedBackgroundLight {
}
RectangleArena {
  floorSize 50 50
}
DEF A1 Robot {
  translation -0.000503899 0.000205106 0.32
  rotation -0.37790211777852123 -0.9258455512094771 -6.844069166881444e-05 0.0016921828101181524
  children [
    Solid {
      children [
        Gyro {
        }
        Accelerometer {
        }
        InertialUnit {
        }
        Shape {
          appearance DEF grey PBRAppearance {
            baseColor 0.5 0.5 0.5
            roughness 1
            metalness 0
          }
          geometry Box {
            size 0.001 0.001 0.001
          }
        }
      ]
      name "imu_link"
      boundingObject Box {
        size 0.001 0.001 0.001
      }
      physics Physics {
        density -1
        mass 0.001
        centerOfMass [
          0 0 0
        ]
        inertiaMatrix [
          0.0001 0.0001 0.0001
          0 0 0
        ]
      }
    }
    DEF trunk_visual CadShape {
      url [
        "../protos/meshes/trunk.dae"
      ]
    }
    HingeJoint {
      jointParameters HingeJointParameters {
        position -4.256196818097635e-06
        anchor 0.1805 -0.047 0
      }
      device [
        RotationalMotor {
          name "FR_hip_joint"
          maxVelocity 21
          minPosition -0.8028514559173915
          maxPosition 0.8028514559173915
          maxTorque 33.5
        }
        PositionSensor {
          name "FR_hip_joint_sensor"
        }
      ]
      endPoint Solid {
        translation 0.1805 -0.047 0
        rotation -1 0 0 1.8393128066313286e-06
        children [
          Pose {
            rotation 1 0 0 3.141593
            children [
              DEF hip_visual CadShape {
                url [
                  "../protos/meshes/hip.dae"
                ]
              }
            ]
          }
          Solid {
            translation 0 -0.081 0
            name "FR_thigh_shoulder"
            boundingObject Pose {
              rotation 1 0 0 1.570796
              children [
                Cylinder {
                  height 0.032
                  radius 0.041
                }
              ]
            }
            physics Physics {
              density -1
              mass 0.001
            }
          }
          HingeJoint {
            jointParameters HingeJointParameters {
              position 0.719998798881066
              axis 0 1 0
              anchor 0 -0.0838 0
            }
            device [
              RotationalMotor {
                name "FR_thigh_joint"
                maxVelocity 21
                minPosition -1.0471975511965976
                maxPosition 4.1887902047863905
                maxTorque 33.5
              }
              PositionSensor {
                name "FR_thigh_joint_sensor"
              }
            ]
            endPoint Solid {
              translation 0 -0.0838 0
              rotation 0 1 0 0.7199987988810661
              children [
                DEF thigh_mirror_visual CadShape {
                  url [
                    "../protos/meshes/thigh_mirror.dae"
                  ]
                }
                HingeJoint {
                  jointParameters HingeJointParameters {
                    position -1.4400100976665615
                    axis 0 1 0
                    anchor 0 0 -0.2
                  }
                  device [
                    RotationalMotor {
                      name "FR_calf_joint"
                      maxVelocity 21
                      minPosition -2.6965336943312392
                      maxPosition -0.9162978572970231
                      maxTorque 33.5
                    }
                    PositionSensor {
                      name "FR_calf_joint_sensor"
                    }
                  ]
                  endPoint Solid {
                    translation 0 0 -0.2
                    rotation 0 -1 0 1.4400100976665613
                    children [
                      DEF calf_visual CadShape {
                        url [
                          "../protos/meshes/calf.dae"
                        ]
                      }
                      Solid {
                        translation 0 0 -0.2
                        children [
                          Shape {
                            appearance DEF grey PBRAppearance {
                              baseColor 0.5 0.5 0.5
                              roughness 1
                              metalness 0
                            }
                            geometry Sphere {
                              radius 0.01
                            }
                          }
                        ]
                        name "FR_foot"
                        boundingObject Sphere {
                          radius 0.02
                        }
                        physics Physics {
                          density -1
                          mass 0.06
                          centerOfMass [
                            0 0 0
                          ]
                          inertiaMatrix [
                            9.6e-06 9.6e-06 9.6e-06
                            0 0 0
                          ]
                        }
                      }
                    ]
                    name "FR_calf"
                    boundingObject Pose {
                      translation 0 0 -0.1
                      rotation 0 1 0 1.570796
                      children [
                        Box {
                          size 0.2 0.016 0.016
                        }
                      ]
                    }
                    physics Physics {
                      density -1
                      mass 0.166
                      centerOfMass [
                        0.006435 0 -0.107388
                      ]
                      inertiaMatrix [
                        0.002997972 0.003014022 3.2426e-05
                        0 -0.000141163 0
                      ]
                    }
                  }
                }
              ]
              name "FR_thigh"
              boundingObject Pose {
                translation 0 0 -0.1
                rotation 0 1 0 1.570796
                children [
                  Box {
                    size 0.2 0.0245 0.034
                  }
                ]
              }
              physics Physics {
                density -1
                mass 1.013
                centerOfMass [
                  -0.003237 0.022327 -0.027326
                ]
                inertiaMatrix [
                  0.005529065 0.005139339 0.001367788
                  -4.825e-06 0.000343869 -2.2448e-05
                ]
              }
            }
          }
        ]
        name "FR_hip"
        boundingObject Pose {
          rotation 1 0 0 1.570796
          children [
            Cylinder {
              height 0.04
              radius 0.046
            }
          ]
        }
        physics Physics {
          density -1
          mass 0.696
          centerOfMass [
            -0.003311 -0.000635 3.1e-05
          ]
          inertiaMatrix [
            0.000469246 0.00080749 0.000552929
            9.409e-06 -3.42e-07 4.66e-07
          ]
        }
      }
    }
    HingeJoint {
      jointParameters HingeJointParameters {
        position 4.400842345951434e-06
        anchor 0.1805 0.047 0
      }
      device [
        RotationalMotor {
          name "FL_hip_joint"
          maxVelocity 21
          minPosition -0.8028514559173915
          maxPosition 0.8028514559173915
          maxTorque 33.5
        }
        PositionSensor {
          name "FL_hip_joint_sensor"
        }
      ]
      endPoint Solid {
        translation 0.1805 0.047 0
        rotation 1 0 0 4.400865667114681e-06
        children [
          DEF hip_visual CadShape {
            url [
              "../protos/meshes/hip.dae"
            ]
          }
          Solid {
            translation 0 0.081 0
            name "FL_thigh_shoulder"
            boundingObject Pose {
              rotation 1 0 0 1.570796
              children [
                Cylinder {
                  height 0.032
                  radius 0.041
                }
              ]
            }
            physics Physics {
              density -1
              mass 0.001
            }
          }
          HingeJoint {
            jointParameters HingeJointParameters {
              position 0.7199987700519094
              axis 0 1 0
              anchor 0 0.0838 0
            }
            device [
              RotationalMotor {
                name "FL_thigh_joint"
                maxVelocity 21
                minPosition -1.0471975511965976
                maxPosition 4.1887902047863905
                maxTorque 33.5
              }
              PositionSensor {
                name "FL_thigh_joint_sensor"
              }
            ]
            endPoint Solid {
              translation 0 0.0838 0
              rotation 0 1 0 0.7199987700519095
              children [
                DEF thigh_visual CadShape {
                  url [
                    "../protos/meshes/thigh.dae"
                  ]
                }
                HingeJoint {
                  jointParameters HingeJointParameters {
                    position -1.4400103828041086
                    axis 0 1 0
                    anchor 0 0 -0.2
                  }
                  device [
                    RotationalMotor {
                      name "FL_calf_joint"
                      maxVelocity 21
                      minPosition -2.6965336943312392
                      maxPosition -0.9162978572970231
                      maxTorque 33.5
                    }
                    PositionSensor {
                      name "FL_calf_joint_sensor"
                    }
                  ]
                  endPoint Solid {
                    translation 0 0 -0.2
                    rotation 0 -1 0 1.4400103828041082
                    children [
                      DEF calf_visual CadShape {
                        url [
                          "../protos/meshes/calf.dae"
                        ]
                      }
                      Solid {
                        translation 0 0 -0.2
                        children [
                          Shape {
                            appearance DEF grey PBRAppearance {
                              baseColor 0.5 0.5 0.5
                              roughness 1
                              metalness 0
                            }
                            geometry Sphere {
                              radius 0.01
                            }
                          }
                        ]
                        name "FL_foot"
                        boundingObject Sphere {
                          radius 0.02
                        }
                        physics Physics {
                          density -1
                          mass 0.06
                          centerOfMass [
                            0 0 0
                          ]
                          inertiaMatrix [
                            9.6e-06 9.6e-06 9.6e-06
                            0 0 0
                          ]
                        }
                      }
                    ]
                    name "FL_calf"
                    boundingObject Pose {
                      translation 0 0 -0.1
                      rotation 0 1 0 1.570796
                      children [
                        Box {
                          size 0.2 0.016 0.016
                        }
                      ]
                    }
                    physics Physics {
                      density -1
                      mass 0.166
                      centerOfMass [
                        0.006435 0 -0.107388
                      ]
                      inertiaMatrix [
                        0.002997972 0.003014022 3.2426e-05
                        0 -0.000141163 0
                      ]
                    }
                  }
                }
              ]
              name "FL_thigh"
              boundingObject Pose {
                translation 0 0 -0.1
                rotation 0 1 0 1.570796
                children [
                  Box {
                    size 0.2 0.0245 0.034
                  }
                ]
              }
              physics Physics {
                density -1
                mass 1.013
                centerOfMass [
                  -0.003237 -0.022327 -0.027326
                ]
                inertiaMatrix [
                  0.005529065 0.005139339 0.001367788
                  4.825e-06 0.000343869 2.2448e-05
                ]
              }
            }
          }
        ]
        name "FL_hip"
        boundingObject Pose {
          rotation 1 0 0 1.570796
          children [
            Cylinder {
              height 0.04
              radius 0.046
            }
          ]
        }
        physics Physics {
          density -1
          mass 0.696
          centerOfMass [
            -0.003311 0.000635 3.1e-05
          ]
          inertiaMatrix [
            0.000469246 0.00080749 0.000552929
            -9.409e-06 -3.42e-07 -4.66e-07
          ]
        }
      }
    }
    HingeJoint {
      jointParameters HingeJointParameters {
        position -5.204793072088876e-06
        anchor -0.1805 -0.047 0
      }
      device [
        RotationalMotor {
          name "RR_hip_joint"
          maxVelocity 21
          minPosition -0.8028514559173915
          maxPosition 0.8028514559173915
          maxTorque 33.5
        }
        PositionSensor {
          name "RR_hip_joint_sensor"
        }
      ]
      endPoint Solid {
        translation -0.1805 -0.047 0
        rotation -1 0 0 5.204751848154637e-06
        children [
          Pose {
            rotation 0 0 -1 3.141593
            children [
              DEF hip_visual CadShape {
                url [
                  "../protos/meshes/hip.dae"
                ]
              }
            ]
          }
          Solid {
            translation 0 -0.081 0
            name "RR_thigh_shoulder"
            boundingObject Pose {
              rotation 1 0 0 1.570796
              children [
                Cylinder {
                  height 0.032
                  radius 0.041
                }
              ]
            }
            physics Physics {
              density -1
              mass 0.001
            }
          }
          HingeJoint {
            jointParameters HingeJointParameters {
              position 0.7199988870093683
              axis 0 1 0
              anchor 0 -0.0838 0
            }
            device [
              RotationalMotor {
                name "RR_thigh_joint"
                maxVelocity 21
                minPosition -1.0471975511965976
                maxPosition 4.1887902047863905
                maxTorque 33.5
              }
              PositionSensor {
                name "RR_thigh_joint_sensor"
              }
            ]
            endPoint Solid {
              translation 0 -0.0838 0
              rotation 0 1 0 0.7199988870093683
              children [
                DEF thigh_mirror_visual CadShape {
                  url [
                    "../protos/meshes/thigh_mirror.dae"
                  ]
                }
                HingeJoint {
                  jointParameters HingeJointParameters {
                    position -1.4400112748327225
                    axis 0 1 0
                    anchor 0 0 -0.2
                  }
                  device [
                    RotationalMotor {
                      name "RR_calf_joint"
                      maxVelocity 21
                      minPosition -2.6965336943312392
                      maxPosition -0.9162978572970231
                      maxTorque 33.5
                    }
                    PositionSensor {
                      name "RR_calf_joint_sensor"
                    }
                  ]
                  endPoint Solid {
                    translation 0 0 -0.2
                    rotation 0 -1 0 1.4400112748327223
                    children [
                      DEF calf_visual CadShape {
                        url [
                          "../protos/meshes/calf.dae"
                        ]
                      }
                      Solid {
                        translation 0 0 -0.2
                        children [
                          Shape {
                            appearance DEF grey PBRAppearance {
                              baseColor 0.5 0.5 0.5
                              roughness 1
                              metalness 0
                            }
                            geometry Sphere {
                              radius 0.01
                            }
                          }
                        ]
                        name "RR_foot"
                        boundingObject Sphere {
                          radius 0.02
                        }
                        physics Physics {
                          density -1
                          mass 0.06
                          centerOfMass [
                            0 0 0
                          ]
                          inertiaMatrix [
                            9.6e-06 9.6e-06 9.6e-06
                            0 0 0
                          ]
                        }
                      }
                    ]
                    name "RR_calf"
                    boundingObject Pose {
                      translation 0 0 -0.1
                      rotation 0 1 0 1.570796
                      children [
                        Box {
                          size 0.2 0.016 0.016
                        }
                      ]
                    }
                    physics Physics {
                      density -1
                      mass 0.166
                      centerOfMass [
                        0.006435 0 -0.107388
                      ]
                      inertiaMatrix [
                        0.002997972 0.003014022 3.2426e-05
                        0 -0.000141163 0
                      ]
                    }
                  }
                }
              ]
              name "RR_thigh"
              boundingObject Pose {
                translation 0 0 -0.1
                rotation 0 1 0 1.570796
                children [
                  Box {
                    size 0.2 0.0245 0.034
                  }
                ]
              }
              physics Physics {
                density -1
                mass 1.013
                centerOfMass [
                  -0.003237 0.022327 -0.027326
                ]
                inertiaMatrix [
                  0.005529065 0.005139339 0.001367788
                  -4.825e-06 0.000343869 -2.2448e-05
                ]
              }
            }
          }
        ]
        name "RR_hip"
        boundingObject Pose {
          rotation 1 0 0 1.570796
          children [
            Cylinder {
              height 0.04
              radius 0.046
            }
          ]
        }
        physics Physics {
          density -1
          mass 0.696
          centerOfMass [
            0.003311 -0.000635 3.1e-05
          ]
          inertiaMatrix [
            0.000469246 0.00080749 0.000552929
            -9.409e-06 3.42e-07 4.66e-07
          ]
        }
      }
    }
    HingeJoint {
      jointParameters HingeJointParameters {
        position 5.340167816392997e-06
        anchor -0.1805 0.047 0
      }
      device [
        RotationalMotor {
          name "RL_hip_joint"
          maxVelocity 21
          minPosition -0.8028514559173915
          maxPosition 0.8028514559173915
          maxTorque 33.5
        }
        PositionSensor {
          name "RL_hip_joint_sensor"
        }
      ]
      endPoint Solid {
        translation -0.1805 0.047 0
        rotation 1 0 0 5.340190324300115e-06
        children [
          Pose {
            rotation 0 1 0 3.141593
            children [
              DEF hip_visual CadShape {
                url [
                  "../protos/meshes/hip.dae"
                ]
              }
            ]
          }
          Solid {
            translation 0 0.081 0
            name "RL_thigh_shoulder"
            boundingObject Pose {
              rotation 1 0 0 1.570796
              children [
                Cylinder {
                  height 0.032
                  radius 0.041
                }
              ]
            }
            physics Physics {
              density -1
              mass 0.001
            }
          }
          HingeJoint {
            jointParameters HingeJointParameters {
              position 0.7199988941900503
              axis 0 1 0
              anchor 0 0.0838 0
            }
            device [
              RotationalMotor {
                name "RL_thigh_joint"
                maxVelocity 21
                minPosition -1.0471975511965976
                maxPosition 4.1887902047863905
                maxTorque 33.5
              }
              PositionSensor {
                name "RL_thigh_joint_sensor"
              }
            ]
            endPoint Solid {
              translation 0 0.0838 0
              rotation 0 1 0 0.71999889419005
              children [
                DEF thigh_visual CadShape {
                  url [
                    "../protos/meshes/thigh.dae"
                  ]
                }
                HingeJoint {
                  jointParameters HingeJointParameters {
                    position -1.4400115486339051
                    axis 0 1 0
                    anchor 0 0 -0.2
                  }
                  device [
                    RotationalMotor {
                      name "RL_calf_joint"
                      maxVelocity 21
                      minPosition -2.6965336943312392
                      maxPosition -0.9162978572970231
                      maxTorque 33.5
                    }
                    PositionSensor {
                      name "RL_calf_joint_sensor"
                    }
                  ]
                  endPoint Solid {
                    translation 0 0 -0.2
                    rotation 0 -1 0 1.4400115486339051
                    children [
                      DEF calf_visual CadShape {
                        url [
                          "../protos/meshes/calf.dae"
                        ]
                      }
                      Solid {
                        translation 0 0 -0.2
                        children [
                          Shape {
                            appearance DEF grey PBRAppearance {
                              baseColor 0.5 0.5 0.5
                              roughness 1
                              metalness 0
                            }
                            geometry Sphere {
                              radius 0.01
                            }
                          }
                        ]
                        name "RL_foot"
                        boundingObject Sphere {
                          radius 0.02
                        }
                        physics Physics {
                          density -1
                          mass 0.06
                          centerOfMass [
                            0 0 0
                          ]
                          inertiaMatrix [
                            9.6e-06 9.6e-06 9.6e-06
                            0 0 0
                          ]
                        }
                      }
                    ]
                    name "RL_calf"
                    boundingObject Pose {
                      translation 0 0 -0.1
                      rotation 0 1 0 1.570796
                      children [
                        Box {
                          size 0.2 0.016 0.016
                        }
                      ]
                    }
                    physics Physics {
                      density -1
                      mass 0.166
                      centerOfMass [
                        0.006435 0 -0.107388
                      ]
                      inertiaMatrix [
                        0.002997972 0.003014022 3.2426e-05
                        0 -0.000141163 0
                      ]
                    }
                  }
                }
              ]
              name "RL_thigh"
              boundingObject Pose {
                translation 0 0 -0.1
                rotation 0 1 0 1.570796
                children [
                  Box {
                    size 0.2 0.0245 0.034
                  }
                ]
              }
              physics Physics {
                density -1
                mass 1.013
                centerOfMass [
                  -0.003237 -0.022327 -0.027326
                ]
                inertiaMatrix [
                  0.005529065 0.005139339 0.001367788
                  4.825e-06 0.000343869 2.2448e-05
                ]
              }
            }
          }
        ]
        name "RL_hip"
        boundingObject Pose {
          rotation 1 0 0 1.570796
          children [
            Cylinder {
              height 0.04
              radius 0.046
            }
          ]
        }
        physics Physics {
          density -1
          mass 0.696
          centerOfMass [
            0.003311 0.000635 3.1e-05
          ]
          inertiaMatrix [
            0.000469246 0.00080749 0.000552929
            9.409e-06 3.42e-07 -4.66e-07
          ]
        }
      }
    }
  ]
  name "A1"
  boundingObject Box {
    size 0.267 0.194 0.114
  }
  physics Physics {
    density -1
    mass 6
    centerOfMass [
      0 0.0041 -0.0005
    ]
    inertiaMatrix [
      0.0158533 0.0377999 0.0456542
      -3.66e-05 -6.11e-05 -2.75e-05
    ]
  }
  controller "<extern>"
  supervisor TRUE
  selfCollision TRUE
}
