#VRML_SIM R2023b utf8

EXTERNPROTO "https://raw.githubusercontent.com/cyberbotics/webots/R2023b/projects/objects/backgrounds/protos/TexturedBackground.proto"
EXTERNPROTO "https://raw.githubusercontent.com/cyberbotics/webots/R2023b/projects/objects/backgrounds/protos/TexturedBackgroundLight.proto"
EXTERNPROTO "https://raw.githubusercontent.com/cyberbotics/webots/R2023b/projects/objects/floors/protos/RectangleArena.proto"

WorldInfo {
  basicTimeStep 1
  FPS 30
}
Viewpoint {
  orientation -0.23727452668422924 0.08270736912844902 0.9679154353964118 2.490812741362552
  position 1.2652961965919658 -1.0457127749549346 0.920163487469584
}
TexturedBackground {
}
TexturedBackgroundLight {
}
RectangleArena {
  floorSize 3 3
}
DEF AliengoZ1 Robot {
  translation 0 0 0.12
  children [
    Shape {
      appearance PBRAppearance {
        baseColor 0.5 0.5 0.5
        roughness 1
        metalness 0
      }
      geometry Box {
        size 0.001 0.001 0.001
      }
    }
    DEF trunk_visual CadShape {
      url [
        "/home/zishang/URDF/unitree/robots/aliengoZ1_description/meshes/trunk.dae"
      ]
    }
    Solid {
      children [
        Shape {
          appearance DEF red PBRAppearance {
            baseColor 0.5 0.5 0.5
            roughness 1
            metalness 0
          }
          geometry Box {
            size 0.001 0.001 0.001
          }
        }
        InertialUnit {
          name "trunk_imu inertial"
        }
        Accelerometer {
          name "trunk_imu accelerometer"
        }
        Gyro {
          name "trunk_imu gyro"
        }
        Compass {
          name "trunk_imu compass"
        }
      ]
      name "imu_link"
      boundingObject Box {
        size 0.001 0.001 0.001
      }
      physics Physics {
        density -1
        mass 0.001
        centerOfMass [
          0 0 0
        ]
        inertiaMatrix [
          0.0001 1e-06 0.0001
          0 0 0
        ]
      }
    }
    HingeJoint {
      jointParameters HingeJointParameters {
        position -0.5
        anchor 0.2407 -0.051 0
      }
      device [
        RotationalMotor {
          name "leg1_hip_joint"
          maxVelocity 20
          minPosition -1.2217304763960306
          maxPosition 1.2217304763960306
          maxTorque 35.278
        }
        PositionSensor {
          name "leg1_hip_joint_sensor"
        }
      ]
      endPoint Solid {
        translation 0.2407 -0.051 0
        rotation -1 0 0 0.5000000000000004
        children [
          Pose {
            rotation 1 0 0 3.141593
            children [
              DEF hip_visual CadShape {
                url [
                  "/home/zishang/URDF/unitree/robots/aliengoZ1_description/meshes/hip.dae"
                ]
              }
            ]
          }
          HingeJoint {
            jointParameters HingeJointParameters {
              position 1
              axis 0 1 0
              anchor 0 -0.0868 0
            }
            device [
              RotationalMotor {
                name "leg1_thigh_joint"
                maxVelocity 20
                maxTorque 35.278
              }
              PositionSensor {
                name "leg1_thigh_joint_sensor"
              }
            ]
            endPoint Solid {
              translation 0 -0.0868 0
              rotation 0 1 0 0.9999999999999998
              children [
                DEF thigh_mirror_visual CadShape {
                  url [
                    "/home/zishang/URDF/unitree/robots/aliengoZ1_description/meshes/thigh_mirror.dae"
                  ]
                }
                HingeJoint {
                  jointParameters HingeJointParameters {
                    position -2.5
                    axis 0 1 0
                    anchor 0 0 -0.25
                  }
                  device [
                    RotationalMotor {
                      name "leg1_calf_joint"
                      maxVelocity 15.89
                      minPosition -2.775073510670984
                      maxPosition -0.6457718232379019
                      maxTorque 44.4
                    }
                    PositionSensor {
                      name "leg1_calf_joint_sensor"
                    }
                  ]
                  endPoint Solid {
                    translation 0 0 -0.25
                    rotation 0 -1 0 2.5
                    children [
                      DEF calf_visual CadShape {
                        url [
                          "/home/zishang/URDF/unitree/robots/aliengoZ1_description/meshes/calf.dae"
                        ]
                      }
                      Solid {
                        translation 0 0 -0.25
                        children [
                          Shape {
                            appearance DEF green PBRAppearance {
                              baseColor 0.5 0.5 0.5
                              roughness 1
                              metalness 0
                            }
                            geometry Sphere {
                              radius 0.0165
                            }
                          }
                        ]
                        name "leg1_foot"
                        boundingObject Sphere {
                          radius 0.0265
                        }
                        physics Physics {
                          density -1
                          mass 0.06
                          centerOfMass [
                            0 0 0
                          ]
                          inertiaMatrix [
                            1.6854e-05 1.6854e-05 1.6854e-05
                            0 0 0
                          ]
                        }
                      }
                    ]
                    name "leg1_calf"
                    boundingObject Pose {
                      translation 0 0 -0.125
                      rotation 0 1 0 1.570796
                      children [
                        Box {
                          size 0.25 0.0208 0.016
                        }
                      ]
                    }
                    physics Physics {
                      density -1
                      mass 0.207
                      centerOfMass [
                        0.002781 6.3e-05 -0.142518
                      ]
                      inertiaMatrix [
                        0.002129279 0.002141463 3.7583e-05
                        3.9e-08 5.757e-06 -5.16e-07
                      ]
                    }
                  }
                }
                Solid {
                  translation 0 0.0997 0
                  children [
                    Pose {
                      rotation 1 0 0 1.570796
                      children [
                        Shape {
                          appearance USE green
                          geometry Cylinder {
                            height 0.02
                            radius 0.035
                          }
                        }
                      ]
                    }
                  ]
                  name "leg1_calf_rotor"
                  boundingObject Pose {
                    rotation 1 0 0 1.570796
                    children [
                      Cylinder {
                        height 0.02
                        radius 0.035
                      }
                    ]
                  }
                  physics Physics {
                    density -1
                    mass 0.132
                    centerOfMass [
                      0 0 0
                    ]
                    inertiaMatrix [
                      0.000145463 0.000133031 0.000145463
                      0 0 0
                    ]
                  }
                }
              ]
              name "leg1_thigh"
              boundingObject Pose {
                translation 0 0 -0.125
                rotation 0 1 0 1.570796
                children [
                  Box {
                    size 0.25 0.0374 0.043
                  }
                ]
              }
              physics Physics {
                density -1
                mass 0.639
                centerOfMass [
                  -0.005607 0.003877 -0.048199
                ]
                inertiaMatrix [
                  0.004173855 0.004343802 0.000340136
                  -1.0284e-05 -0.000318874 -0.000109233
                ]
              }
            }
          }
          Solid {
            translation 0 -0.0298 0
            children [
              Pose {
                rotation 1 0 0 1.570796
                children [
                  Shape {
                    appearance USE green
                    geometry Cylinder {
                      height 0.02
                      radius 0.035
                    }
                  }
                ]
              }
            ]
            name "leg1_thigh_rotor"
            boundingObject Pose {
              rotation 1 0 0 1.570796
              children [
                Cylinder {
                  height 0.02
                  radius 0.035
                }
              ]
            }
            physics Physics {
              density -1
              mass 0.146
              centerOfMass [
                0 0 0
              ]
              inertiaMatrix [
                8.3352e-05 0.000138702 8.3352e-05
                0 0 0
              ]
            }
          }
        ]
        name "leg1_hip"
        boundingObject Pose {
          translation 0 -0.083 0
          rotation 1 0 0 1.570796
          children [
            Cylinder {
              height 0.0418
              radius 0.046
            }
          ]
        }
        physics Physics {
          density -1
          mass 1.993
          centerOfMass [
            -0.022191 -0.015144 -1.5e-05
          ]
          inertiaMatrix [
            0.002446735 0.003925876 0.004148145
            0.00059805 1.945e-06 -1.284e-06
          ]
        }
      }
    }
    Solid {
      translation 0.139985 -0.051 0
      children [
        Pose {
          rotation 0 1 0 1.570796
          children [
            Shape {
              appearance DEF green PBRAppearance {
                baseColor 0.5 0.5 0.5
                roughness 1
                metalness 0
              }
              geometry Cylinder {
                height 0.02
                radius 0.035
              }
            }
          ]
        }
      ]
      name "leg1_hip_rotor"
      boundingObject Pose {
        rotation 0 1 0 1.570796
        children [
          Cylinder {
            height 0.02
            radius 0.035
          }
        ]
      }
      physics Physics {
        density -1
        mass 0.146
        centerOfMass [
          0 0 0
        ]
        inertiaMatrix [
          0.000138702 8.3352e-05 8.3352e-05
          0 0 0
        ]
      }
    }
    HingeJoint {
      jointParameters HingeJointParameters {
        position -0.5
        anchor -0.2407 -0.051 0
      }
      device [
        RotationalMotor {
          name "leg2_hip_joint"
          maxVelocity 20
          minPosition -1.2217304763960306
          maxPosition 1.2217304763960306
          maxTorque 35.278
        }
        PositionSensor {
          name "leg2_hip_joint_sensor"
        }
      ]
      endPoint Solid {
        translation -0.2407 -0.051 0
        rotation -1 0 0 0.5000000000000004
        children [
          Pose {
            rotation 0 0 -1 3.141593
            children [
              DEF hip_visual CadShape {
                url [
                  "/home/zishang/URDF/unitree/robots/aliengoZ1_description/meshes/hip.dae"
                ]
              }
            ]
          }
          HingeJoint {
            jointParameters HingeJointParameters {
              position 1
              axis 0 1 0
              anchor 0 -0.0868 0
            }
            device [
              RotationalMotor {
                name "leg2_thigh_joint"
                maxVelocity 20
                maxTorque 35.278
              }
              PositionSensor {
                name "leg2_thigh_joint_sensor"
              }
            ]
            endPoint Solid {
              translation 0 -0.0868 0
              rotation 0 1 0 0.9999999999999998
              children [
                DEF thigh_mirror_visual CadShape {
                  url [
                    "/home/zishang/URDF/unitree/robots/aliengoZ1_description/meshes/thigh_mirror.dae"
                  ]
                }
                HingeJoint {
                  jointParameters HingeJointParameters {
                    position -2.5
                    axis 0 1 0
                    anchor 0 0 -0.25
                  }
                  device [
                    RotationalMotor {
                      name "leg2_calf_joint"
                      maxVelocity 15.89
                      minPosition -2.775073510670984
                      maxPosition -0.6457718232379019
                      maxTorque 44.4
                    }
                    PositionSensor {
                      name "leg2_calf_joint_sensor"
                    }
                  ]
                  endPoint Solid {
                    translation 0 0 -0.25
                    rotation 0 -1 0 2.5
                    children [
                      DEF calf_visual CadShape {
                        url [
                          "/home/zishang/URDF/unitree/robots/aliengoZ1_description/meshes/calf.dae"
                        ]
                      }
                      Solid {
                        translation 0 0 -0.25
                        children [
                          Shape {
                            appearance DEF green PBRAppearance {
                              baseColor 0.5 0.5 0.5
                              roughness 1
                              metalness 0
                            }
                            geometry Sphere {
                              radius 0.0165
                            }
                          }
                        ]
                        name "leg2_foot"
                        boundingObject Sphere {
                          radius 0.0265
                        }
                        physics Physics {
                          density -1
                          mass 0.06
                          centerOfMass [
                            0 0 0
                          ]
                          inertiaMatrix [
                            1.6854e-05 1.6854e-05 1.6854e-05
                            0 0 0
                          ]
                        }
                      }
                    ]
                    name "leg2_calf"
                    boundingObject Pose {
                      translation 0 0 -0.125
                      rotation 0 1 0 1.570796
                      children [
                        Box {
                          size 0.25 0.0208 0.016
                        }
                      ]
                    }
                    physics Physics {
                      density -1
                      mass 0.207
                      centerOfMass [
                        0.002781 6.3e-05 -0.142518
                      ]
                      inertiaMatrix [
                        0.002129279 0.002141463 3.7583e-05
                        3.9e-08 5.757e-06 -5.16e-07
                      ]
                    }
                  }
                }
                Solid {
                  translation 0 0.0997 0
                  children [
                    Pose {
                      rotation 1 0 0 1.570796
                      children [
                        Shape {
                          appearance USE green
                          geometry Cylinder {
                            height 0.02
                            radius 0.035
                          }
                        }
                      ]
                    }
                  ]
                  name "leg2_calf_rotor"
                  boundingObject Pose {
                    rotation 1 0 0 1.570796
                    children [
                      Cylinder {
                        height 0.02
                        radius 0.035
                      }
                    ]
                  }
                  physics Physics {
                    density -1
                    mass 0.132
                    centerOfMass [
                      0 0 0
                    ]
                    inertiaMatrix [
                      0.000145463 0.000133031 0.000145463
                      0 0 0
                    ]
                  }
                }
              ]
              name "leg2_thigh"
              boundingObject Pose {
                translation 0 0 -0.125
                rotation 0 1 0 1.570796
                children [
                  Box {
                    size 0.25 0.0374 0.043
                  }
                ]
              }
              physics Physics {
                density -1
                mass 0.639
                centerOfMass [
                  -0.005607 0.003877 -0.048199
                ]
                inertiaMatrix [
                  0.004173855 0.004343802 0.000340136
                  -1.0284e-05 -0.000318874 -0.000109233
                ]
              }
            }
          }
          Solid {
            translation 0 -0.0298 0
            children [
              Pose {
                rotation 1 0 0 1.570796
                children [
                  Shape {
                    appearance USE green
                    geometry Cylinder {
                      height 0.02
                      radius 0.035
                    }
                  }
                ]
              }
            ]
            name "leg2_thigh_rotor"
            boundingObject Pose {
              rotation 1 0 0 1.570796
              children [
                Cylinder {
                  height 0.02
                  radius 0.035
                }
              ]
            }
            physics Physics {
              density -1
              mass 0.146
              centerOfMass [
                0 0 0
              ]
              inertiaMatrix [
                8.3352e-05 0.000138702 8.3352e-05
                0 0 0
              ]
            }
          }
        ]
        name "leg2_hip"
        boundingObject Pose {
          translation 0 -0.083 0
          rotation 1 0 0 1.570796
          children [
            Cylinder {
              height 0.0418
              radius 0.046
            }
          ]
        }
        physics Physics {
          density -1
          mass 1.993
          centerOfMass [
            0.022191 -0.015144 -1.5e-05
          ]
          inertiaMatrix [
            0.002446735 0.003925876 0.004148145
            -0.00059805 -1.945e-06 -1.284e-06
          ]
        }
      }
    }
    Solid {
      translation -0.139985 -0.051 0
      children [
        Pose {
          rotation 0 1 0 1.570796
          children [
            Shape {
              appearance DEF green PBRAppearance {
                baseColor 0.5 0.5 0.5
                roughness 1
                metalness 0
              }
              geometry Cylinder {
                height 0.02
                radius 0.035
              }
            }
          ]
        }
      ]
      name "leg2_hip_rotor"
      boundingObject Pose {
        rotation 0 1 0 1.570796
        children [
          Cylinder {
            height 0.02
            radius 0.035
          }
        ]
      }
      physics Physics {
        density -1
        mass 0.146
        centerOfMass [
          0 0 0
        ]
        inertiaMatrix [
          0.000138702 8.3352e-05 8.3352e-05
          0 0 0
        ]
      }
    }
    HingeJoint {
      jointParameters HingeJointParameters {
        position 0.5
        anchor 0.2407 0.051 0
      }
      device [
        RotationalMotor {
          name "leg3_hip_joint"
          maxVelocity 20
          minPosition -1.2217304763960306
          maxPosition 1.2217304763960306
          maxTorque 35.278
        }
        PositionSensor {
          name "leg3_hip_joint_sensor"
        }
      ]
      endPoint Solid {
        translation 0.2407 0.051 0
        rotation 1 0 0 0.5000000000000004
        children [
          DEF hip_visual CadShape {
            url [
              "/home/zishang/URDF/unitree/robots/aliengoZ1_description/meshes/hip.dae"
            ]
          }
          HingeJoint {
            jointParameters HingeJointParameters {
              position 1
              axis 0 1 0
              anchor 0 0.0868 0
            }
            device [
              RotationalMotor {
                name "leg3_thigh_joint"
                maxVelocity 20
                maxTorque 35.278
              }
              PositionSensor {
                name "leg3_thigh_joint_sensor"
              }
            ]
            endPoint Solid {
              translation 0 0.0868 0
              rotation 0 1 0 0.9999999999999998
              children [
                DEF thigh_visual CadShape {
                  url [
                    "/home/zishang/URDF/unitree/robots/aliengoZ1_description/meshes/thigh.dae"
                  ]
                }
                HingeJoint {
                  jointParameters HingeJointParameters {
                    position -2.5
                    axis 0 1 0
                    anchor 0 0 -0.25
                  }
                  device [
                    RotationalMotor {
                      name "leg3_calf_joint"
                      maxVelocity 15.89
                      minPosition -2.775073510670984
                      maxPosition -0.6457718232379019
                      maxTorque 44.4
                    }
                    PositionSensor {
                      name "leg3_calf_joint_sensor"
                    }
                  ]
                  endPoint Solid {
                    translation 0 0 -0.25
                    rotation 0 -1 0 2.5
                    children [
                      DEF calf_visual CadShape {
                        url [
                          "/home/zishang/URDF/unitree/robots/aliengoZ1_description/meshes/calf.dae"
                        ]
                      }
                      Solid {
                        translation 0 0 -0.25
                        children [
                          Shape {
                            appearance DEF green PBRAppearance {
                              baseColor 0.5 0.5 0.5
                              roughness 1
                              metalness 0
                            }
                            geometry Sphere {
                              radius 0.0165
                            }
                          }
                        ]
                        name "leg3_foot"
                        boundingObject Sphere {
                          radius 0.0265
                        }
                        physics Physics {
                          density -1
                          mass 0.06
                          centerOfMass [
                            0 0 0
                          ]
                          inertiaMatrix [
                            1.6854e-05 1.6854e-05 1.6854e-05
                            0 0 0
                          ]
                        }
                      }
                    ]
                    name "leg3_calf"
                    boundingObject Pose {
                      translation 0 0 -0.125
                      rotation 0 1 0 1.570796
                      children [
                        Box {
                          size 0.25 0.0208 0.016
                        }
                      ]
                    }
                    physics Physics {
                      density -1
                      mass 0.207
                      centerOfMass [
                        0.002781 6.3e-05 -0.142518
                      ]
                      inertiaMatrix [
                        0.002129279 0.002141463 3.7583e-05
                        3.9e-08 5.757e-06 -5.16e-07
                      ]
                    }
                  }
                }
                Solid {
                  translation 0 -0.0997 0
                  children [
                    Pose {
                      rotation 1 0 0 1.570796
                      children [
                        Shape {
                          appearance USE green
                          geometry Cylinder {
                            height 0.02
                            radius 0.035
                          }
                        }
                      ]
                    }
                  ]
                  name "leg3_calf_rotor"
                  boundingObject Pose {
                    rotation 1 0 0 1.570796
                    children [
                      Cylinder {
                        height 0.02
                        radius 0.035
                      }
                    ]
                  }
                  physics Physics {
                    density -1
                    mass 0.132
                    centerOfMass [
                      0 0 0
                    ]
                    inertiaMatrix [
                      0.000145463 0.000133031 0.000145463
                      0 0 0
                    ]
                  }
                }
              ]
              name "leg3_thigh"
              boundingObject Pose {
                translation 0 0 -0.125
                rotation 0 1 0 1.570796
                children [
                  Box {
                    size 0.25 0.0374 0.043
                  }
                ]
              }
              physics Physics {
                density -1
                mass 0.639
                centerOfMass [
                  -0.005607 -0.003877 -0.048199
                ]
                inertiaMatrix [
                  0.004173855 0.004343802 0.000340136
                  1.0284e-05 -0.000318874 0.000109233
                ]
              }
            }
          }
          Solid {
            translation 0 0.0298 0
            children [
              Pose {
                rotation 1 0 0 1.570796
                children [
                  Shape {
                    appearance USE green
                    geometry Cylinder {
                      height 0.02
                      radius 0.035
                    }
                  }
                ]
              }
            ]
            name "leg3_thigh_rotor"
            boundingObject Pose {
              rotation 1 0 0 1.570796
              children [
                Cylinder {
                  height 0.02
                  radius 0.035
                }
              ]
            }
            physics Physics {
              density -1
              mass 0.146
              centerOfMass [
                0 0 0
              ]
              inertiaMatrix [
                8.3352e-05 0.000138702 8.3352e-05
                0 0 0
              ]
            }
          }
        ]
        name "leg3_hip"
        boundingObject Pose {
          translation 0 0.083 0
          rotation 1 0 0 1.570796
          children [
            Cylinder {
              height 0.0418
              radius 0.046
            }
          ]
        }
        physics Physics {
          density -1
          mass 1.993
          centerOfMass [
            -0.022191 0.015144 -1.5e-05
          ]
          inertiaMatrix [
            0.002446735 0.003925876 0.004148145
            -0.00059805 1.945e-06 1.284e-06
          ]
        }
      }
    }
    Solid {
      translation 0.139985 0.051 0
      children [
        Pose {
          rotation 0 1 0 1.570796
          children [
            Shape {
              appearance DEF green PBRAppearance {
                baseColor 0.5 0.5 0.5
                roughness 1
                metalness 0
              }
              geometry Cylinder {
                height 0.02
                radius 0.035
              }
            }
          ]
        }
      ]
      name "leg3_hip_rotor"
      boundingObject Pose {
        rotation 0 1 0 1.570796
        children [
          Cylinder {
            height 0.02
            radius 0.035
          }
        ]
      }
      physics Physics {
        density -1
        mass 0.146
        centerOfMass [
          0 0 0
        ]
        inertiaMatrix [
          0.000138702 8.3352e-05 8.3352e-05
          0 0 0
        ]
      }
    }
    HingeJoint {
      jointParameters HingeJointParameters {
        position 0.5
        anchor -0.2407 0.051 0
      }
      device [
        RotationalMotor {
          name "leg4_hip_joint"
          maxVelocity 20
          minPosition -1.2217304763960306
          maxPosition 1.2217304763960306
          maxTorque 35.278
        }
        PositionSensor {
          name "leg4_hip_joint_sensor"
        }
      ]
      endPoint Solid {
        translation -0.2407 0.051 0
        rotation 1 0 0 0.5000000000000004
        children [
          Pose {
            rotation 0 1 0 3.141593
            children [
              DEF hip_visual CadShape {
                url [
                  "/home/zishang/URDF/unitree/robots/aliengoZ1_description/meshes/hip.dae"
                ]
              }
            ]
          }
          HingeJoint {
            jointParameters HingeJointParameters {
              position 1
              axis 0 1 0
              anchor 0 0.0868 0
            }
            device [
              RotationalMotor {
                name "leg4_thigh_joint"
                maxVelocity 20
                maxTorque 35.278
              }
              PositionSensor {
                name "leg4_thigh_joint_sensor"
              }
            ]
            endPoint Solid {
              translation 0 0.0868 0
              rotation 0 1 0 0.9999999999999998
              children [
                DEF thigh_visual CadShape {
                  url [
                    "/home/zishang/URDF/unitree/robots/aliengoZ1_description/meshes/thigh.dae"
                  ]
                }
                HingeJoint {
                  jointParameters HingeJointParameters {
                    position -2.5
                    axis 0 1 0
                    anchor 0 0 -0.25
                  }
                  device [
                    RotationalMotor {
                      name "leg4_calf_joint"
                      maxVelocity 15.89
                      minPosition -2.775073510670984
                      maxPosition -0.6457718232379019
                      maxTorque 44.4
                    }
                    PositionSensor {
                      name "leg4_calf_joint_sensor"
                    }
                  ]
                  endPoint Solid {
                    translation 0 0 -0.25
                    rotation 0 -1 0 2.5
                    children [
                      DEF calf_visual CadShape {
                        url [
                          "/home/zishang/URDF/unitree/robots/aliengoZ1_description/meshes/calf.dae"
                        ]
                      }
                      Solid {
                        translation 0 0 -0.25
                        children [
                          Shape {
                            appearance DEF green PBRAppearance {
                              baseColor 0.5 0.5 0.5
                              roughness 1
                              metalness 0
                            }
                            geometry Sphere {
                              radius 0.0165
                            }
                          }
                        ]
                        name "leg4_foot"
                        boundingObject Sphere {
                          radius 0.0265
                        }
                        physics Physics {
                          density -1
                          mass 0.06
                          centerOfMass [
                            0 0 0
                          ]
                          inertiaMatrix [
                            1.6854e-05 1.6854e-05 1.6854e-05
                            0 0 0
                          ]
                        }
                      }
                    ]
                    name "leg4_calf"
                    boundingObject Pose {
                      translation 0 0 -0.125
                      rotation 0 1 0 1.570796
                      children [
                        Box {
                          size 0.25 0.0208 0.016
                        }
                      ]
                    }
                    physics Physics {
                      density -1
                      mass 0.207
                      centerOfMass [
                        0.002781 6.3e-05 -0.142518
                      ]
                      inertiaMatrix [
                        0.002129279 0.002141463 3.7583e-05
                        3.9e-08 5.757e-06 -5.16e-07
                      ]
                    }
                  }
                }
                Solid {
                  translation 0 -0.0997 0
                  children [
                    Pose {
                      rotation 1 0 0 1.570796
                      children [
                        Shape {
                          appearance USE green
                          geometry Cylinder {
                            height 0.02
                            radius 0.035
                          }
                        }
                      ]
                    }
                  ]
                  name "leg4_calf_rotor"
                  boundingObject Pose {
                    rotation 1 0 0 1.570796
                    children [
                      Cylinder {
                        height 0.02
                        radius 0.035
                      }
                    ]
                  }
                  physics Physics {
                    density -1
                    mass 0.132
                    centerOfMass [
                      0 0 0
                    ]
                    inertiaMatrix [
                      0.000145463 0.000133031 0.000145463
                      0 0 0
                    ]
                  }
                }
              ]
              name "leg4_thigh"
              boundingObject Pose {
                translation 0 0 -0.125
                rotation 0 1 0 1.570796
                children [
                  Box {
                    size 0.25 0.0374 0.043
                  }
                ]
              }
              physics Physics {
                density -1
                mass 0.639
                centerOfMass [
                  -0.005607 -0.003877 -0.048199
                ]
                inertiaMatrix [
                  0.004173855 0.004343802 0.000340136
                  1.0284e-05 -0.000318874 0.000109233
                ]
              }
            }
          }
          Solid {
            translation 0 0.0298 0
            children [
              Pose {
                rotation 1 0 0 1.570796
                children [
                  Shape {
                    appearance USE green
                    geometry Cylinder {
                      height 0.02
                      radius 0.035
                    }
                  }
                ]
              }
            ]
            name "leg4_thigh_rotor"
            boundingObject Pose {
              rotation 1 0 0 1.570796
              children [
                Cylinder {
                  height 0.02
                  radius 0.035
                }
              ]
            }
            physics Physics {
              density -1
              mass 0.146
              centerOfMass [
                0 0 0
              ]
              inertiaMatrix [
                8.3352e-05 0.000138702 8.3352e-05
                0 0 0
              ]
            }
          }
        ]
        name "leg4_hip"
        boundingObject Pose {
          translation 0 0.083 0
          rotation 1 0 0 1.570796
          children [
            Cylinder {
              height 0.0418
              radius 0.046
            }
          ]
        }
        physics Physics {
          density -1
          mass 1.993
          centerOfMass [
            0.022191 0.015144 -1.5e-05
          ]
          inertiaMatrix [
            0.002446735 0.003925876 0.004148145
            0.00059805 -1.945e-06 1.284e-06
          ]
        }
      }
    }
    Solid {
      translation -0.139985 0.051 0
      children [
        Pose {
          rotation 0 1 0 1.570796
          children [
            Shape {
              appearance DEF green PBRAppearance {
                baseColor 0.5 0.5 0.5
                roughness 1
                metalness 0
              }
              geometry Cylinder {
                height 0.02
                radius 0.035
              }
            }
          ]
        }
      ]
      name "leg4_hip_rotor"
      boundingObject Pose {
        rotation 0 1 0 1.570796
        children [
          Cylinder {
            height 0.02
            radius 0.035
          }
        ]
      }
      physics Physics {
        density -1
        mass 0.146
        centerOfMass [
          0 0 0
        ]
        inertiaMatrix [
          0.000138702 8.3352e-05 8.3352e-05
          0 0 0
        ]
      }
    }
  ]
  name "AliengoZ1"
  boundingObject Box {
    size 0.647 0.15 0.112
  }
  physics Physics {
    density -1
    mass 11.644
    centerOfMass [
      0.008811 0.003839 0.000273
    ]
    inertiaMatrix [
      0.05194489 0.2469392 0.2709483
      0.001703617 0.000235941 0.000119783
    ]
  }
  controller "<extern>"
  supervisor TRUE
}
