#VRML_SIM R2025a utf8
# license: Apache License 2.0
# license url: http://www.apache.org/licenses/LICENSE-2.0
# This is a proto file for Webots for the GalileoMiniDescription
# Extracted from: ./urdf/robot.urdf

PROTO GalileoMiniDescription [
  field  SFVec3f     translation     0 0 0
  field  SFRotation  rotation        0 0 1 0
  field  SFString    name            "GalileoMiniDescription"  # Is `Robot.name`.
  field  SFString    controller      "void"                    # Is `Robot.controller`.
  field  MFString    controllerArgs  []                        # Is `Robot.controllerArgs`.
  field  SFString    customData      ""                        # Is `Robot.customData`.
  field  SFBool      supervisor      FALSE                     # Is `Robot.supervisor`.
  field  SFBool      synchronization TRUE                      # Is `Robot.synchronization`.
  field  SFBool      selfCollision   FALSE                     # Is `Robot.selfCollision`.
]
{
  Robot {
    translation IS translation
    rotation IS rotation
    controller IS controller
    controllerArgs IS controllerArgs
    customData IS customData
    supervisor IS supervisor
    synchronization IS synchronization
    selfCollision IS selfCollision
    children [
      Shape {
        appearance DEF base_link_material PBRAppearance {
          baseColor 0.752940 0.752940 0.752940
          roughness 1.000000
          metalness 0
        }
        geometry DEF base_link Mesh {
          url "./meshes/base_link.STL"
        }
      }
      HingeJoint {
        jointParameters HingeJointParameters {
          anchor 0.201500 0.080000 0.000000
        }
        device [
          RotationalMotor {
            name "FL_abd_joint"
            maxVelocity 21.0
            minPosition -0.80285
            maxPosition 0.80285
            maxTorque 100.0
          }
          PositionSensor {
            name "FL_abd_joint_sensor"
          }
        ]
        endPoint Solid {
          translation 0.201500 0.080000 0.000000
          children [
            Shape {
              appearance DEF FL_abd_link_material PBRAppearance {
                baseColor 0.752940 0.752940 0.752940
                roughness 1.000000
                metalness 0
              }
              geometry DEF FL_abd_link Mesh {
                url "./meshes/FL_abd_link.STL"
              }
            }
            HingeJoint {
              jointParameters HingeJointParameters {
                axis 0.000000 1.000000 0.000000
                anchor 0.100000 0.106500 0.000000
              }
              device [
                RotationalMotor {
                  name "FL_hip_joint"
                  maxVelocity 21.0
                  minPosition -1.0472
                  maxPosition 4.1888
                  maxTorque 100.0
                }
                PositionSensor {
                  name "FL_hip_joint_sensor"
                }
              ]
              endPoint Solid {
                translation 0.100000 0.106500 0.000000
                children [
                  Shape {
                    appearance DEF FL_hip_link_material PBRAppearance {
                      baseColor 0.752940 0.752940 0.752940
                      roughness 1.000000
                      metalness 0
                    }
                    geometry DEF FL_hip_link Mesh {
                      url "./meshes/FL_hip_link.STL"
                    }
                  }
                  HingeJoint {
                    jointParameters HingeJointParameters {
                      position -1.806400
                      axis 0.000000 1.000000 0.000000
                      anchor 0.000000 0.000000 -0.260000
                    }
                    device [
                      RotationalMotor {
                        name "FL_knee_joint"
                        maxVelocity 21.0
                        minPosition -2.6965
                        maxPosition -0.9163
                        maxTorque 150.0
                      }
                      PositionSensor {
                        name "FL_knee_joint_sensor"
                      }
                    ]
                    endPoint Solid {
                      translation 0.000000 0.000000 -0.260000
                      rotation 0.000000 -1.000000 0.000000 1.806400
                      children [
                        Shape {
                          appearance DEF FL_knee_link_material PBRAppearance {
                            baseColor 0.752940 0.752940 0.752940
                            roughness 1.000000
                            metalness 0
                          }
                          geometry DEF FL_knee_link Mesh {
                            url "./meshes/FL_knee_link.STL"
                          }
                        }
                        Solid {
                          translation 0.032939 0.000000 -0.261490
                          children [
                            Shape {
                              appearance DEF FL_foot_link_material PBRAppearance {
                                roughness 1.000000
                                metalness 0
                              }
                              geometry Sphere {
                                radius 0.03
                              }
                            }
                          ]
                          name "FL_foot_link"
                          boundingObject Sphere {
                            radius 0.03
                          }
                          physics Physics {
                            density -1
                            mass 0.000205
                            centerOfMass [ -0.000000 0.000000 0.000000 ]
                            inertiaMatrix [
                              1.096000e-09 1.096000e-09 1.096000e-09
                              -2.039200e-56 0.000000e+00 0.000000e+00
                            ]
                          }
                        }
                      ]
                      name "FL_knee_link"
                      boundingObject Pose {
                        translation 0.016470 0.000000 -0.130000
                        rotation 0.000000 -1.000000 0.000000 0.174530
                        children [
                          Box {
                             size 0.050000 0.030000 0.230000
                          }
                        ]
                      }
                      physics Physics {
                        density -1
                        mass 0.314000
                        centerOfMass [ 0.017829 -0.000016 -0.099213 ]
                        inertiaMatrix [
                          3.733000e-03 3.882000e-03 1.770000e-04
                          -8.700000e-08 -6.000000e-04 8.380000e-07
                        ]
                      }
                    }
                  }
                ]
                name "FL_hip_link"
                boundingObject Pose {
                  translation -0.025000 0.000000 -0.080000
                  children [
                    Box {
                       size 0.060000 0.035000 0.260000
                    }
                  ]
                }
                physics Physics {
                  density -1
                  mass 2.600000
                  centerOfMass [ -0.009099 -0.006529 -0.068800 ]
                  inertiaMatrix [
                    1.684800e-02 1.674900e-02 2.088000e-03
                    -3.100000e-04 1.116000e-03 -2.270000e-03
                  ]
                }
              }
            }
          ]
          name "FL_abd_link"
          boundingObject Pose {
            translation 0.100000 0.033250 0.000000
            rotation 1.000000 0.000000 0.000000 1.570796
            children [
              Cylinder {
                radius 0.06
                height 0.1065
              }
            ]
          }
          physics Physics {
            density -1
            mass 2.860000
            centerOfMass [ 0.067568 0.009593 0.000014 ]
            inertiaMatrix [
              4.368000e-03 7.476000e-03 6.777000e-03
              3.620000e-04 1.140000e-04 3.500000e-05
            ]
          }
        }
      }
      HingeJoint {
        jointParameters HingeJointParameters {
          anchor 0.201500 -0.080000 0.000000
        }
        device [
          RotationalMotor {
            name "FR_abd_joint"
            maxVelocity 21.0
            minPosition -0.80285
            maxPosition 0.80285
            maxTorque 100.0
          }
          PositionSensor {
            name "FR_abd_joint_sensor"
          }
        ]
        endPoint Solid {
          translation 0.201500 -0.080000 0.000000
          children [
            Shape {
              appearance DEF FR_abd_link_material PBRAppearance {
                baseColor 0.752940 0.752940 0.752940
                roughness 1.000000
                metalness 0
              }
              geometry DEF FR_abd_link Mesh {
                url "./meshes/FR_abd_link.STL"
              }
            }
            HingeJoint {
              jointParameters HingeJointParameters {
                axis 0.000000 1.000000 0.000000
                anchor 0.100000 -0.106850 0.000000
              }
              device [
                RotationalMotor {
                  name "FR_hip_joint"
                  maxVelocity 21.0
                  minPosition -1.0472
                  maxPosition 4.1888
                  maxTorque 100.0
                }
                PositionSensor {
                  name "FR_hip_joint_sensor"
                }
              ]
              endPoint Solid {
                translation 0.100000 -0.106850 0.000000
                children [
                  Shape {
                    appearance DEF FR_hip_link_material PBRAppearance {
                      baseColor 0.752940 0.752940 0.752940
                      roughness 1.000000
                      metalness 0
                    }
                    geometry DEF FR_hip_link Mesh {
                      url "./meshes/FR_hip_link.STL"
                    }
                  }
                  HingeJoint {
                    jointParameters HingeJointParameters {
                      position -1.806400
                      axis 0.000000 1.000000 0.000000
                      anchor 0.000000 0.000000 -0.260000
                    }
                    device [
                      RotationalMotor {
                        name "FR_knee_joint"
                        maxVelocity 21.0
                        minPosition -2.6965
                        maxPosition -0.9163
                        maxTorque 150.0
                      }
                      PositionSensor {
                        name "FR_knee_joint_sensor"
                      }
                    ]
                    endPoint Solid {
                      translation 0.000000 0.000000 -0.260000
                      rotation 0.000000 -1.000000 0.000000 1.806400
                      children [
                        Shape {
                          appearance DEF FR_knee_link_material PBRAppearance {
                            baseColor 0.752940 0.752940 0.752940
                            roughness 1.000000
                            metalness 0
                          }
                          geometry DEF FR_knee_link Mesh {
                            url "./meshes/FR_knee_link.STL"
                          }
                        }
                        Solid {
                          translation 0.032939 0.000000 -0.261490
                          children [
                            Shape {
                              appearance DEF FR_foot_link_material PBRAppearance {
                                roughness 1.000000
                                metalness 0
                              }
                              geometry Sphere {
                                radius 0.03
                              }
                            }
                          ]
                          name "FR_foot_link"
                          boundingObject Sphere {
                            radius 0.03
                          }
                          physics Physics {
                            density -1
                            mass 0.000205
                            centerOfMass [ 0.000000 0.000000 0.000000 ]
                            inertiaMatrix [
                              1.096000e-09 1.096000e-09 1.096000e-09
                              0.000000e+00 1.715200e-40 0.000000e+00
                            ]
                          }
                        }
                      ]
                      name "FR_knee_link"
                      boundingObject Pose {
                        translation 0.016470 0.000000 -0.130000
                        rotation 0.000000 -1.000000 0.000000 0.174530
                        children [
                          Box {
                             size 0.050000 0.030000 0.230000
                          }
                        ]
                      }
                      physics Physics {
                        density -1
                        mass 0.314000
                        centerOfMass [ 0.017829 -0.000016 -0.099213 ]
                        inertiaMatrix [
                          3.733000e-03 3.882000e-03 1.770000e-04
                          -8.700000e-08 -6.000000e-04 8.380000e-07
                        ]
                      }
                    }
                  }
                ]
                name "FR_hip_link"
                boundingObject Pose {
                  translation -0.025000 0.000000 -0.080000
                  children [
                    Box {
                       size 0.060000 0.035000 0.260000
                    }
                  ]
                }
                physics Physics {
                  density -1
                  mass 2.600000
                  centerOfMass [ -0.009534 0.026092 -0.067392 ]
                  inertiaMatrix [
                    1.626100e-02 1.638900e-02 2.194000e-03
                    2.840000e-04 1.143000e-03 2.508000e-03
                  ]
                }
              }
            }
          ]
          name "FR_abd_link"
          boundingObject Pose {
            translation 0.100000 -0.033250 0.000000
            rotation 1.000000 0.000000 0.000000 1.570796
            children [
              Cylinder {
                radius 0.06
                height 0.1065
              }
            ]
          }
          physics Physics {
            density -1
            mass 2.860000
            centerOfMass [ 0.067568 -0.009176 -0.000237 ]
            inertiaMatrix [
              4.373000e-03 7.483000e-03 6.775000e-03
              -3.970000e-04 -9.600000e-05 3.000000e-05
            ]
          }
        }
      }
      HingeJoint {
        jointParameters HingeJointParameters {
          anchor -0.201500 -0.080000 0.000000
        }
        device [
          RotationalMotor {
            name "HR_abd_joint"
            maxVelocity 21.0
            minPosition -0.80285
            maxPosition 0.80285
            maxTorque 100.0
          }
          PositionSensor {
            name "HR_abd_joint_sensor"
          }
        ]
        endPoint Solid {
          translation -0.201500 -0.080000 0.000000
          children [
            Shape {
              appearance DEF HR_abd_link_material PBRAppearance {
                baseColor 0.752940 0.752940 0.752940
                roughness 1.000000
                metalness 0
              }
              geometry DEF HR_abd_link Mesh {
                url "./meshes/HR_abd_link.STL"
              }
            }
            HingeJoint {
              jointParameters HingeJointParameters {
                axis 0.000000 1.000000 0.000000
                anchor -0.100000 -0.106850 0.000000
              }
              device [
                RotationalMotor {
                  name "HR_hip_joint"
                  maxVelocity 21.0
                  minPosition -1.0472
                  maxPosition 4.1888
                  maxTorque 100.0
                }
                PositionSensor {
                  name "HR_hip_joint_sensor"
                }
              ]
              endPoint Solid {
                translation -0.100000 -0.106850 0.000000
                children [
                  Shape {
                    appearance DEF HR_hip_link_material PBRAppearance {
                      baseColor 0.752940 0.752940 0.752940
                      roughness 1.000000
                      metalness 0
                    }
                    geometry DEF HR_hip_link Mesh {
                      url "./meshes/HR_hip_link.STL"
                    }
                  }
                  HingeJoint {
                    jointParameters HingeJointParameters {
                      position -1.806400
                      axis 0.000000 1.000000 0.000000
                      anchor 0.000000 0.000000 -0.260000
                    }
                    device [
                      RotationalMotor {
                        name "HR_knee_joint"
                        maxVelocity 21.0
                        minPosition -2.6965
                        maxPosition -0.9163
                        maxTorque 150.0
                      }
                      PositionSensor {
                        name "HR_knee_joint_sensor"
                      }
                    ]
                    endPoint Solid {
                      translation 0.000000 0.000000 -0.260000
                      rotation 0.000000 -1.000000 0.000000 1.806400
                      children [
                        Shape {
                          appearance DEF HR_knee_link_material PBRAppearance {
                            baseColor 0.752940 0.752940 0.752940
                            roughness 1.000000
                            metalness 0
                          }
                          geometry DEF HR_knee_link Mesh {
                            url "./meshes/HR_knee_link.STL"
                          }
                        }
                        Solid {
                          translation 0.032939 0.000000 -0.261490
                          children [
                            Shape {
                              appearance DEF HR_foot_link_material PBRAppearance {
                                roughness 1.000000
                                metalness 0
                              }
                              geometry Sphere {
                                radius 0.03
                              }
                            }
                          ]
                          name "HR_foot_link"
                          boundingObject Sphere {
                            radius 0.03
                          }
                          physics Physics {
                            density -1
                            mass 0.000205
                            centerOfMass [ 0.000000 0.000000 0.000000 ]
                            inertiaMatrix [
                              1.096001e-09 1.096001e-09 1.096001e-09
                              0.000000e+00 5.284431e-42 0.000000e+00
                            ]
                          }
                        }
                      ]
                      name "HR_knee_link"
                      boundingObject Pose {
                        translation 0.016470 0.000000 -0.130000
                        rotation 0.000000 -1.000000 0.000000 0.174530
                        children [
                          Box {
                             size 0.050000 0.030000 0.230000
                          }
                        ]
                      }
                      physics Physics {
                        density -1
                        mass 0.314000
                        centerOfMass [ 0.017829 -0.000016 -0.099213 ]
                        inertiaMatrix [
                          3.733000e-03 3.882000e-03 1.770000e-04
                          -8.700000e-08 -6.000000e-04 8.380000e-07
                        ]
                      }
                    }
                  }
                ]
                name "HR_hip_link"
                boundingObject Pose {
                  translation -0.025000 0.000000 -0.080000
                  children [
                    Box {
                       size 0.060000 0.035000 0.260000
                    }
                  ]
                }
                physics Physics {
                  density -1
                  mass 2.600000
                  centerOfMass [ -0.009805 0.020667 -0.067167 ]
                  inertiaMatrix [
                    1.714400e-02 1.650800e-02 2.907000e-03
                    1.980000e-04 1.067000e-03 2.833000e-03
                  ]
                }
              }
            }
          ]
          name "HR_abd_link"
          boundingObject Pose {
            translation -0.100000 -0.033250 0.000000
            rotation 1.000000 0.000000 0.000000 1.570796
            children [
              Cylinder {
                radius 0.06
                height 0.1065
              }
            ]
          }
          physics Physics {
            density -1
            mass 2.860000
            centerOfMass [ -0.067556 -0.009593 -0.000017 ]
            inertiaMatrix [
              4.372000e-03 7.471000e-03 6.768000e-03
              3.640000e-04 -1.060000e-04 -3.800000e-05
            ]
          }
        }
      }
      HingeJoint {
        jointParameters HingeJointParameters {
          anchor -0.201500 0.080000 0.000000
        }
        device [
          RotationalMotor {
            name "HL_abd_joint"
            maxVelocity 21.0
            minPosition -0.80285
            maxPosition 0.80285
            maxTorque 100.0
          }
          PositionSensor {
            name "HL_abd_joint_sensor"
          }
        ]
        endPoint Solid {
          translation -0.201500 0.080000 0.000000
          children [
            Shape {
              appearance DEF HL_abd_link_material PBRAppearance {
                baseColor 0.752940 0.752940 0.752940
                roughness 1.000000
                metalness 0
              }
              geometry DEF HL_abd_link Mesh {
                url "./meshes/HL_abd_link.STL"
              }
            }
            HingeJoint {
              jointParameters HingeJointParameters {
                axis 0.000000 1.000000 0.000000
                anchor -0.100000 0.106500 0.000000
              }
              device [
                RotationalMotor {
                  name "HL_hip_joint"
                  maxVelocity 21.0
                  minPosition -1.0472
                  maxPosition 4.1888
                  maxTorque 100.0
                }
                PositionSensor {
                  name "HL_hip_joint_sensor"
                }
              ]
              endPoint Solid {
                translation -0.100000 0.106500 0.000000
                children [
                  Shape {
                    appearance DEF HL_hip_link_material PBRAppearance {
                      baseColor 0.752940 0.752940 0.752940
                      roughness 1.000000
                      metalness 0
                    }
                    geometry DEF HL_hip_link Mesh {
                      url "./meshes/HL_hip_link.STL"
                    }
                  }
                  HingeJoint {
                    jointParameters HingeJointParameters {
                      position -1.806400
                      axis 0.000000 1.000000 0.000000
                      anchor 0.000063 0.000000 -0.260000
                    }
                    device [
                      RotationalMotor {
                        name "HL_knee_joint"
                        maxVelocity 21.0
                        minPosition -2.6965
                        maxPosition -0.9163
                        maxTorque 150.0
                      }
                      PositionSensor {
                        name "HL_knee_joint_sensor"
                      }
                    ]
                    endPoint Solid {
                      translation 0.000063 0.000000 -0.260000
                      rotation 0.000000 -1.000000 0.000000 1.806400
                      children [
                        Shape {
                          appearance DEF HL_knee_link_material PBRAppearance {
                            baseColor 0.752940 0.752940 0.752940
                            roughness 1.000000
                            metalness 0
                          }
                          geometry DEF HL_knee_link Mesh {
                            url "./meshes/HL_knee_link.STL"
                          }
                        }
                        Solid {
                          translation 0.032939 0.000000 -0.261493
                          children [
                            Shape {
                              appearance DEF HL_foot_link_material PBRAppearance {
                                roughness 1.000000
                                metalness 0
                              }
                              geometry Sphere {
                                radius 0.03
                              }
                            }
                          ]
                          name "HL_foot_link"
                          boundingObject Sphere {
                            radius 0.03
                          }
                          physics Physics {
                            density -1
                            mass 0.000205
                            centerOfMass [ 0.000000 0.000000 0.000000 ]
                            inertiaMatrix [
                              1.096001e-09 1.096001e-09 1.096001e-09
                              0.000000e+00 7.974876e-42 0.000000e+00
                            ]
                          }
                        }
                      ]
                      name "HL_knee_link"
                      boundingObject Pose {
                        translation 0.016470 0.000000 -0.130000
                        rotation 0.000000 -1.000000 0.000000 0.174530
                        children [
                          Box {
                             size 0.050000 0.030000 0.230000
                          }
                        ]
                      }
                      physics Physics {
                        density -1
                        mass 0.314000
                        centerOfMass [ 0.017829 -0.000016 -0.099213 ]
                        inertiaMatrix [
                          3.733000e-03 3.882000e-03 1.770000e-04
                          -8.700000e-08 -6.000000e-04 8.380000e-07
                        ]
                      }
                    }
                  }
                ]
                name "HL_hip_link"
                boundingObject Pose {
                  translation -0.025000 0.000000 -0.080000
                  children [
                    Box {
                       size 0.060000 0.035000 0.260000
                    }
                  ]
                }
                physics Physics {
                  density -1
                  mass 2.600000
                  centerOfMass [ -0.009036 -0.006529 -0.068800 ]
                  inertiaMatrix [
                    1.684800e-02 1.674900e-02 2.088000e-03
                    -3.100000e-04 1.116000e-03 -2.270000e-03
                  ]
                }
              }
            }
          ]
          name "HL_abd_link"
          boundingObject Pose {
            translation -0.100000 0.033250 0.000000
            rotation 1.000000 0.000000 0.000000 1.570796
            children [
              Cylinder {
                radius 0.06
                height 0.1065
              }
            ]
          }
          physics Physics {
            density -1
            mass 2.860000
            centerOfMass [ -0.067410 0.009593 0.000073 ]
            inertiaMatrix [
              4.372000e-03 7.471000e-03 6.768000e-03
              3.640000e-04 -1.060000e-04 -3.800000e-05
            ]
          }
        }
      }
    ]
    name IS name
    boundingObject Box {
       size 0.450000 0.250000 0.100000
    }
    physics Physics {
      density -1
      mass 20.800000
      centerOfMass [ 0.037380 -0.006590 0.005793 ]
      inertiaMatrix [
        1.311020e-01 4.079150e-01 4.767550e-01
        1.924000e-03 1.299000e-03 2.595000e-03
      ]
    }
  }
}
