#VRML_SIM R2023b utf8

EXTERNPROTO "https://raw.githubusercontent.com/cyberbotics/webots/R2023b/projects/objects/backgrounds/protos/TexturedBackground.proto"
EXTERNPROTO "https://raw.githubusercontent.com/cyberbotics/webots/R2023b/projects/objects/backgrounds/protos/TexturedBackgroundLight.proto"
EXTERNPROTO "https://raw.githubusercontent.com/cyberbotics/webots/R2023b/projects/objects/floors/protos/RectangleArena.proto"
EXTERNPROTO "https://raw.githubusercontent.com/cyberbotics/webots/R2023b/projects/appearances/protos/Grass.proto"
EXTERNPROTO "https://raw.githubusercontent.com/cyberbotics/webots/R2023b/projects/appearances/protos/RedBricks.proto"

WorldInfo {
  basicTimeStep 1
  FPS 30
  lineScale 0.2
}
Viewpoint {
  orientation -0.16032966457000802 0.08741275166184814 0.983185338329337 2.157487562780709
  position 1.314734864755941 -1.5576238349627833 0.9282890605780556
  follow "AliengoZ1"
}
TexturedBackground {
  texture "noon_park_empty"
}
TexturedBackgroundLight {
}
RectangleArena {
  floorSize 20 20
  floorAppearance Grass {
  }
  wallThickness 0.05
  wallHeight 0.5
  wallAppearance RedBricks {
    textureTransform TextureTransform {
      scale 30 30
    }
  }
}
DEF AliengoZ1 Robot {
  translation 0 0 0.424
  children [
    Shape {
      appearance PBRAppearance {
        baseColor 0.5 0.5 0.5
        roughness 1
        metalness 0
      }
      geometry Box {
        size 0.001 0.001 0.001
      }
    }
    DEF trunk_visual CadShape {
      url [
        "../protos/aliengoZ1_description/meshes/trunk.dae"
      ]
    }
    Solid {
      children [
        Shape {
          appearance DEF red PBRAppearance {
            baseColor 0.5 0.5 0.5
            roughness 1
            metalness 0
          }
          geometry Box {
            size 0.001 0.001 0.001
          }
        }
        InertialUnit {
          name "trunk_imu inertial"
        }
        Accelerometer {
          name "trunk_imu accelerometer"
        }
        Gyro {
          name "trunk_imu gyro"
        }
        Compass {
          name "trunk_imu compass"
        }
      ]
      name "imu_link"
      boundingObject Box {
        size 0.001 0.001 0.001
      }
      physics Physics {
        density -1
        mass 0.001
        centerOfMass [
          0 0 0
        ]
        inertiaMatrix [
          0.0001 1e-06 0.0001
          0 0 0
        ]
      }
    }
    HingeJoint {
      jointParameters HingeJointParameters {
        anchor 0.2407 -0.051 0
      }
      device [
        RotationalMotor {
          name "leg1_hip_joint"
          maxVelocity 20
          minPosition -1.2217304763960306
          maxPosition 1.2217304763960306
          maxTorque 100
        }
        PositionSensor {
          name "leg1_hip_joint_sensor"
        }
      ]
      endPoint Solid {
        translation 0.2407 -0.051 0
        rotation 1 0 0 0
        children [
          Pose {
            rotation 1 0 0 3.141593
            children [
              DEF hip_visual CadShape {
                url [
                  "../protos/aliengoZ1_description/meshes/hip.dae"
                ]
              }
            ]
          }
          HingeJoint {
            jointParameters HingeJointParameters {
              position 0.67
              axis 0 1 0
              anchor 0 -0.0868 0
            }
            device [
              RotationalMotor {
                name "leg1_thigh_joint"
                maxVelocity 20
                maxTorque 100
              }
              PositionSensor {
                name "leg1_thigh_joint_sensor"
              }
            ]
            endPoint Solid {
              translation 0 -0.0868 0
              rotation 0 1 0 0.6699999999999997
              children [
                DEF thigh_mirror_visual CadShape {
                  url [
                    "../protos/aliengoZ1_description/meshes/thigh_mirror.dae"
                  ]
                }
                HingeJoint {
                  jointParameters HingeJointParameters {
                    position -1.3
                    axis 0 1 0
                    anchor 0 0 -0.25
                  }
                  device [
                    RotationalMotor {
                      name "leg1_calf_joint"
                      maxVelocity 15.89
                      minPosition -2.775073510670984
                      maxPosition -0.6457718232379019
                      maxTorque 100
                    }
                    PositionSensor {
                      name "leg1_calf_joint_sensor"
                    }
                  ]
                  endPoint Solid {
                    translation 0 0 -0.25
                    rotation 0 -1 0 1.2999999999999998
                    children [
                      DEF calf_visual CadShape {
                        url [
                          "../protos/aliengoZ1_description/meshes/calf.dae"
                        ]
                      }
                      Solid {
                        translation 0 0 -0.25
                        children [
                          Shape {
                            appearance DEF green PBRAppearance {
                              baseColor 0.5 0.5 0.5
                              roughness 1
                              metalness 0
                            }
                            geometry Sphere {
                              radius 0.0165
                            }
                          }
                        ]
                        name "leg1_foot"
                        boundingObject Sphere {
                          radius 0.0265
                        }
                        physics Physics {
                          density -1
                          mass 0.06
                          centerOfMass [
                            0 0 0
                          ]
                          inertiaMatrix [
                            1.6854e-05 1.6854e-05 1.6854e-05
                            0 0 0
                          ]
                        }
                      }
                    ]
                    name "leg1_calf"
                    boundingObject Pose {
                      translation 0 0 -0.125
                      rotation 0 1 0 1.570796
                      children [
                        Box {
                          size 0.25 0.0208 0.016
                        }
                      ]
                    }
                    physics Physics {
                      density -1
                      mass 0.207
                      centerOfMass [
                        0.002781 6.3e-05 -0.142518
                      ]
                      inertiaMatrix [
                        0.002129279 0.002141463 3.7583e-05
                        3.9e-08 5.757e-06 -5.16e-07
                      ]
                    }
                  }
                }
                Solid {
                  translation 0 0.0997 0
                  children [
                    Pose {
                      rotation 1 0 0 1.570796
                      children [
                        Shape {
                          appearance USE green
                          geometry Cylinder {
                            height 0.02
                            radius 0.035
                          }
                        }
                      ]
                    }
                  ]
                  name "leg1_calf_rotor"
                  boundingObject Pose {
                    rotation 1 0 0 1.570796
                    children [
                      Cylinder {
                        height 0.02
                        radius 0.035
                      }
                    ]
                  }
                  physics Physics {
                    density -1
                    mass 0.132
                    centerOfMass [
                      0 0 0
                    ]
                    inertiaMatrix [
                      0.000145463 0.000133031 0.000145463
                      0 0 0
                    ]
                  }
                }
              ]
              name "leg1_thigh"
              boundingObject Pose {
                translation 0 0 -0.125
                rotation 0 1 0 1.570796
                children [
                  Box {
                    size 0.25 0.0374 0.043
                  }
                ]
              }
              physics Physics {
                density -1
                mass 0.639
                centerOfMass [
                  -0.005607 0.003877 -0.048199
                ]
                inertiaMatrix [
                  0.004173855 0.004343802 0.000340136
                  -1.0284e-05 -0.000318874 -0.000109233
                ]
              }
            }
          }
          Solid {
            translation 0 -0.0298 0
            children [
              Pose {
                rotation 1 0 0 1.570796
                children [
                  Shape {
                    appearance USE green
                    geometry Cylinder {
                      height 0.02
                      radius 0.035
                    }
                  }
                ]
              }
            ]
            name "leg1_thigh_rotor"
            boundingObject Pose {
              rotation 1 0 0 1.570796
              children [
                Cylinder {
                  height 0.02
                  radius 0.035
                }
              ]
            }
            physics Physics {
              density -1
              mass 0.146
              centerOfMass [
                0 0 0
              ]
              inertiaMatrix [
                8.3352e-05 0.000138702 8.3352e-05
                0 0 0
              ]
            }
          }
        ]
        name "leg1_hip"
        boundingObject Pose {
          translation 0 -0.083 0
          rotation 1 0 0 1.570796
          children [
            Cylinder {
              height 0.0418
              radius 0.046
            }
          ]
        }
        physics Physics {
          density -1
          mass 1.993
          centerOfMass [
            -0.022191 -0.015144 -1.5e-05
          ]
          inertiaMatrix [
            0.002446735 0.003925876 0.004148145
            0.00059805 1.945e-06 -1.284e-06
          ]
        }
      }
    }
    Solid {
      translation 0.139985 -0.051 0
      children [
        Pose {
          rotation 0 1 0 1.570796
          children [
            Shape {
              appearance DEF green PBRAppearance {
                baseColor 0.5 0.5 0.5
                roughness 1
                metalness 0
              }
              geometry Cylinder {
                height 0.02
                radius 0.035
              }
            }
          ]
        }
      ]
      name "leg1_hip_rotor"
      boundingObject Pose {
        rotation 0 1 0 1.570796
        children [
          Cylinder {
            height 0.02
            radius 0.035
          }
        ]
      }
      physics Physics {
        density -1
        mass 0.146
        centerOfMass [
          0 0 0
        ]
        inertiaMatrix [
          0.000138702 8.3352e-05 8.3352e-05
          0 0 0
        ]
      }
    }
    HingeJoint {
      jointParameters HingeJointParameters {
        anchor -0.2407 -0.051 0
      }
      device [
        RotationalMotor {
          name "leg2_hip_joint"
          maxVelocity 20
          minPosition -1.2217304763960306
          maxPosition 1.2217304763960306
          maxTorque 100
        }
        PositionSensor {
          name "leg2_hip_joint_sensor"
        }
      ]
      endPoint Solid {
        translation -0.2407 -0.051 0
        rotation 1 0 0 0
        children [
          Pose {
            rotation 0 0 -1 3.141593
            children [
              DEF hip_visual CadShape {
                url [
                  "../protos/aliengoZ1_description/meshes/hip.dae"
                ]
              }
            ]
          }
          HingeJoint {
            jointParameters HingeJointParameters {
              position 0.67
              axis 0 1 0
              anchor 0 -0.0868 0
            }
            device [
              RotationalMotor {
                name "leg2_thigh_joint"
                maxVelocity 20
                maxTorque 100
              }
              PositionSensor {
                name "leg2_thigh_joint_sensor"
              }
            ]
            endPoint Solid {
              translation 0 -0.0868 0
              rotation 0 1 0 0.6699999999999997
              children [
                DEF thigh_mirror_visual CadShape {
                  url [
                    "../protos/aliengoZ1_description/meshes/thigh_mirror.dae"
                  ]
                }
                HingeJoint {
                  jointParameters HingeJointParameters {
                    position -1.3
                    axis 0 1 0
                    anchor 0 0 -0.25
                  }
                  device [
                    RotationalMotor {
                      name "leg2_calf_joint"
                      maxVelocity 15.89
                      minPosition -2.775073510670984
                      maxPosition -0.6457718232379019
                      maxTorque 100
                    }
                    PositionSensor {
                      name "leg2_calf_joint_sensor"
                    }
                  ]
                  endPoint Solid {
                    translation 0 0 -0.25
                    rotation 0 -1 0 1.2999999999999998
                    children [
                      DEF calf_visual CadShape {
                        url [
                          "../protos/aliengoZ1_description/meshes/calf.dae"
                        ]
                      }
                      Solid {
                        translation 0 0 -0.25
                        children [
                          Shape {
                            appearance DEF green PBRAppearance {
                              baseColor 0.5 0.5 0.5
                              roughness 1
                              metalness 0
                            }
                            geometry Sphere {
                              radius 0.0165
                            }
                          }
                        ]
                        name "leg2_foot"
                        boundingObject Sphere {
                          radius 0.0265
                        }
                        physics Physics {
                          density -1
                          mass 0.06
                          centerOfMass [
                            0 0 0
                          ]
                          inertiaMatrix [
                            1.6854e-05 1.6854e-05 1.6854e-05
                            0 0 0
                          ]
                        }
                      }
                    ]
                    name "leg2_calf"
                    boundingObject Pose {
                      translation 0 0 -0.125
                      rotation 0 1 0 1.570796
                      children [
                        Box {
                          size 0.25 0.0208 0.016
                        }
                      ]
                    }
                    physics Physics {
                      density -1
                      mass 0.207
                      centerOfMass [
                        0.002781 6.3e-05 -0.142518
                      ]
                      inertiaMatrix [
                        0.002129279 0.002141463 3.7583e-05
                        3.9e-08 5.757e-06 -5.16e-07
                      ]
                    }
                  }
                }
                Solid {
                  translation 0 0.0997 0
                  children [
                    Pose {
                      rotation 1 0 0 1.570796
                      children [
                        Shape {
                          appearance USE green
                          geometry Cylinder {
                            height 0.02
                            radius 0.035
                          }
                        }
                      ]
                    }
                  ]
                  name "leg2_calf_rotor"
                  boundingObject Pose {
                    rotation 1 0 0 1.570796
                    children [
                      Cylinder {
                        height 0.02
                        radius 0.035
                      }
                    ]
                  }
                  physics Physics {
                    density -1
                    mass 0.132
                    centerOfMass [
                      0 0 0
                    ]
                    inertiaMatrix [
                      0.000145463 0.000133031 0.000145463
                      0 0 0
                    ]
                  }
                }
              ]
              name "leg2_thigh"
              boundingObject Pose {
                translation 0 0 -0.125
                rotation 0 1 0 1.570796
                children [
                  Box {
                    size 0.25 0.0374 0.043
                  }
                ]
              }
              physics Physics {
                density -1
                mass 0.639
                centerOfMass [
                  -0.005607 0.003877 -0.048199
                ]
                inertiaMatrix [
                  0.004173855 0.004343802 0.000340136
                  -1.0284e-05 -0.000318874 -0.000109233
                ]
              }
            }
          }
          Solid {
            translation 0 -0.0298 0
            children [
              Pose {
                rotation 1 0 0 1.570796
                children [
                  Shape {
                    appearance USE green
                    geometry Cylinder {
                      height 0.02
                      radius 0.035
                    }
                  }
                ]
              }
            ]
            name "leg2_thigh_rotor"
            boundingObject Pose {
              rotation 1 0 0 1.570796
              children [
                Cylinder {
                  height 0.02
                  radius 0.035
                }
              ]
            }
            physics Physics {
              density -1
              mass 0.146
              centerOfMass [
                0 0 0
              ]
              inertiaMatrix [
                8.3352e-05 0.000138702 8.3352e-05
                0 0 0
              ]
            }
          }
        ]
        name "leg2_hip"
        boundingObject Pose {
          translation 0 -0.083 0
          rotation 1 0 0 1.570796
          children [
            Cylinder {
              height 0.0418
              radius 0.046
            }
          ]
        }
        physics Physics {
          density -1
          mass 1.993
          centerOfMass [
            0.022191 -0.015144 -1.5e-05
          ]
          inertiaMatrix [
            0.002446735 0.003925876 0.004148145
            -0.00059805 -1.945e-06 -1.284e-06
          ]
        }
      }
    }
    Solid {
      translation -0.139985 -0.051 0
      children [
        Pose {
          rotation 0 1 0 1.570796
          children [
            Shape {
              appearance DEF green PBRAppearance {
                baseColor 0.5 0.5 0.5
                roughness 1
                metalness 0
              }
              geometry Cylinder {
                height 0.02
                radius 0.035
              }
            }
          ]
        }
      ]
      name "leg2_hip_rotor"
      boundingObject Pose {
        rotation 0 1 0 1.570796
        children [
          Cylinder {
            height 0.02
            radius 0.035
          }
        ]
      }
      physics Physics {
        density -1
        mass 0.146
        centerOfMass [
          0 0 0
        ]
        inertiaMatrix [
          0.000138702 8.3352e-05 8.3352e-05
          0 0 0
        ]
      }
    }
    HingeJoint {
      jointParameters HingeJointParameters {
        anchor 0.2407 0.051 0
      }
      device [
        RotationalMotor {
          name "leg3_hip_joint"
          maxVelocity 20
          minPosition -1.2217304763960306
          maxPosition 1.2217304763960306
          maxTorque 100
        }
        PositionSensor {
          name "leg3_hip_joint_sensor"
        }
      ]
      endPoint Solid {
        translation 0.2407 0.051 0
        rotation 1 0 0 0
        children [
          DEF hip_visual CadShape {
            url [
              "../protos/aliengoZ1_description/meshes/hip.dae"
            ]
          }
          HingeJoint {
            jointParameters HingeJointParameters {
              position 0.67
              axis 0 1 0
              anchor 0 0.0868 0
            }
            device [
              RotationalMotor {
                name "leg3_thigh_joint"
                maxVelocity 20
                maxTorque 100
              }
              PositionSensor {
                name "leg3_thigh_joint_sensor"
              }
            ]
            endPoint Solid {
              translation 0 0.0868 0
              rotation 0 1 0 0.6699999999999997
              children [
                DEF thigh_visual CadShape {
                  url [
                    "../protos/aliengoZ1_description/meshes/thigh.dae"
                  ]
                }
                HingeJoint {
                  jointParameters HingeJointParameters {
                    position -1.3
                    axis 0 1 0
                    anchor 0 0 -0.25
                  }
                  device [
                    RotationalMotor {
                      name "leg3_calf_joint"
                      maxVelocity 15.89
                      minPosition -2.775073510670984
                      maxPosition -0.6457718232379019
                      maxTorque 100
                    }
                    PositionSensor {
                      name "leg3_calf_joint_sensor"
                    }
                  ]
                  endPoint Solid {
                    translation 0 0 -0.25
                    rotation 0 -1 0 1.2999999999999998
                    children [
                      DEF calf_visual CadShape {
                        url [
                          "../protos/aliengoZ1_description/meshes/calf.dae"
                        ]
                      }
                      Solid {
                        translation 0 0 -0.25
                        children [
                          Shape {
                            appearance DEF green PBRAppearance {
                              baseColor 0.5 0.5 0.5
                              roughness 1
                              metalness 0
                            }
                            geometry Sphere {
                              radius 0.0165
                            }
                          }
                        ]
                        name "leg3_foot"
                        boundingObject Sphere {
                          radius 0.0265
                        }
                        physics Physics {
                          density -1
                          mass 0.06
                          centerOfMass [
                            0 0 0
                          ]
                          inertiaMatrix [
                            1.6854e-05 1.6854e-05 1.6854e-05
                            0 0 0
                          ]
                        }
                      }
                    ]
                    name "leg3_calf"
                    boundingObject Pose {
                      translation 0 0 -0.125
                      rotation 0 1 0 1.570796
                      children [
                        Box {
                          size 0.25 0.0208 0.016
                        }
                      ]
                    }
                    physics Physics {
                      density -1
                      mass 0.207
                      centerOfMass [
                        0.002781 6.3e-05 -0.142518
                      ]
                      inertiaMatrix [
                        0.002129279 0.002141463 3.7583e-05
                        3.9e-08 5.757e-06 -5.16e-07
                      ]
                    }
                  }
                }
                Solid {
                  translation 0 -0.0997 0
                  children [
                    Pose {
                      rotation 1 0 0 1.570796
                      children [
                        Shape {
                          appearance USE green
                          geometry Cylinder {
                            height 0.02
                            radius 0.035
                          }
                        }
                      ]
                    }
                  ]
                  name "leg3_calf_rotor"
                  boundingObject Pose {
                    rotation 1 0 0 1.570796
                    children [
                      Cylinder {
                        height 0.02
                        radius 0.035
                      }
                    ]
                  }
                  physics Physics {
                    density -1
                    mass 0.132
                    centerOfMass [
                      0 0 0
                    ]
                    inertiaMatrix [
                      0.000145463 0.000133031 0.000145463
                      0 0 0
                    ]
                  }
                }
              ]
              name "leg3_thigh"
              boundingObject Pose {
                translation 0 0 -0.125
                rotation 0 1 0 1.570796
                children [
                  Box {
                    size 0.25 0.0374 0.043
                  }
                ]
              }
              physics Physics {
                density -1
                mass 0.639
                centerOfMass [
                  -0.005607 -0.003877 -0.048199
                ]
                inertiaMatrix [
                  0.004173855 0.004343802 0.000340136
                  1.0284e-05 -0.000318874 0.000109233
                ]
              }
            }
          }
          Solid {
            translation 0 0.0298 0
            children [
              Pose {
                rotation 1 0 0 1.570796
                children [
                  Shape {
                    appearance USE green
                    geometry Cylinder {
                      height 0.02
                      radius 0.035
                    }
                  }
                ]
              }
            ]
            name "leg3_thigh_rotor"
            boundingObject Pose {
              rotation 1 0 0 1.570796
              children [
                Cylinder {
                  height 0.02
                  radius 0.035
                }
              ]
            }
            physics Physics {
              density -1
              mass 0.146
              centerOfMass [
                0 0 0
              ]
              inertiaMatrix [
                8.3352e-05 0.000138702 8.3352e-05
                0 0 0
              ]
            }
          }
        ]
        name "leg3_hip"
        boundingObject Pose {
          translation 0 0.083 0
          rotation 1 0 0 1.570796
          children [
            Cylinder {
              height 0.0418
              radius 0.046
            }
          ]
        }
        physics Physics {
          density -1
          mass 1.993
          centerOfMass [
            -0.022191 0.015144 -1.5e-05
          ]
          inertiaMatrix [
            0.002446735 0.003925876 0.004148145
            -0.00059805 1.945e-06 1.284e-06
          ]
        }
      }
    }
    Solid {
      translation 0.139985 0.051 0
      children [
        Pose {
          rotation 0 1 0 1.570796
          children [
            Shape {
              appearance DEF green PBRAppearance {
                baseColor 0.5 0.5 0.5
                roughness 1
                metalness 0
              }
              geometry Cylinder {
                height 0.02
                radius 0.035
              }
            }
          ]
        }
      ]
      name "leg3_hip_rotor"
      boundingObject Pose {
        rotation 0 1 0 1.570796
        children [
          Cylinder {
            height 0.02
            radius 0.035
          }
        ]
      }
      physics Physics {
        density -1
        mass 0.146
        centerOfMass [
          0 0 0
        ]
        inertiaMatrix [
          0.000138702 8.3352e-05 8.3352e-05
          0 0 0
        ]
      }
    }
    HingeJoint {
      jointParameters HingeJointParameters {
        anchor -0.2407 0.051 0
      }
      device [
        RotationalMotor {
          name "leg4_hip_joint"
          maxVelocity 20
          minPosition -1.2217304763960306
          maxPosition 1.2217304763960306
          maxTorque 100
        }
        PositionSensor {
          name "leg4_hip_joint_sensor"
        }
      ]
      endPoint Solid {
        translation -0.2407 0.051 0
        rotation 1 0 0 0
        children [
          Pose {
            rotation 0 1 0 3.141593
            children [
              DEF hip_visual CadShape {
                url [
                  "../protos/aliengoZ1_description/meshes/hip.dae"
                ]
              }
            ]
          }
          HingeJoint {
            jointParameters HingeJointParameters {
              position 0.67
              axis 0 1 0
              anchor 0 0.0868 0
            }
            device [
              RotationalMotor {
                name "leg4_thigh_joint"
                maxVelocity 20
                maxTorque 100
              }
              PositionSensor {
                name "leg4_thigh_joint_sensor"
              }
            ]
            endPoint Solid {
              translation 0 0.0868 0
              rotation 0 1 0 0.6699999999999997
              children [
                DEF thigh_visual CadShape {
                  url [
                    "../protos/aliengoZ1_description/meshes/thigh.dae"
                  ]
                }
                HingeJoint {
                  jointParameters HingeJointParameters {
                    position -1.3
                    axis 0 1 0
                    anchor 0 0 -0.25
                  }
                  device [
                    RotationalMotor {
                      name "leg4_calf_joint"
                      maxVelocity 15.89
                      minPosition -2.775073510670984
                      maxPosition -0.6457718232379019
                      maxTorque 100
                    }
                    PositionSensor {
                      name "leg4_calf_joint_sensor"
                    }
                  ]
                  endPoint Solid {
                    translation 0 0 -0.25
                    rotation 0 -1 0 1.2999999999999998
                    children [
                      DEF calf_visual CadShape {
                        url [
                          "../protos/aliengoZ1_description/meshes/calf.dae"
                        ]
                      }
                      Solid {
                        translation 0 0 -0.25
                        children [
                          Shape {
                            appearance DEF green PBRAppearance {
                              baseColor 0.5 0.5 0.5
                              roughness 1
                              metalness 0
                            }
                            geometry Sphere {
                              radius 0.0165
                            }
                          }
                        ]
                        name "leg4_foot"
                        boundingObject Sphere {
                          radius 0.0265
                        }
                        physics Physics {
                          density -1
                          mass 0.06
                          centerOfMass [
                            0 0 0
                          ]
                          inertiaMatrix [
                            1.6854e-05 1.6854e-05 1.6854e-05
                            0 0 0
                          ]
                        }
                      }
                    ]
                    name "leg4_calf"
                    boundingObject Pose {
                      translation 0 0 -0.125
                      rotation 0 1 0 1.570796
                      children [
                        Box {
                          size 0.25 0.0208 0.016
                        }
                      ]
                    }
                    physics Physics {
                      density -1
                      mass 0.207
                      centerOfMass [
                        0.002781 6.3e-05 -0.142518
                      ]
                      inertiaMatrix [
                        0.002129279 0.002141463 3.7583e-05
                        3.9e-08 5.757e-06 -5.16e-07
                      ]
                    }
                  }
                }
                Solid {
                  translation 0 -0.0997 0
                  children [
                    Pose {
                      rotation 1 0 0 1.570796
                      children [
                        Shape {
                          appearance USE green
                          geometry Cylinder {
                            height 0.02
                            radius 0.035
                          }
                        }
                      ]
                    }
                  ]
                  name "leg4_calf_rotor"
                  boundingObject Pose {
                    rotation 1 0 0 1.570796
                    children [
                      Cylinder {
                        height 0.02
                        radius 0.035
                      }
                    ]
                  }
                  physics Physics {
                    density -1
                    mass 0.132
                    centerOfMass [
                      0 0 0
                    ]
                    inertiaMatrix [
                      0.000145463 0.000133031 0.000145463
                      0 0 0
                    ]
                  }
                }
              ]
              name "leg4_thigh"
              boundingObject Pose {
                translation 0 0 -0.125
                rotation 0 1 0 1.570796
                children [
                  Box {
                    size 0.25 0.0374 0.043
                  }
                ]
              }
              physics Physics {
                density -1
                mass 0.639
                centerOfMass [
                  -0.005607 -0.003877 -0.048199
                ]
                inertiaMatrix [
                  0.004173855 0.004343802 0.000340136
                  1.0284e-05 -0.000318874 0.000109233
                ]
              }
            }
          }
          Solid {
            translation 0 0.0298 0
            children [
              Pose {
                rotation 1 0 0 1.570796
                children [
                  Shape {
                    appearance USE green
                    geometry Cylinder {
                      height 0.02
                      radius 0.035
                    }
                  }
                ]
              }
            ]
            name "leg4_thigh_rotor"
            boundingObject Pose {
              rotation 1 0 0 1.570796
              children [
                Cylinder {
                  height 0.02
                  radius 0.035
                }
              ]
            }
            physics Physics {
              density -1
              mass 0.146
              centerOfMass [
                0 0 0
              ]
              inertiaMatrix [
                8.3352e-05 0.000138702 8.3352e-05
                0 0 0
              ]
            }
          }
        ]
        name "leg4_hip"
        boundingObject Pose {
          translation 0 0.083 0
          rotation 1 0 0 1.570796
          children [
            Cylinder {
              height 0.0418
              radius 0.046
            }
          ]
        }
        physics Physics {
          density -1
          mass 1.993
          centerOfMass [
            0.022191 0.015144 -1.5e-05
          ]
          inertiaMatrix [
            0.002446735 0.003925876 0.004148145
            0.00059805 -1.945e-06 1.284e-06
          ]
        }
      }
    }
    Solid {
      translation -0.139985 0.051 0
      children [
        Pose {
          rotation 0 1 0 1.570796
          children [
            Shape {
              appearance DEF green PBRAppearance {
                baseColor 0.5 0.5 0.5
                roughness 1
                metalness 0
              }
              geometry Cylinder {
                height 0.02
                radius 0.035
              }
            }
          ]
        }
      ]
      name "leg4_hip_rotor"
      boundingObject Pose {
        rotation 0 1 0 1.570796
        children [
          Cylinder {
            height 0.02
            radius 0.035
          }
        ]
      }
      physics Physics {
        density -1
        mass 0.146
        centerOfMass [
          0 0 0
        ]
        inertiaMatrix [
          0.000138702 8.3352e-05 8.3352e-05
          0 0 0
        ]
      }
    }
    Solid {
      translation 0.2535 0 0.056
      children [
        DEF z1_Link00_visual CadShape {
          url [
            "../protos/aliengoZ1_description/meshes/visual/z1_Link00.dae"
          ]
        }
        HingeJoint {
          jointParameters HingeJointParameters {
            axis 0 0 1
            anchor 0 0 0.0585
            dampingConstant 1
            staticFriction 1
          }
          device [
            RotationalMotor {
              name "joint1"
              maxVelocity 3.1415
              minPosition -2.6179938779914944
              maxPosition 2.6179938779914944
              maxTorque 30
            }
            PositionSensor {
              name "joint1_sensor"
            }
          ]
          endPoint Solid {
            translation 0 0 0.0585
            children [
              DEF z1_Link01_visual CadShape {
                url [
                  "../protos/aliengoZ1_description/meshes/visual/z1_Link01.dae"
                ]
              }
              HingeJoint {
                jointParameters HingeJointParameters {
                  axis 0 1 0
                  anchor 0 0 0.045
                  dampingConstant 2
                  staticFriction 2
                }
                device [
                  RotationalMotor {
                    name "joint2"
                    maxVelocity 3.1415
                    maxPosition 2.9670597283903604
                    maxTorque 60
                  }
                  PositionSensor {
                    name "joint2_sensor"
                  }
                ]
                endPoint Solid {
                  translation 0 0 0.045
                  rotation 0 1 0 0
                  children [
                    DEF z1_Link02_visual CadShape {
                      url [
                        "../protos/aliengoZ1_description/meshes/visual/z1_Link02.dae"
                      ]
                    }
                    HingeJoint {
                      jointParameters HingeJointParameters {
                        axis 0 1 0
                        anchor -0.35 0 0
                        dampingConstant 1
                        staticFriction 1
                      }
                      device [
                        RotationalMotor {
                          name "joint3"
                          maxVelocity 3.1415
                          minPosition -2.8797932657906435
                          maxTorque 30
                        }
                        PositionSensor {
                          name "joint3_sensor"
                        }
                      ]
                      endPoint Solid {
                        translation -0.35 0 0
                        rotation 0 1 0 0
                        children [
                          DEF z1_Link03_visual CadShape {
                            url [
                              "../protos/aliengoZ1_description/meshes/visual/z1_Link03.dae"
                            ]
                          }
                          HingeJoint {
                            jointParameters HingeJointParameters {
                              axis 0 1 0
                              anchor 0.218 0 0.057
                              dampingConstant 1
                              staticFriction 1
                            }
                            device [
                              RotationalMotor {
                                name "joint4"
                                maxVelocity 3.1415
                                minPosition -1.5184364492350666
                                maxPosition 1.5184364492350666
                                maxTorque 30
                              }
                              PositionSensor {
                                name "joint4_sensor"
                              }
                            ]
                            endPoint Solid {
                              translation 0.218 0 0.057
                              rotation 0 1 0 0
                              children [
                                DEF z1_Link04_visual CadShape {
                                  url [
                                    "../protos/aliengoZ1_description/meshes/visual/z1_Link04.dae"
                                  ]
                                }
                                HingeJoint {
                                  jointParameters HingeJointParameters {
                                    axis 0 0 1
                                    anchor 0.07 0 0
                                    dampingConstant 1
                                    staticFriction 1
                                  }
                                  device [
                                    RotationalMotor {
                                      name "joint5"
                                      maxVelocity 3.1415
                                      minPosition -1.3439035240356338
                                      maxPosition 1.3439035240356338
                                      maxTorque 30
                                    }
                                    PositionSensor {
                                      name "joint5_sensor"
                                    }
                                  ]
                                  endPoint Solid {
                                    translation 0.07 0 0
                                    children [
                                      DEF z1_Link05_visual CadShape {
                                        url [
                                          "../protos/aliengoZ1_description/meshes/visual/z1_Link05.dae"
                                        ]
                                      }
                                      HingeJoint {
                                        jointParameters HingeJointParameters {
                                          anchor 0.0492 0 0
                                          dampingConstant 1
                                          staticFriction 1
                                        }
                                        device [
                                          RotationalMotor {
                                            name "joint6"
                                            maxVelocity 3.1415
                                            minPosition -2.792526803190927
                                            maxPosition 2.792526803190927
                                            maxTorque 30
                                          }
                                          PositionSensor {
                                            name "joint6_sensor"
                                          }
                                        ]
                                        endPoint Solid {
                                          translation 0.0492 0 0
                                          rotation 1 0 0 0
                                          children [
                                            DEF z1_Link06_visual CadShape {
                                              url [
                                                "../protos/aliengoZ1_description/meshes/visual/z1_Link06.dae"
                                              ]
                                            }
                                            Solid {
                                              translation 0.051 0 0
                                              children [
                                                DEF z1_GripperStator_visual CadShape {
                                                  url [
                                                    "../protos/aliengoZ1_description/meshes/visual/z1_GripperStator.dae"
                                                  ]
                                                }
                                                HingeJoint {
                                                  jointParameters HingeJointParameters {
                                                    axis 0 1 0
                                                    anchor 0.049 0 0
                                                    dampingConstant 1
                                                    staticFriction 1
                                                  }
                                                  device [
                                                    RotationalMotor {
                                                      name "jointGripper"
                                                      maxVelocity 3.1415
                                                      minPosition -1.5707963
                                                      maxTorque 30
                                                    }
                                                    PositionSensor {
                                                      name "jointGripper_sensor"
                                                    }
                                                  ]
                                                  endPoint Solid {
                                                    translation 0.049 0 0
                                                    rotation 0 1 0 0
                                                    children [
                                                      DEF z1_GripperMover_visual CadShape {
                                                        url [
                                                          "../protos/aliengoZ1_description/meshes/visual/z1_GripperMover.dae"
                                                        ]
                                                      }
                                                    ]
                                                    name "gripperMover"
                                                    boundingObject DEF z1_GripperMover Mesh {
                                                      url [
                                                        "../protos/aliengoZ1_description/meshes/collision/z1_GripperMover.STL"
                                                      ]
                                                    }
                                                    physics Physics {
                                                      density -1
                                                      mass 0.276213
                                                      centerOfMass [
                                                        0.013206 0.004767 0.003805
                                                      ]
                                                      inertiaMatrix [
                                                        0.00017716 0.00026787 0.00035728
                                                        1.683e-05 -1.786e-05 2.62e-06
                                                      ]
                                                    }
                                                  }
                                                }
                                              ]
                                              name "gripperStator"
                                              boundingObject DEF z1_GripperStator Mesh {
                                                url [
                                                  "../protos/aliengoZ1_description/meshes/collision/z1_GripperStator.STL"
                                                ]
                                              }
                                              physics Physics {
                                                density -1
                                                mass 0.526037
                                                centerOfMass [
                                                  0.047644 -0.000358 -0.002492
                                                ]
                                                inertiaMatrix [
                                                  0.00038683 0.00068614 0.00066293
                                                  -3.59e-06 7.662e-05 2.09e-06
                                                ]
                                              }
                                            }
                                          ]
                                          name "link06"
                                          boundingObject Pose {
                                            translation 0.0255 0 0
                                            rotation 0 1 0 1.570796
                                            children [
                                              Cylinder {
                                                height 0.051
                                                radius 0.0325
                                              }
                                            ]
                                          }
                                          physics Physics {
                                            density -1
                                            mass 0.288758
                                            centerOfMass [
                                              0.024157 -0.000174 -0.001439
                                            ]
                                            inertiaMatrix [
                                              0.00018328 0.0001475 0.0001468
                                              1.22e-06 5.4e-07 8e-08
                                            ]
                                          }
                                        }
                                      }
                                    ]
                                    name "link05"
                                    physics Physics {
                                      density -1
                                      mass 0.389385
                                      centerOfMass [
                                        0.031215 0 0.006463
                                      ]
                                      inertiaMatrix [
                                        0.00017605 0.00055896 0.0005386
                                        4e-07 5.689e-05 -1.3e-07
                                      ]
                                    }
                                  }
                                }
                              ]
                              name "link04"
                              boundingObject Pose {
                                translation 0.072 0 0
                                children [
                                  Cylinder {
                                    height 0.067
                                    radius 0.0325
                                  }
                                ]
                              }
                              physics Physics {
                                density -1
                                mass 0.564046
                                centerOfMass [
                                  0.043667 0.003647 -0.001702
                                ]
                                inertiaMatrix [
                                  0.00031576 0.00092996 0.00097912
                                  8.13e-05 4.091e-05 -5.96e-06
                                ]
                              }
                            }
                          }
                        ]
                        name "link03"
                        boundingObject Group {
                          children [
                            Pose {
                              translation 0.128 0 0.055
                              rotation 0 1 0 1.570796
                              children [
                                Cylinder {
                                  height 0.116
                                  radius 0.02
                                }
                              ]
                            }
                            Pose {
                              translation 0.2205 0 0.055
                              rotation -0.5773502691896258 0.5773502691896258 0.5773502691896258 2.094395
                              children [
                                Cylinder {
                                  height 0.059
                                  radius 0.0325
                                }
                              ]
                            }
                          ]
                        }
                        physics Physics {
                          density -1
                          mass 0.839409
                          centerOfMass [
                            0.106092 -0.005418 0.034764
                          ]
                          inertiaMatrix [
                            0.00108061 0.00954238 0.00886621
                            -8.669e-05 -0.00208102 -1.332e-05
                          ]
                        }
                      }
                    }
                  ]
                  name "link02"
                  boundingObject Group {
                    children [
                      Pose {
                        rotation 1 0 0 1.570796
                        children [
                          Cylinder {
                            height 0.102
                            radius 0.0325
                          }
                        ]
                      }
                      Pose {
                        translation -0.1625 0 0
                        rotation 0 1 0 1.570796
                        children [
                          Cylinder {
                            height 0.235
                            radius 0.0225
                          }
                        ]
                      }
                      Pose {
                        translation -0.35 0 0
                        rotation 1 0 0 1.570796
                        children [
                          Cylinder {
                            height 0.051
                            radius 0.0325
                          }
                        ]
                      }
                    ]
                  }
                  physics Physics {
                    density -1
                    mass 1.191323
                    centerOfMass [
                      -0.110126 0.0024 0.001583
                    ]
                    inertiaMatrix [
                      0.00102138 0.02429457 0.02466114
                      0.00062358 5.13e-06 -2.1e-06
                    ]
                  }
                }
              }
            ]
            name "link01"
            physics Physics {
              density -1
              mass 0.673326
              centerOfMass [
                2e-06 -0.000252 0.023172
              ]
              inertiaMatrix [
                0.00128328 0.00071931 0.00083936
                -6e-08 -4e-07 5e-07
              ]
            }
          }
        }
      ]
      name "link00"
      boundingObject Pose {
        translation 0 0 0.0255
        children [
          Cylinder {
            height 0.051
            radius 0.0325
          }
        ]
      }
      physics Physics {
        density -1
        mass 0.472475
        centerOfMass [
          -0.00335 -0.000136 0.024958
        ]
        inertiaMatrix [
          0.00037937 0.00041521 0.00053066
          -3.5e-07 -1.037e-05 -9.9e-07
        ]
      }
    }
  ]
  name "AliengoZ1"
  boundingObject Box {
    size 0.647 0.15 0.112
  }
  physics Physics {
    density -1
    mass 11.6
    centerOfMass [
      0.008811 0.003839 0.000273
    ]
    inertiaMatrix [
      0.05194489 0.2469392 0.2709483
      0.001703617 0.000235941 0.000119783
    ]
  }
  controller "joystick_test"
  supervisor TRUE
}
DEF DesiredPos Robot {
  children [
    DEF DesiredBody Solid {
      translation 0 0 0.42
      children [
        Pose {
          translation 0.2535 0 0.056
          children [
            Solid {
              children [
                Pose {
                  translation 0 0 0.0255
                  children [
                    Shape {
                      appearance DEF DesiredMaterial Appearance {
                        material Material {
                          ambientIntensity 0.9
                          diffuseColor 0.937255 0.160784 0.160784
                          transparency 0.3
                        }
                      }
                      geometry Cylinder {
                        height 0.051
                        radius 0.02
                      }
                    }
                  ]
                }
                DEF DesiredJoint1 HingeJoint {
                  jointParameters HingeJointParameters {
                    axis 0 0 1
                    anchor 0 0 0.0585
                  }
                  endPoint Solid {
                    translation 0 0 0.0585
                    children [
                      Pose {
                        translation 0 0 0.0255
                        children [
                          Shape {
                            appearance DEF DesiredMaterial Appearance {
                              material Material {
                                ambientIntensity 0.9
                                diffuseColor 0.937255 0.160784 0.160784
                                transparency 0.3
                              }
                            }
                            geometry Cylinder {
                              height 0.035
                              radius 0.02
                            }
                          }
                        ]
                      }
                      DEF DesiredJoint2 HingeJoint {
                        jointParameters HingeJointParameters {
                          axis 0 1 0
                          anchor 0 0 0.045
                        }
                        endPoint Solid {
                          translation 0 0 0.045
                          rotation 0 1 0 0
                          children [
                            Pose {
                              translation -0.18 0 0
                              rotation 0 1 0 1.570796
                              children [
                                Shape {
                                  appearance DEF DesiredMaterial Appearance {
                                    material Material {
                                      ambientIntensity 0.9
                                      diffuseColor 0.937255 0.160784 0.160784
                                      transparency 0.3
                                    }
                                  }
                                  geometry Cylinder {
                                    height 0.28
                                    radius 0.02
                                  }
                                }
                              ]
                            }
                            DEF DesiredJoint3 HingeJoint {
                              jointParameters HingeJointParameters {
                                axis 0 1 0
                                anchor -0.35 0 0
                              }
                              endPoint Solid {
                                translation -0.35 0 0
                                rotation 0 1 0 0
                                children [
                                  Pose {
                                    translation 0.128 0 0.055
                                    rotation 0 1 0 1.570796
                                    children [
                                      Shape {
                                        appearance DEF DesiredMaterial Appearance {
                                          material Material {
                                            ambientIntensity 0.9
                                            diffuseColor 0.937255 0.160784 0.160784
                                            transparency 0.3
                                          }
                                        }
                                        geometry Cylinder {
                                          height 0.116
                                          radius 0.02
                                        }
                                      }
                                    ]
                                  }
                                  Pose {
                                    translation 0.2205 0 0.055
                                    rotation 0 1 0 1.570796
                                    children [
                                      Shape {
                                        appearance DEF DesiredMaterial Appearance {
                                          material Material {
                                            ambientIntensity 0.9
                                            diffuseColor 0.937255 0.160784 0.160784
                                            transparency 0.3
                                          }
                                        }
                                        geometry Cylinder {
                                          height 0.059
                                          radius 0.02
                                        }
                                      }
                                    ]
                                  }
                                  DEF DesiredJoint4 HingeJoint {
                                    jointParameters HingeJointParameters {
                                      axis 0 1 0
                                      anchor 0.218 0 0.057
                                    }
                                    endPoint Solid {
                                      translation 0.218 0 0.057
                                      rotation 0 1 0 0
                                      children [
                                        Pose {
                                          translation 0.072 0 0
                                          rotation 0 1 0 1.570796
                                          children [
                                            Shape {
                                              appearance DEF DesiredMaterial Appearance {
                                                material Material {
                                                  ambientIntensity 0.9
                                                  diffuseColor 0.937255 0.160784 0.160784
                                                  transparency 0.3
                                                }
                                              }
                                              geometry Cylinder {
                                                height 0.067
                                                radius 0.02
                                              }
                                            }
                                          ]
                                        }
                                        DEF DesiredJoint5 HingeJoint {
                                          jointParameters HingeJointParameters {
                                            axis 0 0 1
                                            anchor 0.07 0 0
                                          }
                                          endPoint Solid {
                                            translation 0.07 0 0
                                            children [
                                              DEF DesiredJoint6 HingeJoint {
                                                jointParameters HingeJointParameters {
                                                  anchor 0.0492 0 0
                                                }
                                                endPoint Solid {
                                                  translation 0.0492 0 0
                                                  rotation 1 0 0 0
                                                  children [
                                                    Pose {
                                                      translation 0.0255 0 0
                                                      rotation 0 1 0 1.570796
                                                      children [
                                                        Shape {
                                                          appearance DEF DesiredMaterial Appearance {
                                                            material Material {
                                                              ambientIntensity 0.9
                                                              diffuseColor 0.937255 0.160784 0.160784
                                                              transparency 0.3
                                                            }
                                                          }
                                                          geometry Cylinder {
                                                            height 0.051
                                                            radius 0.02
                                                          }
                                                        }
                                                      ]
                                                    }
                                                  ]
                                                  name "link06"
                                                }
                                              }
                                            ]
                                            name "link05"
                                          }
                                        }
                                      ]
                                      name "link04"
                                    }
                                  }
                                ]
                                name "link03"
                              }
                            }
                          ]
                          name "link02"
                        }
                      }
                    ]
                    name "link01"
                  }
                }
              ]
              name "link00"
            }
          ]
        }
        DEF BodyShape Shape {
          appearance DEF DesiredMaterial Appearance {
            material Material {
              ambientIntensity 0.9
              diffuseColor 0.937255 0.160784 0.160784
              transparency 0.3
            }
          }
          geometry Box {
            size 0.68 0.22 0.14
          }
        }
      ]
    }
    DEF DesiredLeg1Foot Solid {
      translation 0.23274 -0.1378 0.0260377
      children [
        DEF BodyShape Shape {
          appearance DEF DesiredMaterial Appearance {
            material Material {
              ambientIntensity 0.9
              diffuseColor 0.937255 0.160784 0.160784
              transparency 0.3
            }
          }
          geometry Sphere {
            radius 0.03
          }
        }
      ]
    }
    DEF DesiredLeg2Foot Solid {
      translation -0.24866 -0.1378 0.0260377
      children [
        DEF BodyShape Shape {
          appearance DEF DesiredMaterial Appearance {
            material Material {
              ambientIntensity 0.9
              diffuseColor 0.937255 0.160784 0.160784
              transparency 0.3
            }
          }
          geometry Sphere {
            radius 0.03
          }
        }
      ]
    }
    DEF DesiredLeg3Foot Solid {
      translation 0.23274 0.1378 0.0260377
      children [
        DEF BodyShape Shape {
          appearance DEF DesiredMaterial Appearance {
            material Material {
              ambientIntensity 0.9
              diffuseColor 0.937255 0.160784 0.160784
              transparency 0.3
            }
          }
          geometry Sphere {
            radius 0.03
          }
        }
      ]
    }
    DEF DesiredLeg4Foot Solid {
      translation -0.24866 0.1378 0.0260377
      children [
        DEF BodyShape Shape {
          appearance DEF DesiredMaterial Appearance {
            material Material {
              ambientIntensity 0.9
              diffuseColor 0.937255 0.160784 0.160784
              transparency 0.3
            }
          }
          geometry Sphere {
            radius 0.03
          }
        }
      ]
    }
  ]
  name "DesiredPos Robot"
  supervisor TRUE
}
