#VRML_SIM R2025a utf8

EXTERNPROTO "https://raw.githubusercontent.com/cyberbotics/webots/R2025a/projects/objects/backgrounds/protos/TexturedBackground.proto"
EXTERNPROTO "https://raw.githubusercontent.com/cyberbotics/webots/R2025a/projects/objects/backgrounds/protos/TexturedBackgroundLight.proto"
EXTERNPROTO "https://raw.githubusercontent.com/cyberbotics/webots/R2025a/projects/objects/floors/protos/RectangleArena.proto"

WorldInfo {
  basicTimeStep 1
}
Viewpoint {
  orientation -0.05537097998380406 -0.0035807125591433425 0.9984594298584203 3.270600811421811
  position 2.2382928314172075 0.5061963390904696 0.46276952852570924
}
TexturedBackground {
}
TexturedBackgroundLight {
}
RectangleArena {
  floorSize 20 20
}
DEF galileo_mini_x5 Robot {
  translation -0.011144262266404328 -3.461291382878158e-05 0.09999856372775541
  rotation 0.8456077077518083 -0.3539354025566661 0.3995964657098249 0.0004868630642065675
  children [
    Solid {
      children [
        InertialUnit {
          name "imu_link_imu"
        }
        Accelerometer {
          name "imu_link_accelerometer"
        }
        Gyro {
          name "imu_link_gyro"
        }
      ]
      name "imu_link"
      boundingObject Box {
        size 0.001 0.001 0.001
      }
      physics Physics {
        density -1
        mass 0.001
      }
    }
    Shape {
      appearance DEF base_link_material PBRAppearance {
        baseColor 0.75294 0.75294 0.75294
        roughness 1
        metalness 0
      }
      geometry DEF base_link Mesh {
        url [
          "/home/zishang/Webots/galileo_mini_x5/protos/meshes/base_link.STL"
        ]
      }
    }
    HingeJoint {
      jointParameters HingeJointParameters {
        position 0.5000129274168289
        anchor 0.2015 0.08 0
      }
      device [
        RotationalMotor {
          name "FL_abd_joint"
          maxVelocity 21
          minPosition -0.80285
          maxPosition 0.80285
          maxTorque 100
        }
        PositionSensor {
          name "FL_abd_joint_sensor"
        }
      ]
      endPoint Solid {
        translation 0.2015 0.08 0
        rotation 1 0 0 0.5000129274168288
        children [
          Shape {
            appearance DEF FL_abd_link_material PBRAppearance {
              baseColor 0.75294 0.75294 0.75294
              roughness 1
              metalness 0
            }
            geometry DEF FL_abd_link Mesh {
              url [
                "/home/zishang/Webots/galileo_mini_x5/protos/meshes/FL_abd_link.STL"
              ]
            }
          }
          HingeJoint {
            jointParameters HingeJointParameters {
              position 1.0499948758925488
              axis 0 1 0
              anchor 0.1 0.1065 0
            }
            device [
              RotationalMotor {
                name "FL_hip_joint"
                maxVelocity 21
                minPosition -1.0472
                maxPosition 4.1888
                maxTorque 100
              }
              PositionSensor {
                name "FL_hip_joint_sensor"
              }
            ]
            endPoint Solid {
              translation 0.1 0.1065 0
              rotation 0 1 0 1.049994875892549
              children [
                Shape {
                  appearance DEF FL_hip_link_material PBRAppearance {
                    baseColor 0.75294 0.75294 0.75294
                    roughness 1
                    metalness 0
                  }
                  geometry DEF FL_hip_link Mesh {
                    url [
                      "/home/zishang/Webots/galileo_mini_x5/protos/meshes/FL_hip_link.STL"
                    ]
                  }
                }
                HingeJoint {
                  jointParameters HingeJointParameters {
                    position -2.4600230940697605
                    axis 0 1 0
                    anchor 0 0 -0.26
                  }
                  device [
                    RotationalMotor {
                      name "FL_knee_joint"
                      maxVelocity 21
                      minPosition -2.6965
                      maxPosition -0.9163
                      maxTorque 150
                    }
                    PositionSensor {
                      name "FL_knee_joint_sensor"
                    }
                  ]
                  endPoint Solid {
                    translation 0 0 -0.26
                    rotation 0 -1 0 2.4600230940697605
                    children [
                      Shape {
                        appearance DEF FL_knee_link_material PBRAppearance {
                          baseColor 0.75294 0.75294 0.75294
                          roughness 1
                          metalness 0
                        }
                        geometry DEF FL_knee_link Mesh {
                          url [
                            "/home/zishang/Webots/galileo_mini_x5/protos/meshes/FL_knee_link.STL"
                          ]
                        }
                      }
                      Solid {
                        translation 0.032939 0 -0.26149
                        children [
                          Shape {
                            appearance DEF FL_foot_link_material PBRAppearance {
                              roughness 1
                              metalness 0
                            }
                            geometry Sphere {
                              radius 0.03
                            }
                          }
                        ]
                        name "FL_foot_link"
                        boundingObject Sphere {
                          radius 0.03
                        }
                        physics Physics {
                          density -1
                          mass 0.000205
                          centerOfMass [
                            0 0 0
                          ]
                          inertiaMatrix [
                            1.096e-09 1.096e-09 1.096e-09
                            -2.0392e-56 0 0
                          ]
                        }
                      }
                    ]
                    name "FL_knee_link"
                    boundingObject Pose {
                      translation 0.01647 0 -0.13
                      rotation 0 -1 0 0.17453
                      children [
                        Box {
                          size 0.05 0.03 0.23
                        }
                      ]
                    }
                    physics Physics {
                      density -1
                      mass 0.314
                      centerOfMass [
                        0.017829 -1.6e-05 -0.099213
                      ]
                      inertiaMatrix [
                        0.003733 0.003882 0.000177
                        -8.7e-08 -0.0006 8.38e-07
                      ]
                    }
                    linearVelocity 5.861607512174976e-09 -1.3596998565552661e-08 4.97631708052428e-09
                    angularVelocity -3.950625643069861e-07 5.2807509263242327e-08 5.7371529786654193e-08
                  }
                }
              ]
              name "FL_hip_link"
              boundingObject Pose {
                translation -0.025 0 -0.08
                children [
                  Box {
                    size 0.06 0.035 0.26
                  }
                ]
              }
              physics Physics {
                density -1
                mass 2.6
                centerOfMass [
                  -0.009099 -0.006529 -0.0688
                ]
                inertiaMatrix [
                  0.016848 0.016749 0.002088
                  -0.00031 0.001116 -0.00227
                ]
              }
              linearVelocity -7.655905847901338e-09 9.217355608232363e-09 5.182487546115602e-08
              angularVelocity -3.9496987505854027e-07 -1.2477030301763595e-07 -3.9464099121712074e-08
            }
          }
        ]
        name "FL_abd_link"
        boundingObject Pose {
          translation 0.1 0.03325 0
          rotation 1 0 0 1.570796
          children [
            Cylinder {
              height 0.1065
              radius 0.06
            }
          ]
        }
        physics Physics {
          density -1
          mass 2.86
          centerOfMass [
            0.067568 0.009593 1.4e-05
          ]
          inertiaMatrix [
            0.004368 0.007476 0.006777
            0.000362 0.000114 3.5e-05
          ]
        }
        linearVelocity -9.110093575069523e-09 -1.526160996216074e-10 9.459009776472491e-08
        angularVelocity -3.948307487442246e-07 -5.409816166105863e-08 -7.873576439677669e-10
      }
    }
    HingeJoint {
      jointParameters HingeJointParameters {
        position -0.5000143235269299
        anchor 0.2015 -0.08 0
      }
      device [
        RotationalMotor {
          name "FR_abd_joint"
          maxVelocity 21
          minPosition -0.80285
          maxPosition 0.80285
          maxTorque 100
        }
        PositionSensor {
          name "FR_abd_joint_sensor"
        }
      ]
      endPoint Solid {
        translation 0.2015 -0.08 0
        rotation -1 0 0 0.5000143235269301
        children [
          Shape {
            appearance DEF FR_abd_link_material PBRAppearance {
              baseColor 0.75294 0.75294 0.75294
              roughness 1
              metalness 0
            }
            geometry DEF FR_abd_link Mesh {
              url [
                "/home/zishang/Webots/galileo_mini_x5/protos/meshes/FR_abd_link.STL"
              ]
            }
          }
          HingeJoint {
            jointParameters HingeJointParameters {
              position 1.0499947064592867
              axis 0 1 0
              anchor 0.1 -0.10685 0
            }
            device [
              RotationalMotor {
                name "FR_hip_joint"
                maxVelocity 21
                minPosition -1.0472
                maxPosition 4.1888
                maxTorque 100
              }
              PositionSensor {
                name "FR_hip_joint_sensor"
              }
            ]
            endPoint Solid {
              translation 0.1 -0.10685 0
              rotation 0 1 0 1.0499947064592865
              children [
                Shape {
                  appearance DEF FR_hip_link_material PBRAppearance {
                    baseColor 0.75294 0.75294 0.75294
                    roughness 1
                    metalness 0
                  }
                  geometry DEF FR_hip_link Mesh {
                    url [
                      "/home/zishang/Webots/galileo_mini_x5/protos/meshes/FR_hip_link.STL"
                    ]
                  }
                }
                HingeJoint {
                  jointParameters HingeJointParameters {
                    position -2.4600244213708606
                    axis 0 1 0
                    anchor 0 0 -0.26
                  }
                  device [
                    RotationalMotor {
                      name "FR_knee_joint"
                      maxVelocity 21
                      minPosition -2.6965
                      maxPosition -0.9163
                      maxTorque 150
                    }
                    PositionSensor {
                      name "FR_knee_joint_sensor"
                    }
                  ]
                  endPoint Solid {
                    translation 0 0 -0.26
                    rotation 0 -0.9999999999999999 0 2.4600244213708606
                    children [
                      Shape {
                        appearance DEF FR_knee_link_material PBRAppearance {
                          baseColor 0.75294 0.75294 0.75294
                          roughness 1
                          metalness 0
                        }
                        geometry DEF FR_knee_link Mesh {
                          url [
                            "/home/zishang/Webots/galileo_mini_x5/protos/meshes/FR_knee_link.STL"
                          ]
                        }
                      }
                      Solid {
                        translation 0.032939 0 -0.26149
                        children [
                          Shape {
                            appearance DEF FR_foot_link_material PBRAppearance {
                              roughness 1
                              metalness 0
                            }
                            geometry Sphere {
                              radius 0.03
                            }
                          }
                        ]
                        name "FR_foot_link"
                        boundingObject Sphere {
                          radius 0.03
                        }
                        physics Physics {
                          density -1
                          mass 0.000205
                          centerOfMass [
                            0 0 0
                          ]
                          inertiaMatrix [
                            1.096e-09 1.096e-09 1.096e-09
                            0 1.7152e-40 0
                          ]
                        }
                      }
                    ]
                    name "FR_knee_link"
                    boundingObject Pose {
                      translation 0.01647 0 -0.13
                      rotation 0 -1 0 0.17453
                      children [
                        Box {
                          size 0.05 0.03 0.23
                        }
                      ]
                    }
                    physics Physics {
                      density -1
                      mass 0.314
                      centerOfMass [
                        0.017829 -1.6e-05 -0.099213
                      ]
                      inertiaMatrix [
                        0.003733 0.003882 0.000177
                        -8.7e-08 -0.0006 8.38e-07
                      ]
                    }
                    linearVelocity 5.323784394675927e-09 1.2868362195563335e-08 8.235057946388245e-09
                    angularVelocity 4.101219591664565e-07 4.645084088786778e-08 -5.473434093848999e-08
                  }
                }
              ]
              name "FR_hip_link"
              boundingObject Pose {
                translation -0.025 0 -0.08
                children [
                  Box {
                    size 0.06 0.035 0.26
                  }
                ]
              }
              physics Physics {
                density -1
                mass 2.6
                centerOfMass [
                  -0.009534 0.026092 -0.067392
                ]
                inertiaMatrix [
                  0.016261 0.016389 0.002194
                  0.000284 0.001143 0.002508
                ]
              }
              linearVelocity -7.574804551838139e-09 -8.1249291152347e-09 6.256164512171625e-08
              angularVelocity 4.1010261908652846e-07 -1.2399100334221484e-07 3.804328477293767e-08
            }
          }
        ]
        name "FR_abd_link"
        boundingObject Pose {
          translation 0.1 -0.03325 0
          rotation 1 0 0 1.570796
          children [
            Cylinder {
              height 0.1065
              radius 0.06
            }
          ]
        }
        physics Physics {
          density -1
          mass 2.86
          centerOfMass [
            0.067568 -0.009176 -0.000237
          ]
          inertiaMatrix [
            0.004373 0.007483 0.006775
            -0.000397 -9.6e-05 3e-05
          ]
        }
        linearVelocity -9.15264696192783e-09 -1.6019001723284114e-09 9.94186535651421e-08
        angularVelocity 4.0995226773633443e-07 -5.385102147490074e-08 -2.675418757050543e-10
      }
    }
    HingeJoint {
      jointParameters HingeJointParameters {
        position -0.5000173619956643
        anchor -0.2015 -0.08 0
      }
      device [
        RotationalMotor {
          name "HR_abd_joint"
          maxVelocity 21
          minPosition -0.80285
          maxPosition 0.80285
          maxTorque 100
        }
        PositionSensor {
          name "HR_abd_joint_sensor"
        }
      ]
      endPoint Solid {
        translation -0.2015 -0.08 0
        rotation -1 0 0 0.5000173619956645
        children [
          Shape {
            appearance DEF HR_abd_link_material PBRAppearance {
              baseColor 0.75294 0.75294 0.75294
              roughness 1
              metalness 0
            }
            geometry DEF HR_abd_link Mesh {
              url [
                "/home/zishang/Webots/galileo_mini_x5/protos/meshes/HR_abd_link.STL"
              ]
            }
          }
          HingeJoint {
            jointParameters HingeJointParameters {
              position 1.049994042189405
              axis 0 1 0
              anchor -0.1 -0.10685 0
            }
            device [
              RotationalMotor {
                name "HR_hip_joint"
                maxVelocity 21
                minPosition -1.0472
                maxPosition 4.1888
                maxTorque 100
              }
              PositionSensor {
                name "HR_hip_joint_sensor"
              }
            ]
            endPoint Solid {
              translation -0.1 -0.10685 0
              rotation 0 1 0 1.0499940421894047
              children [
                Shape {
                  appearance DEF HR_hip_link_material PBRAppearance {
                    baseColor 0.75294 0.75294 0.75294
                    roughness 1
                    metalness 0
                  }
                  geometry DEF HR_hip_link Mesh {
                    url [
                      "/home/zishang/Webots/galileo_mini_x5/protos/meshes/HR_hip_link.STL"
                    ]
                  }
                }
                HingeJoint {
                  jointParameters HingeJointParameters {
                    position -2.4600290111598264
                    axis 0 1 0
                    anchor 0 0 -0.26
                  }
                  device [
                    RotationalMotor {
                      name "HR_knee_joint"
                      maxVelocity 21
                      minPosition -2.6965
                      maxPosition -0.9163
                      maxTorque 150
                    }
                    PositionSensor {
                      name "HR_knee_joint_sensor"
                    }
                  ]
                  endPoint Solid {
                    translation 0 0 -0.26
                    rotation 0 -0.9999999999999999 0 2.4600290111598264
                    children [
                      Shape {
                        appearance DEF HR_knee_link_material PBRAppearance {
                          baseColor 0.75294 0.75294 0.75294
                          roughness 1
                          metalness 0
                        }
                        geometry DEF HR_knee_link Mesh {
                          url [
                            "/home/zishang/Webots/galileo_mini_x5/protos/meshes/HR_knee_link.STL"
                          ]
                        }
                      }
                      Solid {
                        translation 0.032939 0 -0.26149
                        children [
                          Shape {
                            appearance DEF HR_foot_link_material PBRAppearance {
                              roughness 1
                              metalness 0
                            }
                            geometry Sphere {
                              radius 0.03
                            }
                          }
                        ]
                        name "HR_foot_link"
                        boundingObject Sphere {
                          radius 0.03
                        }
                        physics Physics {
                          density -1
                          mass 0.000205
                          centerOfMass [
                            0 0 0
                          ]
                          inertiaMatrix [
                            1.096001e-09 1.096001e-09 1.096001e-09
                            0 5.284431e-42 0
                          ]
                        }
                      }
                    ]
                    name "HR_knee_link"
                    boundingObject Pose {
                      translation 0.01647 0 -0.13
                      rotation 0 -1 0 0.17453
                      children [
                        Box {
                          size 0.05 0.03 0.23
                        }
                      ]
                    }
                    physics Physics {
                      density -1
                      mass 0.314
                      centerOfMass [
                        0.017829 -1.6e-05 -0.099213
                      ]
                      inertiaMatrix [
                        0.003733 0.003882 0.000177
                        -8.7e-08 -0.0006 8.38e-07
                      ]
                    }
                    linearVelocity -1.0278842712496902e-09 2.8618839875292535e-09 2.5348188864779982e-08
                    angularVelocity 1.7162165395185572e-07 9.230134519365991e-09 -3.4905006664780087e-08
                  }
                }
              ]
              name "HR_hip_link"
              boundingObject Pose {
                translation -0.025 0 -0.08
                children [
                  Box {
                    size 0.06 0.035 0.26
                  }
                ]
              }
              physics Physics {
                density -1
                mass 2.6
                centerOfMass [
                  -0.009805 0.020667 -0.067167
                ]
                inertiaMatrix [
                  0.017144 0.016508 0.002907
                  0.000198 0.001067 0.002833
                ]
              }
              linearVelocity -9.503439680731376e-09 -4.652711175210335e-09 5.231893551282951e-08
              angularVelocity 1.716240791748206e-07 -8.770495163217355e-08 1.7924751771690234e-08
            }
          }
        ]
        name "HR_abd_link"
        boundingObject Pose {
          translation -0.1 -0.03325 0
          rotation 1 0 0 1.570796
          children [
            Cylinder {
              height 0.1065
              radius 0.06
            }
          ]
        }
        physics Physics {
          density -1
          mass 2.86
          centerOfMass [
            -0.067556 -0.009593 -1.7e-05
          ]
          inertiaMatrix [
            0.004372 0.007471 0.006768
            0.000364 -0.000106 -3.8e-05
          ]
        }
        linearVelocity -9.601515980372635e-09 -1.1720135013929875e-09 7.341317452315664e-08
        angularVelocity 1.7157906314923762e-07 -5.397712188614567e-08 -4.927637498870111e-10
      }
    }
    HingeJoint {
      jointParameters HingeJointParameters {
        position 0.5000175683173329
        anchor -0.2015 0.08 0
      }
      device [
        RotationalMotor {
          name "HL_abd_joint"
          maxVelocity 21
          minPosition -0.80285
          maxPosition 0.80285
          maxTorque 100
        }
        PositionSensor {
          name "HL_abd_joint_sensor"
        }
      ]
      endPoint Solid {
        translation -0.2015 0.08 0
        rotation 1 0 0 0.5000175683173332
        children [
          Shape {
            appearance DEF HL_abd_link_material PBRAppearance {
              baseColor 0.75294 0.75294 0.75294
              roughness 1
              metalness 0
            }
            geometry DEF HL_abd_link Mesh {
              url [
                "/home/zishang/Webots/galileo_mini_x5/protos/meshes/HL_abd_link.STL"
              ]
            }
          }
          HingeJoint {
            jointParameters HingeJointParameters {
              position 1.049993900534613
              axis 0 1 0
              anchor -0.1 0.1065 0
            }
            device [
              RotationalMotor {
                name "HL_hip_joint"
                maxVelocity 21
                minPosition -1.0472
                maxPosition 4.1888
                maxTorque 100
              }
              PositionSensor {
                name "HL_hip_joint_sensor"
              }
            ]
            endPoint Solid {
              translation -0.1 0.1065 0
              rotation 0 1 0 1.0499939005346128
              children [
                Shape {
                  appearance DEF HL_hip_link_material PBRAppearance {
                    baseColor 0.75294 0.75294 0.75294
                    roughness 1
                    metalness 0
                  }
                  geometry DEF HL_hip_link Mesh {
                    url [
                      "/home/zishang/Webots/galileo_mini_x5/protos/meshes/HL_hip_link.STL"
                    ]
                  }
                }
                HingeJoint {
                  jointParameters HingeJointParameters {
                    position -2.4600298169621073
                    axis 0 1 0
                    anchor 6.3e-05 0 -0.26
                  }
                  device [
                    RotationalMotor {
                      name "HL_knee_joint"
                      maxVelocity 21
                      minPosition -2.6965
                      maxPosition -0.9163
                      maxTorque 150
                    }
                    PositionSensor {
                      name "HL_knee_joint_sensor"
                    }
                  ]
                  endPoint Solid {
                    translation 6.3e-05 0 -0.26
                    rotation 0 -1 0 2.4600298169621073
                    children [
                      Shape {
                        appearance DEF HL_knee_link_material PBRAppearance {
                          baseColor 0.75294 0.75294 0.75294
                          roughness 1
                          metalness 0
                        }
                        geometry DEF HL_knee_link Mesh {
                          url [
                            "/home/zishang/Webots/galileo_mini_x5/protos/meshes/HL_knee_link.STL"
                          ]
                        }
                      }
                      Solid {
                        translation 0.032939 0 -0.261493
                        children [
                          Shape {
                            appearance DEF HL_foot_link_material PBRAppearance {
                              roughness 1
                              metalness 0
                            }
                            geometry Sphere {
                              radius 0.03
                            }
                          }
                        ]
                        name "HL_foot_link"
                        boundingObject Sphere {
                          radius 0.03
                        }
                        physics Physics {
                          density -1
                          mass 0.000205
                          centerOfMass [
                            0 0 0
                          ]
                          inertiaMatrix [
                            1.096001e-09 1.096001e-09 1.096001e-09
                            0 7.974876e-42 0
                          ]
                        }
                      }
                    ]
                    name "HL_knee_link"
                    boundingObject Pose {
                      translation 0.01647 0 -0.13
                      rotation 0 -1 0 0.17453
                      children [
                        Box {
                          size 0.05 0.03 0.23
                        }
                      ]
                    }
                    physics Physics {
                      density -1
                      mass 0.314
                      centerOfMass [
                        0.017829 -1.6e-05 -0.099213
                      ]
                      inertiaMatrix [
                        0.003733 0.003882 0.000177
                        -8.7e-08 -0.0006 8.38e-07
                      ]
                    }
                    linearVelocity -1.0160643703064345e-10 -3.411802139102796e-09 1.9669484871458758e-08
                    angularVelocity -1.6614307941674254e-07 8.816108126621796e-09 3.374170958484398e-08
                  }
                }
              ]
              name "HL_hip_link"
              boundingObject Pose {
                translation -0.025 0 -0.08
                children [
                  Box {
                    size 0.06 0.035 0.26
                  }
                ]
              }
              physics Physics {
                density -1
                mass 2.6
                centerOfMass [
                  -0.009036 -0.006529 -0.0688
                ]
                inertiaMatrix [
                  0.016848 0.016749 0.002088
                  -0.00031 0.001116 -0.00227
                ]
              }
              linearVelocity -9.302916453149508e-09 4.393213235854447e-09 4.437869623375744e-08
              angularVelocity -1.6610326402616204e-07 -9.05770019026898e-08 -2.051723745987712e-08
            }
          }
        ]
        name "HL_abd_link"
        boundingObject Pose {
          translation -0.1 0.03325 0
          rotation 1 0 0 1.570796
          children [
            Cylinder {
              height 0.1065
              radius 0.06
            }
          ]
        }
        physics Physics {
          density -1
          mass 2.86
          centerOfMass [
            -0.06741 0.009593 7.3e-05
          ]
          inertiaMatrix [
            0.004372 0.007471 0.006768
            0.000364 -0.000106 -3.8e-05
          ]
        }
        linearVelocity -9.430265295551366e-09 -3.2950890380977047e-11 6.745569873246027e-08
        angularVelocity -1.6605958558787906e-07 -5.40615501425518e-08 -5.393464027999736e-10
      }
    }
    Solid {
      translation 0.1 0 0.08
      children [
        Shape {
          appearance DEF manipulator_base_link_material PBRAppearance {
            baseColor 0.75294 0.75294 0.75294
            roughness 1
            metalness 0
          }
          geometry DEF manipulator_base_link Mesh {
            url [
              "/home/zishang/Webots/galileo_mini_x5/protos/meshes/manipulator_base_link.STL"
            ]
          }
        }
        HingeJoint {
          jointParameters HingeJointParameters {
            position -1.494844260038132e-08
            axis 0 0 1
            anchor 0 0 0.0605
          }
          device [
            RotationalMotor {
              name "joint1"
              maxVelocity 1000
              minPosition -10
              maxPosition 10
              maxTorque 100
            }
            PositionSensor {
              name "joint1_sensor"
            }
          ]
          endPoint Solid {
            translation 0 0 0.0605
            children [
              Shape {
                appearance DEF link1_material PBRAppearance {
                  baseColor 0.79216 0.81961 0.93333
                  roughness 1
                  metalness 0
                }
                geometry DEF link1 Mesh {
                  url [
                    "/home/zishang/Webots/galileo_mini_x5/protos/meshes/link1.STL"
                  ]
                }
              }
              HingeJoint {
                jointParameters HingeJointParameters {
                  position -1.568156156424825e-06
                  axis 0 1 0
                  anchor 0.02 0 0.04
                }
                device [
                  RotationalMotor {
                    name "joint2"
                    maxVelocity 1000
                    minPosition -10
                    maxPosition 10
                    maxTorque 100
                  }
                  PositionSensor {
                    name "joint2_sensor"
                  }
                ]
                endPoint Solid {
                  translation 0.02 0 0.04
                  rotation 0 -1 0 1.5682366033700951e-06
                  children [
                    Shape {
                      appearance DEF link2_material PBRAppearance {
                        baseColor 0.75294 0.75294 0.75294
                        roughness 1
                        metalness 0
                      }
                      geometry DEF link2 Mesh {
                        url [
                          "/home/zishang/Webots/galileo_mini_x5/protos/meshes/link2.STL"
                        ]
                      }
                    }
                    HingeJoint {
                      jointParameters HingeJointParameters {
                        position -1.151186623744686e-05
                        axis 0 -1 -7e-06
                        anchor -0.264 0 0
                      }
                      device [
                        RotationalMotor {
                          name "joint3"
                          maxVelocity 1000
                          minPosition -10
                          maxPosition 10
                          maxTorque 100
                        }
                        PositionSensor {
                          name "joint3_sensor"
                        }
                      ]
                      endPoint Solid {
                        translation -0.264 0 0
                        rotation 0.9999999999834347 1.9148808925024214e-11 -5.7559331186986195e-06 3.1416
                        children [
                          Shape {
                            appearance DEF link3_material PBRAppearance {
                              baseColor 1 0.98431 0.96471
                              roughness 1
                              metalness 0
                            }
                            geometry DEF link3 Mesh {
                              url [
                                "/home/zishang/Webots/galileo_mini_x5/protos/meshes/link3.STL"
                              ]
                            }
                          }
                          HingeJoint {
                            jointParameters HingeJointParameters {
                              position -2.7703904999817173e-06
                              axis 0 1 0
                              anchor 0.245 0 -0.056
                            }
                            device [
                              RotationalMotor {
                                name "joint4"
                                maxVelocity 1000
                                minPosition -10
                                maxPosition 10
                                maxTorque 100
                              }
                              PositionSensor {
                                name "joint4_sensor"
                              }
                            ]
                            endPoint Solid {
                              translation 0.245 0 -0.056
                              rotation 0 -1 0 2.7703338651920655e-06
                              children [
                                Shape {
                                  appearance DEF link4_material PBRAppearance {
                                    baseColor 0.79216 0.81961 0.92941
                                    roughness 1
                                    metalness 0
                                  }
                                  geometry DEF link4 Mesh {
                                    url [
                                      "/home/zishang/Webots/galileo_mini_x5/protos/meshes/link4.STL"
                                    ]
                                  }
                                }
                                HingeJoint {
                                  jointParameters HingeJointParameters {
                                    position 4.2980411483037135e-08
                                    axis 0 0 1
                                    anchor 0.06775 0.0005 -0.0865
                                  }
                                  device [
                                    RotationalMotor {
                                      name "joint5"
                                      maxVelocity 1000
                                      minPosition -10
                                      maxPosition 10
                                      maxTorque 100
                                    }
                                    PositionSensor {
                                      name "joint5_sensor"
                                    }
                                  ]
                                  endPoint Solid {
                                    translation 0.06775 0.0005 -0.0865
                                    rotation 0 0 0.9999999999999999 4.2146848510894035e-08
                                    children [
                                      Shape {
                                        appearance DEF link5_material PBRAppearance {
                                          baseColor 0.69804 0.69804 0.69804
                                          roughness 1
                                          metalness 0
                                        }
                                        geometry DEF link5 Mesh {
                                          url [
                                            "/home/zishang/Webots/galileo_mini_x5/protos/meshes/link5.STL"
                                          ]
                                        }
                                      }
                                      HingeJoint {
                                        jointParameters HingeJointParameters {
                                          position -2.632295482929675e-08
                                          anchor 0.02895 0 0.0865
                                        }
                                        device [
                                          RotationalMotor {
                                            name "joint6"
                                            maxVelocity 1000
                                            minPosition -10
                                            maxPosition 10
                                            maxTorque 100
                                          }
                                          PositionSensor {
                                            name "joint6_sensor"
                                          }
                                        ]
                                        endPoint Solid {
                                          translation 0.02895 0 0.0865
                                          rotation -1 0 0 3.1416000266294297
                                          children [
                                            Shape {
                                              appearance DEF link6_material PBRAppearance {
                                                baseColor 0.89804 0.91765 0.92941
                                                roughness 1
                                                metalness 0
                                              }
                                              geometry DEF link6 Mesh {
                                                url [
                                                  "/home/zishang/Webots/galileo_mini_x5/protos/meshes/link6.STL"
                                                ]
                                              }
                                            }
                                            Solid {
                                              translation 0.08657 0.024896 -0.000244
                                              children [
                                                Shape {
                                                  appearance DEF link7_material PBRAppearance {
                                                    roughness 1
                                                    metalness 0
                                                  }
                                                  geometry DEF link7 Mesh {
                                                    url [
                                                      "/home/zishang/Webots/galileo_mini_x5/protos/meshes/link7.STL"
                                                    ]
                                                  }
                                                }
                                              ]
                                              name "link7"
                                              physics Physics {
                                                density -1
                                                mass 0.064798
                                                centerOfMass [
                                                  -0.000355 -0.007827 -0.002988
                                                ]
                                                inertiaMatrix [
                                                  2e-05 3e-05 3e-05
                                                  0 0 0
                                                ]
                                              }
                                            }
                                            Solid {
                                              translation 0.08657 -0.0249 -0.000244
                                              children [
                                                Shape {
                                                  appearance DEF link8_material PBRAppearance {
                                                    roughness 1
                                                    metalness 0
                                                  }
                                                  geometry DEF link8 Mesh {
                                                    url [
                                                      "/home/zishang/Webots/galileo_mini_x5/protos/meshes/link8.STL"
                                                    ]
                                                  }
                                                }
                                              ]
                                              name "link8"
                                              physics Physics {
                                                density -1
                                                mass 0.064798
                                                centerOfMass [
                                                  -0.000355 0.007828 0.00242
                                                ]
                                                inertiaMatrix [
                                                  2e-05 3e-05 3e-05
                                                  0 0 0
                                                ]
                                              }
                                            }
                                          ]
                                          name "link6"
                                          physics Physics {
                                            density -1
                                            mass 0.44089
                                            centerOfMass [
                                              0.041697 2.4e-05 0.000145
                                            ]
                                            inertiaMatrix [
                                              0.00038 0.00028 0.0005
                                              0 0 0
                                            ]
                                          }
                                          linearVelocity -2.330129529421942e-08 -2.2317342644936568e-08 1.0518661551457816e-07
                                          angularVelocity -1.8333965026230053e-07 -6.45102810339673e-08 -3.2186158588735815e-07
                                        }
                                      }
                                    ]
                                    name "link5"
                                    physics Physics {
                                      density -1
                                      mass 0.63488
                                      centerOfMass [
                                        0.003612 -1.5e-05 0.055214
                                      ]
                                      inertiaMatrix [
                                        0.00083 0.00082 0.00026
                                        0 7e-05 0
                                      ]
                                    }
                                    linearVelocity -2.529297511427615e-08 3.4806455362030197e-09 1.0015076029215274e-07
                                    angularVelocity -3.7338043834964564e-08 -6.447845292974012e-08 -3.2185158837874234e-07
                                  }
                                }
                              ]
                              name "link4"
                              physics Physics {
                                density -1
                                mass 0.11714
                                centerOfMass [
                                  0.040231 0.004481 -0.035335
                                ]
                                inertiaMatrix [
                                  0.00019 0.00023 0.00014
                                  -2e-05 -9e-05 2e-05
                                ]
                              }
                              linearVelocity -2.5810367235692574e-08 6.80890897564408e-09 9.816223384194367e-08
                              angularVelocity -3.739713644883952e-08 -6.457847670361708e-08 -8.257188273374559e-08
                            }
                          }
                        ]
                        name "link3"
                        physics Physics {
                          density -1
                          mass 0.54534
                          centerOfMass [
                            0.18531 0.000684 -0.051638
                          ]
                          inertiaMatrix [
                            0.00036 0.00423 0.0042
                            -3e-05 -0.00039 1e-05
                          ]
                        }
                        linearVelocity -2.284728943055842e-08 1.331378028714403e-08 9.14313350759232e-08
                        angularVelocity -3.7395601618207865e-08 -6.453411542741785e-08 -8.26098231916629e-08
                      }
                    }
                  ]
                  name "link2"
                  physics Physics {
                    density -1
                    mass 1.0795
                    centerOfMass [
                      -0.13237 0.002085 0.000105
                    ]
                    inertiaMatrix [
                      0.00051 0.01599 0.01605
                      1e-05 -4e-05 0
                    ]
                  }
                  linearVelocity -1.917185438939277e-08 1.5566828957526292e-08 8.630316890345601e-08
                  angularVelocity -3.7382798907091646e-08 -5.405292038765103e-08 -8.270745451951428e-08
                }
              }
            ]
            name "link1"
            physics Physics {
              density -1
              mass 0.066982
              centerOfMass [
                0.005423 -0.008029 0.017086
              ]
              inertiaMatrix [
                8e-05 3e-05 8e-05
                0 1e-05 0
              ]
            }
            linearVelocity -1.858886120162502e-08 4.8218640219112275e-09 9.27965332793905e-08
            angularVelocity -3.73680622703466e-08 -5.3989014109652484e-08 -8.277346678682646e-08
          }
        }
      ]
      name "manipulator_base_link"
      physics Physics {
        density -1
        mass 0.43995
        centerOfMass [
          -3e-05 3.1e-05 0.027324
        ]
        inertiaMatrix [
          0.00017 0.00017 0.00016
          0 0 0
        ]
      }
    }
  ]
  name "galileo_mini_x5"
  boundingObject Box {
    size 0.45 0.25 0.1
  }
  physics Physics {
    density -1
    mass 20.8
    centerOfMass [
      0.03738 -0.00659 0.005793
    ]
    inertiaMatrix [
      0.131102 0.407915 0.476755
      0.001924 0.001299 0.002595
    ]
  }
  controller "<extern>"
  supervisor TRUE
}
