#VRML_SIM R2025a utf8

EXTERNPROTO "https://raw.githubusercontent.com/cyberbotics/webots/R2025a/projects/objects/backgrounds/protos/TexturedBackground.proto"
EXTERNPROTO "https://raw.githubusercontent.com/cyberbotics/webots/R2025a/projects/objects/backgrounds/protos/TexturedBackgroundLight.proto"
EXTERNPROTO "https://raw.githubusercontent.com/cyberbotics/webots/R2025a/projects/objects/floors/protos/RectangleArena.proto"

WorldInfo {
  basicTimeStep 1
}
Viewpoint {
  orientation 0.1496517620427634 0.04926126548280198 -0.9875108494799076 2.51299861809113
  position 1.3348658370561404 1.2060355725571867 0.9283105336977925
}
TexturedBackground {
}
TexturedBackgroundLight {
}
RectangleArena {
  floorSize 20 20
}
DEF galileo_mini_x5 Robot {
  translation -0.011260799571310178 -0.0001364248460208996 0.3997463389544853
  rotation 0.43798120856535133 -0.424245874376198 0.7925830549654778 0.00017010652278195423
  children [
    Solid {
      children [
        InertialUnit {
          name "imu_link_imu"
        }
        Accelerometer {
          name "imu_link_accelerometer"
        }
        Gyro {
          name "imu_link_gyro"
        }
      ]
      name "imu_link"
      boundingObject Box {
        size 0.001 0.001 0.001
      }
      physics Physics {
        density -1
        mass 0.001
      }
    }
    Shape {
      appearance DEF base_link_material PBRAppearance {
        baseColor 0.75294 0.75294 0.75294
        roughness 1
        metalness 0
      }
      geometry DEF base_link Mesh {
        url [
          "/home/zishang/Webots/galileo_mini_x5/protos/meshes/base_link.STL"
        ]
      }
    }
    HingeJoint {
      jointParameters HingeJointParameters {
        position 9.361139608795074e-06
        anchor 0.2015 0.08 0
      }
      device [
        RotationalMotor {
          name "FL_abd_joint"
          maxVelocity 21
          minPosition -0.80285
          maxPosition 0.80285
          maxTorque 100
        }
        PositionSensor {
          name "FL_abd_joint_sensor"
        }
      ]
      endPoint Solid {
        translation 0.2015 0.08 0
        rotation 1 0 0 9.361155676595339e-06
        children [
          Shape {
            appearance DEF FL_abd_link_material PBRAppearance {
              baseColor 0.75294 0.75294 0.75294
              roughness 1
              metalness 0
            }
            geometry DEF FL_abd_link Mesh {
              url [
                "/home/zishang/Webots/galileo_mini_x5/protos/meshes/FL_abd_link.STL"
              ]
            }
          }
          HingeJoint {
            jointParameters HingeJointParameters {
              position 0.7199952381766677
              axis 0 1 0
              anchor 0.1 0.1065 0
            }
            device [
              RotationalMotor {
                name "FL_hip_joint"
                maxVelocity 21
                minPosition -1.0472
                maxPosition 4.1888
                maxTorque 100
              }
              PositionSensor {
                name "FL_hip_joint_sensor"
              }
            ]
            endPoint Solid {
              translation 0.1 0.1065 0
              rotation 0 1 0 0.7199952381766677
              children [
                Shape {
                  appearance DEF FL_hip_link_material PBRAppearance {
                    baseColor 0.75294 0.75294 0.75294
                    roughness 1
                    metalness 0
                  }
                  geometry DEF FL_hip_link Mesh {
                    url [
                      "/home/zishang/Webots/galileo_mini_x5/protos/meshes/FL_hip_link.STL"
                    ]
                  }
                }
                HingeJoint {
                  jointParameters HingeJointParameters {
                    position -1.4400229706951158
                    axis 0 1 0
                    anchor 0 0 -0.26
                  }
                  device [
                    RotationalMotor {
                      name "FL_knee_joint"
                      maxVelocity 21
                      minPosition -2.6965
                      maxPosition -0.9163
                      maxTorque 150
                    }
                    PositionSensor {
                      name "FL_knee_joint_sensor"
                    }
                  ]
                  endPoint Solid {
                    translation 0 0 -0.26
                    rotation 0 -1 0 1.4400229706951158
                    children [
                      Shape {
                        appearance DEF FL_knee_link_material PBRAppearance {
                          baseColor 0.75294 0.75294 0.75294
                          roughness 1
                          metalness 0
                        }
                        geometry DEF FL_knee_link Mesh {
                          url [
                            "/home/zishang/Webots/galileo_mini_x5/protos/meshes/FL_knee_link.STL"
                          ]
                        }
                      }
                      Solid {
                        translation 0.032939 0 -0.26149
                        children [
                          Shape {
                            appearance DEF FL_foot_link_material PBRAppearance {
                              roughness 1
                              metalness 0
                            }
                            geometry Sphere {
                              radius 0.03
                            }
                          }
                        ]
                        name "FL_foot_link"
                        boundingObject Sphere {
                          radius 0.03
                        }
                        physics Physics {
                          density -1
                          mass 0.000205
                          centerOfMass [
                            0 0 0
                          ]
                          inertiaMatrix [
                            1.096e-09 1.096e-09 1.096e-09
                            -2.0392e-56 0 0
                          ]
                        }
                      }
                    ]
                    name "FL_knee_link"
                    boundingObject Pose {
                      translation 0.01647 0 -0.13
                      rotation 0 -1 0 0.17453
                      children [
                        Box {
                          size 0.05 0.03 0.23
                        }
                      ]
                    }
                    physics Physics {
                      density -1
                      mass 0.314
                      centerOfMass [
                        0.017829 -1.6e-05 -0.099213
                      ]
                      inertiaMatrix [
                        0.003733 0.003882 0.000177
                        -8.7e-08 -0.0006 8.38e-07
                      ]
                    }
                  }
                }
              ]
              name "FL_hip_link"
              boundingObject Pose {
                translation -0.025 0 -0.08
                children [
                  Box {
                    size 0.06 0.035 0.26
                  }
                ]
              }
              physics Physics {
                density -1
                mass 2.6
                centerOfMass [
                  -0.009099 -0.006529 -0.0688
                ]
                inertiaMatrix [
                  0.016848 0.016749 0.002088
                  -0.00031 0.001116 -0.00227
                ]
              }
            }
          }
        ]
        name "FL_abd_link"
        boundingObject Pose {
          translation 0.1 0.03325 0
          rotation 1 0 0 1.570796
          children [
            Cylinder {
              height 0.1065
              radius 0.06
            }
          ]
        }
        physics Physics {
          density -1
          mass 2.86
          centerOfMass [
            0.067568 0.009593 1.4e-05
          ]
          inertiaMatrix [
            0.004368 0.007476 0.006777
            0.000362 0.000114 3.5e-05
          ]
        }
      }
    }
    HingeJoint {
      jointParameters HingeJointParameters {
        position -1.057373189336022e-05
        anchor 0.2015 -0.08 0
      }
      device [
        RotationalMotor {
          name "FR_abd_joint"
          maxVelocity 21
          minPosition -0.80285
          maxPosition 0.80285
          maxTorque 100
        }
        PositionSensor {
          name "FR_abd_joint_sensor"
        }
      ]
      endPoint Solid {
        translation 0.2015 -0.08 0
        rotation -1 0 0 1.0573736306155558e-05
        children [
          Shape {
            appearance DEF FR_abd_link_material PBRAppearance {
              baseColor 0.75294 0.75294 0.75294
              roughness 1
              metalness 0
            }
            geometry DEF FR_abd_link Mesh {
              url [
                "/home/zishang/Webots/galileo_mini_x5/protos/meshes/FR_abd_link.STL"
              ]
            }
          }
          HingeJoint {
            jointParameters HingeJointParameters {
              position 0.7199951166798714
              axis 0 1 0
              anchor 0.1 -0.10685 0
            }
            device [
              RotationalMotor {
                name "FR_hip_joint"
                maxVelocity 21
                minPosition -1.0472
                maxPosition 4.1888
                maxTorque 100
              }
              PositionSensor {
                name "FR_hip_joint_sensor"
              }
            ]
            endPoint Solid {
              translation 0.1 -0.10685 0
              rotation 0 1 0 0.7199951166798716
              children [
                Shape {
                  appearance DEF FR_hip_link_material PBRAppearance {
                    baseColor 0.75294 0.75294 0.75294
                    roughness 1
                    metalness 0
                  }
                  geometry DEF FR_hip_link Mesh {
                    url [
                      "/home/zishang/Webots/galileo_mini_x5/protos/meshes/FR_hip_link.STL"
                    ]
                  }
                }
                HingeJoint {
                  jointParameters HingeJointParameters {
                    position -1.440024125133309
                    axis 0 1 0
                    anchor 0 0 -0.26
                  }
                  device [
                    RotationalMotor {
                      name "FR_knee_joint"
                      maxVelocity 21
                      minPosition -2.6965
                      maxPosition -0.9163
                      maxTorque 150
                    }
                    PositionSensor {
                      name "FR_knee_joint_sensor"
                    }
                  ]
                  endPoint Solid {
                    translation 0 0 -0.26
                    rotation 0 -1 0 1.440024125133309
                    children [
                      Shape {
                        appearance DEF FR_knee_link_material PBRAppearance {
                          baseColor 0.75294 0.75294 0.75294
                          roughness 1
                          metalness 0
                        }
                        geometry DEF FR_knee_link Mesh {
                          url [
                            "/home/zishang/Webots/galileo_mini_x5/protos/meshes/FR_knee_link.STL"
                          ]
                        }
                      }
                      Solid {
                        translation 0.032939 0 -0.26149
                        children [
                          Shape {
                            appearance DEF FR_foot_link_material PBRAppearance {
                              roughness 1
                              metalness 0
                            }
                            geometry Sphere {
                              radius 0.03
                            }
                          }
                        ]
                        name "FR_foot_link"
                        boundingObject Sphere {
                          radius 0.03
                        }
                        physics Physics {
                          density -1
                          mass 0.000205
                          centerOfMass [
                            0 0 0
                          ]
                          inertiaMatrix [
                            1.096e-09 1.096e-09 1.096e-09
                            0 1.7152e-40 0
                          ]
                        }
                      }
                    ]
                    name "FR_knee_link"
                    boundingObject Pose {
                      translation 0.01647 0 -0.13
                      rotation 0 -1 0 0.17453
                      children [
                        Box {
                          size 0.05 0.03 0.23
                        }
                      ]
                    }
                    physics Physics {
                      density -1
                      mass 0.314
                      centerOfMass [
                        0.017829 -1.6e-05 -0.099213
                      ]
                      inertiaMatrix [
                        0.003733 0.003882 0.000177
                        -8.7e-08 -0.0006 8.38e-07
                      ]
                    }
                  }
                }
              ]
              name "FR_hip_link"
              boundingObject Pose {
                translation -0.025 0 -0.08
                children [
                  Box {
                    size 0.06 0.035 0.26
                  }
                ]
              }
              physics Physics {
                density -1
                mass 2.6
                centerOfMass [
                  -0.009534 0.026092 -0.067392
                ]
                inertiaMatrix [
                  0.016261 0.016389 0.002194
                  0.000284 0.001143 0.002508
                ]
              }
            }
          }
        ]
        name "FR_abd_link"
        boundingObject Pose {
          translation 0.1 -0.03325 0
          rotation 1 0 0 1.570796
          children [
            Cylinder {
              height 0.1065
              radius 0.06
            }
          ]
        }
        physics Physics {
          density -1
          mass 2.86
          centerOfMass [
            0.067568 -0.009176 -0.000237
          ]
          inertiaMatrix [
            0.004373 0.007483 0.006775
            -0.000397 -9.6e-05 3e-05
          ]
        }
      }
    }
    HingeJoint {
      jointParameters HingeJointParameters {
        position -1.1081399080137088e-05
        anchor -0.2015 -0.08 0
      }
      device [
        RotationalMotor {
          name "HR_abd_joint"
          maxVelocity 21
          minPosition -0.80285
          maxPosition 0.80285
          maxTorque 100
        }
        PositionSensor {
          name "HR_abd_joint_sensor"
        }
      ]
      endPoint Solid {
        translation -0.2015 -0.08 0
        rotation -1 0 0 1.1081415611338384e-05
        children [
          Shape {
            appearance DEF HR_abd_link_material PBRAppearance {
              baseColor 0.75294 0.75294 0.75294
              roughness 1
              metalness 0
            }
            geometry DEF HR_abd_link Mesh {
              url [
                "/home/zishang/Webots/galileo_mini_x5/protos/meshes/HR_abd_link.STL"
              ]
            }
          }
          HingeJoint {
            jointParameters HingeJointParameters {
              position 0.7199947840934279
              axis 0 1 0
              anchor -0.1 -0.10685 0
            }
            device [
              RotationalMotor {
                name "HR_hip_joint"
                maxVelocity 21
                minPosition -1.0472
                maxPosition 4.1888
                maxTorque 100
              }
              PositionSensor {
                name "HR_hip_joint_sensor"
              }
            ]
            endPoint Solid {
              translation -0.1 -0.10685 0
              rotation 0 1 0 0.7199947840934279
              children [
                Shape {
                  appearance DEF HR_hip_link_material PBRAppearance {
                    baseColor 0.75294 0.75294 0.75294
                    roughness 1
                    metalness 0
                  }
                  geometry DEF HR_hip_link Mesh {
                    url [
                      "/home/zishang/Webots/galileo_mini_x5/protos/meshes/HR_hip_link.STL"
                    ]
                  }
                }
                HingeJoint {
                  jointParameters HingeJointParameters {
                    position -1.4400259824906654
                    axis 0 1 0
                    anchor 0 0 -0.26
                  }
                  device [
                    RotationalMotor {
                      name "HR_knee_joint"
                      maxVelocity 21
                      minPosition -2.6965
                      maxPosition -0.9163
                      maxTorque 150
                    }
                    PositionSensor {
                      name "HR_knee_joint_sensor"
                    }
                  ]
                  endPoint Solid {
                    translation 0 0 -0.26
                    rotation 0 -1 0 1.4400259824906654
                    children [
                      Shape {
                        appearance DEF HR_knee_link_material PBRAppearance {
                          baseColor 0.75294 0.75294 0.75294
                          roughness 1
                          metalness 0
                        }
                        geometry DEF HR_knee_link Mesh {
                          url [
                            "/home/zishang/Webots/galileo_mini_x5/protos/meshes/HR_knee_link.STL"
                          ]
                        }
                      }
                      Solid {
                        translation 0.032939 0 -0.26149
                        children [
                          Shape {
                            appearance DEF HR_foot_link_material PBRAppearance {
                              roughness 1
                              metalness 0
                            }
                            geometry Sphere {
                              radius 0.03
                            }
                          }
                        ]
                        name "HR_foot_link"
                        boundingObject Sphere {
                          radius 0.03
                        }
                        physics Physics {
                          density -1
                          mass 0.000205
                          centerOfMass [
                            0 0 0
                          ]
                          inertiaMatrix [
                            1.096001e-09 1.096001e-09 1.096001e-09
                            0 5.284431e-42 0
                          ]
                        }
                      }
                    ]
                    name "HR_knee_link"
                    boundingObject Pose {
                      translation 0.01647 0 -0.13
                      rotation 0 -1 0 0.17453
                      children [
                        Box {
                          size 0.05 0.03 0.23
                        }
                      ]
                    }
                    physics Physics {
                      density -1
                      mass 0.314
                      centerOfMass [
                        0.017829 -1.6e-05 -0.099213
                      ]
                      inertiaMatrix [
                        0.003733 0.003882 0.000177
                        -8.7e-08 -0.0006 8.38e-07
                      ]
                    }
                  }
                }
              ]
              name "HR_hip_link"
              boundingObject Pose {
                translation -0.025 0 -0.08
                children [
                  Box {
                    size 0.06 0.035 0.26
                  }
                ]
              }
              physics Physics {
                density -1
                mass 2.6
                centerOfMass [
                  -0.009805 0.020667 -0.067167
                ]
                inertiaMatrix [
                  0.017144 0.016508 0.002907
                  0.000198 0.001067 0.002833
                ]
              }
            }
          }
        ]
        name "HR_abd_link"
        boundingObject Pose {
          translation -0.1 -0.03325 0
          rotation 1 0 0 1.570796
          children [
            Cylinder {
              height 0.1065
              radius 0.06
            }
          ]
        }
        physics Physics {
          density -1
          mass 2.86
          centerOfMass [
            -0.067556 -0.009593 -1.7e-05
          ]
          inertiaMatrix [
            0.004372 0.007471 0.006768
            0.000364 -0.000106 -3.8e-05
          ]
        }
      }
    }
    HingeJoint {
      jointParameters HingeJointParameters {
        position 1.1021374872737688e-05
        anchor -0.2015 0.08 0
      }
      device [
        RotationalMotor {
          name "HL_abd_joint"
          maxVelocity 21
          minPosition -0.80285
          maxPosition 0.80285
          maxTorque 100
        }
        PositionSensor {
          name "HL_abd_joint_sensor"
        }
      ]
      endPoint Solid {
        translation -0.2015 0.08 0
        rotation 1 0 0 1.1021380738917212e-05
        children [
          Shape {
            appearance DEF HL_abd_link_material PBRAppearance {
              baseColor 0.75294 0.75294 0.75294
              roughness 1
              metalness 0
            }
            geometry DEF HL_abd_link Mesh {
              url [
                "/home/zishang/Webots/galileo_mini_x5/protos/meshes/HL_abd_link.STL"
              ]
            }
          }
          HingeJoint {
            jointParameters HingeJointParameters {
              position 0.7199946815243207
              axis 0 1 0
              anchor -0.1 0.1065 0
            }
            device [
              RotationalMotor {
                name "HL_hip_joint"
                maxVelocity 21
                minPosition -1.0472
                maxPosition 4.1888
                maxTorque 100
              }
              PositionSensor {
                name "HL_hip_joint_sensor"
              }
            ]
            endPoint Solid {
              translation -0.1 0.1065 0
              rotation 0 1 0 0.7199946815243207
              children [
                Shape {
                  appearance DEF HL_hip_link_material PBRAppearance {
                    baseColor 0.75294 0.75294 0.75294
                    roughness 1
                    metalness 0
                  }
                  geometry DEF HL_hip_link Mesh {
                    url [
                      "/home/zishang/Webots/galileo_mini_x5/protos/meshes/HL_hip_link.STL"
                    ]
                  }
                }
                HingeJoint {
                  jointParameters HingeJointParameters {
                    position -1.4400266446391223
                    axis 0 1 0
                    anchor 6.3e-05 0 -0.26
                  }
                  device [
                    RotationalMotor {
                      name "HL_knee_joint"
                      maxVelocity 21
                      minPosition -2.6965
                      maxPosition -0.9163
                      maxTorque 150
                    }
                    PositionSensor {
                      name "HL_knee_joint_sensor"
                    }
                  ]
                  endPoint Solid {
                    translation 6.3e-05 0 -0.26
                    rotation 0 -0.9999999999999999 0 1.4400266446391223
                    children [
                      Shape {
                        appearance DEF HL_knee_link_material PBRAppearance {
                          baseColor 0.75294 0.75294 0.75294
                          roughness 1
                          metalness 0
                        }
                        geometry DEF HL_knee_link Mesh {
                          url [
                            "/home/zishang/Webots/galileo_mini_x5/protos/meshes/HL_knee_link.STL"
                          ]
                        }
                      }
                      Solid {
                        translation 0.032939 0 -0.261493
                        children [
                          Shape {
                            appearance DEF HL_foot_link_material PBRAppearance {
                              roughness 1
                              metalness 0
                            }
                            geometry Sphere {
                              radius 0.03
                            }
                          }
                        ]
                        name "HL_foot_link"
                        boundingObject Sphere {
                          radius 0.03
                        }
                        physics Physics {
                          density -1
                          mass 0.000205
                          centerOfMass [
                            0 0 0
                          ]
                          inertiaMatrix [
                            1.096001e-09 1.096001e-09 1.096001e-09
                            0 7.974876e-42 0
                          ]
                        }
                      }
                    ]
                    name "HL_knee_link"
                    boundingObject Pose {
                      translation 0.01647 0 -0.13
                      rotation 0 -1 0 0.17453
                      children [
                        Box {
                          size 0.05 0.03 0.23
                        }
                      ]
                    }
                    physics Physics {
                      density -1
                      mass 0.314
                      centerOfMass [
                        0.017829 -1.6e-05 -0.099213
                      ]
                      inertiaMatrix [
                        0.003733 0.003882 0.000177
                        -8.7e-08 -0.0006 8.38e-07
                      ]
                    }
                  }
                }
              ]
              name "HL_hip_link"
              boundingObject Pose {
                translation -0.025 0 -0.08
                children [
                  Box {
                    size 0.06 0.035 0.26
                  }
                ]
              }
              physics Physics {
                density -1
                mass 2.6
                centerOfMass [
                  -0.009036 -0.006529 -0.0688
                ]
                inertiaMatrix [
                  0.016848 0.016749 0.002088
                  -0.00031 0.001116 -0.00227
                ]
              }
            }
          }
        ]
        name "HL_abd_link"
        boundingObject Pose {
          translation -0.1 0.03325 0
          rotation 1 0 0 1.570796
          children [
            Cylinder {
              height 0.1065
              radius 0.06
            }
          ]
        }
        physics Physics {
          density -1
          mass 2.86
          centerOfMass [
            -0.06741 0.009593 7.3e-05
          ]
          inertiaMatrix [
            0.004372 0.007471 0.006768
            0.000364 -0.000106 -3.8e-05
          ]
        }
      }
    }
    Solid {
      translation 0.1 0 0.08
      children [
        Shape {
          appearance DEF manipulator_base_link_material PBRAppearance {
            baseColor 0.75294 0.75294 0.75294
            roughness 1
            metalness 0
          }
          geometry DEF manipulator_base_link Mesh {
            url [
              "/home/zishang/Webots/galileo_mini_x5/protos/meshes/manipulator_base_link.STL"
            ]
          }
        }
        HingeJoint {
          jointParameters HingeJointParameters {
            position -6.64775623989623e-09
            axis 0 0 1
            anchor 0 0 0.0605
          }
          device [
            RotationalMotor {
              name "joint1"
              maxVelocity 1000
              minPosition -10
              maxPosition 10
              maxTorque 100
            }
            PositionSensor {
              name "joint1_sensor"
            }
          ]
          endPoint Solid {
            translation 0 0 0.0605
            children [
              Shape {
                appearance DEF link1_material PBRAppearance {
                  baseColor 0.79216 0.81961 0.93333
                  roughness 1
                  metalness 0
                }
                geometry DEF link1 Mesh {
                  url [
                    "/home/zishang/Webots/galileo_mini_x5/protos/meshes/link1.STL"
                  ]
                }
              }
              HingeJoint {
                jointParameters HingeJointParameters {
                  position -8.205181515860339e-07
                  axis 0 1 0
                  anchor 0.02 0 0.04
                }
                device [
                  RotationalMotor {
                    name "joint2"
                    maxVelocity 1000
                    minPosition -10
                    maxPosition 10
                    maxTorque 100
                  }
                  PositionSensor {
                    name "joint2_sensor"
                  }
                ]
                endPoint Solid {
                  translation 0.02 0 0.04
                  rotation 0 -1 0 8.205115734300793e-07
                  children [
                    Shape {
                      appearance DEF link2_material PBRAppearance {
                        baseColor 0.75294 0.75294 0.75294
                        roughness 1
                        metalness 0
                      }
                      geometry DEF link2 Mesh {
                        url [
                          "/home/zishang/Webots/galileo_mini_x5/protos/meshes/link2.STL"
                        ]
                      }
                    }
                    HingeJoint {
                      jointParameters HingeJointParameters {
                        position -6.0192064002661355e-06
                        axis 0 -1 -7e-06
                        anchor -0.264 0 0
                      }
                      device [
                        RotationalMotor {
                          name "joint3"
                          maxVelocity 1000
                          minPosition -10
                          maxPosition 10
                          maxTorque 100
                        }
                        PositionSensor {
                          name "joint3_sensor"
                        }
                      ]
                      endPoint Solid {
                        translation -0.264 0 0
                        rotation 0.9999999999954713 1.0012332567263126e-11 -3.0096032001321703e-06 3.1416
                        children [
                          Shape {
                            appearance DEF link3_material PBRAppearance {
                              baseColor 1 0.98431 0.96471
                              roughness 1
                              metalness 0
                            }
                            geometry DEF link3 Mesh {
                              url [
                                "/home/zishang/Webots/galileo_mini_x5/protos/meshes/link3.STL"
                              ]
                            }
                          }
                          HingeJoint {
                            jointParameters HingeJointParameters {
                              position -1.4485914582059556e-06
                              axis 0 1 0
                              anchor 0.245 0 -0.056
                            }
                            device [
                              RotationalMotor {
                                name "joint4"
                                maxVelocity 1000
                                minPosition -10
                                maxPosition 10
                                maxTorque 100
                              }
                              PositionSensor {
                                name "joint4_sensor"
                              }
                            ]
                            endPoint Solid {
                              translation 0.245 0 -0.056
                              rotation 0 -1 0 1.4487117055340886e-06
                              children [
                                Shape {
                                  appearance DEF link4_material PBRAppearance {
                                    baseColor 0.79216 0.81961 0.92941
                                    roughness 1
                                    metalness 0
                                  }
                                  geometry DEF link4 Mesh {
                                    url [
                                      "/home/zishang/Webots/galileo_mini_x5/protos/meshes/link4.STL"
                                    ]
                                  }
                                }
                                HingeJoint {
                                  jointParameters HingeJointParameters {
                                    position 1.925006134393391e-08
                                    axis 0 0 1
                                    anchor 0.06775 0.0005 -0.0865
                                  }
                                  device [
                                    RotationalMotor {
                                      name "joint5"
                                      maxVelocity 1000
                                      minPosition -10
                                      maxPosition 10
                                      maxTorque 100
                                    }
                                    PositionSensor {
                                      name "joint5_sensor"
                                    }
                                  ]
                                  endPoint Solid {
                                    translation 0.06775 0.0005 -0.0865
                                    children [
                                      Shape {
                                        appearance DEF link5_material PBRAppearance {
                                          baseColor 0.69804 0.69804 0.69804
                                          roughness 1
                                          metalness 0
                                        }
                                        geometry DEF link5 Mesh {
                                          url [
                                            "/home/zishang/Webots/galileo_mini_x5/protos/meshes/link5.STL"
                                          ]
                                        }
                                      }
                                      HingeJoint {
                                        jointParameters HingeJointParameters {
                                          position -1.1825096026479721e-08
                                          anchor 0.02895 0 0.0865
                                        }
                                        device [
                                          RotationalMotor {
                                            name "joint6"
                                            maxVelocity 1000
                                            minPosition -10
                                            maxPosition 10
                                            maxTorque 100
                                          }
                                          PositionSensor {
                                            name "joint6_sensor"
                                          }
                                        ]
                                        endPoint Solid {
                                          translation 0.02895 0 0.0865
                                          rotation -1 0 0 3.141600012131571
                                          children [
                                            Shape {
                                              appearance DEF link6_material PBRAppearance {
                                                baseColor 0.89804 0.91765 0.92941
                                                roughness 1
                                                metalness 0
                                              }
                                              geometry DEF link6 Mesh {
                                                url [
                                                  "/home/zishang/Webots/galileo_mini_x5/protos/meshes/link6.STL"
                                                ]
                                              }
                                            }
                                            Solid {
                                              translation 0.08657 0.024896 -0.000244
                                              children [
                                                Shape {
                                                  appearance DEF link7_material PBRAppearance {
                                                    roughness 1
                                                    metalness 0
                                                  }
                                                  geometry DEF link7 Mesh {
                                                    url [
                                                      "/home/zishang/Webots/galileo_mini_x5/protos/meshes/link7.STL"
                                                    ]
                                                  }
                                                }
                                              ]
                                              name "link7"
                                              physics Physics {
                                                density -1
                                                mass 0.064798
                                                centerOfMass [
                                                  -0.000355 -0.007827 -0.002988
                                                ]
                                                inertiaMatrix [
                                                  2e-05 3e-05 3e-05
                                                  0 0 0
                                                ]
                                              }
                                            }
                                            Solid {
                                              translation 0.08657 -0.0249 -0.000244
                                              children [
                                                Shape {
                                                  appearance DEF link8_material PBRAppearance {
                                                    roughness 1
                                                    metalness 0
                                                  }
                                                  geometry DEF link8 Mesh {
                                                    url [
                                                      "/home/zishang/Webots/galileo_mini_x5/protos/meshes/link8.STL"
                                                    ]
                                                  }
                                                }
                                              ]
                                              name "link8"
                                              physics Physics {
                                                density -1
                                                mass 0.064798
                                                centerOfMass [
                                                  -0.000355 0.007828 0.00242
                                                ]
                                                inertiaMatrix [
                                                  2e-05 3e-05 3e-05
                                                  0 0 0
                                                ]
                                              }
                                            }
                                          ]
                                          name "link6"
                                          physics Physics {
                                            density -1
                                            mass 0.44089
                                            centerOfMass [
                                              0.041697 2.4e-05 0.000145
                                            ]
                                            inertiaMatrix [
                                              0.00038 0.00028 0.0005
                                              0 0 0
                                            ]
                                          }
                                        }
                                      }
                                    ]
                                    name "link5"
                                    physics Physics {
                                      density -1
                                      mass 0.63488
                                      centerOfMass [
                                        0.003612 -1.5e-05 0.055214
                                      ]
                                      inertiaMatrix [
                                        0.00083 0.00082 0.00026
                                        0 7e-05 0
                                      ]
                                    }
                                  }
                                }
                              ]
                              name "link4"
                              physics Physics {
                                density -1
                                mass 0.11714
                                centerOfMass [
                                  0.040231 0.004481 -0.035335
                                ]
                                inertiaMatrix [
                                  0.00019 0.00023 0.00014
                                  -2e-05 -9e-05 2e-05
                                ]
                              }
                            }
                          }
                        ]
                        name "link3"
                        physics Physics {
                          density -1
                          mass 0.54534
                          centerOfMass [
                            0.18531 0.000684 -0.051638
                          ]
                          inertiaMatrix [
                            0.00036 0.00423 0.0042
                            -3e-05 -0.00039 1e-05
                          ]
                        }
                      }
                    }
                  ]
                  name "link2"
                  physics Physics {
                    density -1
                    mass 1.0795
                    centerOfMass [
                      -0.13237 0.002085 0.000105
                    ]
                    inertiaMatrix [
                      0.00051 0.01599 0.01605
                      1e-05 -4e-05 0
                    ]
                  }
                }
              }
            ]
            name "link1"
            physics Physics {
              density -1
              mass 0.066982
              centerOfMass [
                0.005423 -0.008029 0.017086
              ]
              inertiaMatrix [
                8e-05 3e-05 8e-05
                0 1e-05 0
              ]
            }
          }
        }
      ]
      name "manipulator_base_link"
      physics Physics {
        density -1
        mass 0.43995
        centerOfMass [
          -3e-05 3.1e-05 0.027324
        ]
        inertiaMatrix [
          0.00017 0.00017 0.00016
          0 0 0
        ]
      }
    }
  ]
  name "galileo_mini_x5"
  boundingObject Box {
    size 0.45 0.25 0.1
  }
  physics Physics {
    density -1
    mass 20.8
    centerOfMass [
      0.03738 -0.00659 0.005793
    ]
    inertiaMatrix [
      0.131102 0.407915 0.476755
      0.001924 0.001299 0.002595
    ]
  }
  controller "<extern>"
  supervisor TRUE
}
